2024-10-09 15:36:00,865 ERROR scheduler Exception in Enqueue Events for Site ozerpan
Traceback (most recent call last):
  File "/home/mstfrs/Desktop/ozerpan/apps/frappe/frappe/utils/scheduler.py", line 106, in enqueue_events_for_site
    if is_scheduler_inactive():
  File "/home/mstfrs/Desktop/ozerpan/apps/frappe/frappe/utils/scheduler.py", line 150, in is_scheduler_inactive
    if is_scheduler_disabled(verbose=verbose):
  File "/home/mstfrs/Desktop/ozerpan/apps/frappe/frappe/utils/scheduler.py", line 163, in is_scheduler_disabled
    frappe.db.get_single_value("System Settings", "enable_scheduler")
  File "/home/mstfrs/Desktop/ozerpan/apps/frappe/frappe/database/database.py", line 846, in get_single_value
    ).run()
  File "/home/mstfrs/Desktop/ozerpan/apps/frappe/frappe/query_builder/utils.py", line 84, in execute_query
    result = frappe.db.sql(query, params, *args, **kwargs)  # nosemgrep
  File "/home/mstfrs/Desktop/ozerpan/apps/frappe/frappe/database/database.py", line 213, in sql
    self.connect()
  File "/home/mstfrs/Desktop/ozerpan/apps/frappe/frappe/database/database.py", line 118, in connect
    self._conn: "MariadbConnection" | "PostgresConnection" = self.get_connection()
  File "/home/mstfrs/Desktop/ozerpan/apps/frappe/frappe/database/mariadb/database.py", line 107, in get_connection
    conn = self._get_connection()
  File "/home/mstfrs/Desktop/ozerpan/apps/frappe/frappe/database/mariadb/database.py", line 113, in _get_connection
    return self.create_connection()
  File "/home/mstfrs/Desktop/ozerpan/apps/frappe/frappe/database/mariadb/database.py", line 116, in create_connection
    return pymysql.connect(**self.get_connection_settings())
  File "/home/mstfrs/Desktop/ozerpan/env/lib/python3.10/site-packages/pymysql/connections.py", line 361, in __init__
    self.connect()
  File "/home/mstfrs/Desktop/ozerpan/env/lib/python3.10/site-packages/pymysql/connections.py", line 669, in connect
    self._request_authentication()
  File "/home/mstfrs/Desktop/ozerpan/env/lib/python3.10/site-packages/pymysql/connections.py", line 957, in _request_authentication
    auth_packet = self._read_packet()
  File "/home/mstfrs/Desktop/ozerpan/env/lib/python3.10/site-packages/pymysql/connections.py", line 775, in _read_packet
    packet.raise_for_error()
  File "/home/mstfrs/Desktop/ozerpan/env/lib/python3.10/site-packages/pymysql/protocol.py", line 219, in raise_for_error
    err.raise_mysql_exception(self._data)
  File "/home/mstfrs/Desktop/ozerpan/env/lib/python3.10/site-packages/pymysql/err.py", line 150, in raise_mysql_exception
    raise errorclass(errno, errval)
pymysql.err.OperationalError: (1049, "Unknown database '_be61cf5335d3ad96'")
2024-10-09 15:40:01,109 ERROR scheduler Exception in Enqueue Events for Site ozerpan
Traceback (most recent call last):
  File "/home/mstfrs/Desktop/ozerpan/apps/frappe/frappe/utils/scheduler.py", line 106, in enqueue_events_for_site
    if is_scheduler_inactive():
  File "/home/mstfrs/Desktop/ozerpan/apps/frappe/frappe/utils/scheduler.py", line 150, in is_scheduler_inactive
    if is_scheduler_disabled(verbose=verbose):
  File "/home/mstfrs/Desktop/ozerpan/apps/frappe/frappe/utils/scheduler.py", line 163, in is_scheduler_disabled
    frappe.db.get_single_value("System Settings", "enable_scheduler")
  File "/home/mstfrs/Desktop/ozerpan/apps/frappe/frappe/database/database.py", line 846, in get_single_value
    ).run()
  File "/home/mstfrs/Desktop/ozerpan/apps/frappe/frappe/query_builder/utils.py", line 84, in execute_query
    result = frappe.db.sql(query, params, *args, **kwargs)  # nosemgrep
  File "/home/mstfrs/Desktop/ozerpan/apps/frappe/frappe/database/database.py", line 213, in sql
    self.connect()
  File "/home/mstfrs/Desktop/ozerpan/apps/frappe/frappe/database/database.py", line 118, in connect
    self._conn: "MariadbConnection" | "PostgresConnection" = self.get_connection()
  File "/home/mstfrs/Desktop/ozerpan/apps/frappe/frappe/database/mariadb/database.py", line 107, in get_connection
    conn = self._get_connection()
  File "/home/mstfrs/Desktop/ozerpan/apps/frappe/frappe/database/mariadb/database.py", line 113, in _get_connection
    return self.create_connection()
  File "/home/mstfrs/Desktop/ozerpan/apps/frappe/frappe/database/mariadb/database.py", line 116, in create_connection
    return pymysql.connect(**self.get_connection_settings())
  File "/home/mstfrs/Desktop/ozerpan/env/lib/python3.10/site-packages/pymysql/connections.py", line 361, in __init__
    self.connect()
  File "/home/mstfrs/Desktop/ozerpan/env/lib/python3.10/site-packages/pymysql/connections.py", line 669, in connect
    self._request_authentication()
  File "/home/mstfrs/Desktop/ozerpan/env/lib/python3.10/site-packages/pymysql/connections.py", line 957, in _request_authentication
    auth_packet = self._read_packet()
  File "/home/mstfrs/Desktop/ozerpan/env/lib/python3.10/site-packages/pymysql/connections.py", line 775, in _read_packet
    packet.raise_for_error()
  File "/home/mstfrs/Desktop/ozerpan/env/lib/python3.10/site-packages/pymysql/protocol.py", line 219, in raise_for_error
    err.raise_mysql_exception(self._data)
  File "/home/mstfrs/Desktop/ozerpan/env/lib/python3.10/site-packages/pymysql/err.py", line 150, in raise_mysql_exception
    raise errorclass(errno, errval)
pymysql.err.OperationalError: (1049, "Unknown database '_be61cf5335d3ad96'")
2024-10-09 15:44:01,035 ERROR scheduler Exception in Enqueue Events for Site ozerpan
Traceback (most recent call last):
  File "/home/mstfrs/Desktop/ozerpan/apps/frappe/frappe/utils/scheduler.py", line 106, in enqueue_events_for_site
    if is_scheduler_inactive():
  File "/home/mstfrs/Desktop/ozerpan/apps/frappe/frappe/utils/scheduler.py", line 150, in is_scheduler_inactive
    if is_scheduler_disabled(verbose=verbose):
  File "/home/mstfrs/Desktop/ozerpan/apps/frappe/frappe/utils/scheduler.py", line 163, in is_scheduler_disabled
    frappe.db.get_single_value("System Settings", "enable_scheduler")
  File "/home/mstfrs/Desktop/ozerpan/apps/frappe/frappe/database/database.py", line 846, in get_single_value
    ).run()
  File "/home/mstfrs/Desktop/ozerpan/apps/frappe/frappe/query_builder/utils.py", line 84, in execute_query
    result = frappe.db.sql(query, params, *args, **kwargs)  # nosemgrep
  File "/home/mstfrs/Desktop/ozerpan/apps/frappe/frappe/database/database.py", line 213, in sql
    self.connect()
  File "/home/mstfrs/Desktop/ozerpan/apps/frappe/frappe/database/database.py", line 118, in connect
    self._conn: "MariadbConnection" | "PostgresConnection" = self.get_connection()
  File "/home/mstfrs/Desktop/ozerpan/apps/frappe/frappe/database/mariadb/database.py", line 107, in get_connection
    conn = self._get_connection()
  File "/home/mstfrs/Desktop/ozerpan/apps/frappe/frappe/database/mariadb/database.py", line 113, in _get_connection
    return self.create_connection()
  File "/home/mstfrs/Desktop/ozerpan/apps/frappe/frappe/database/mariadb/database.py", line 116, in create_connection
    return pymysql.connect(**self.get_connection_settings())
  File "/home/mstfrs/Desktop/ozerpan/env/lib/python3.10/site-packages/pymysql/connections.py", line 361, in __init__
    self.connect()
  File "/home/mstfrs/Desktop/ozerpan/env/lib/python3.10/site-packages/pymysql/connections.py", line 669, in connect
    self._request_authentication()
  File "/home/mstfrs/Desktop/ozerpan/env/lib/python3.10/site-packages/pymysql/connections.py", line 957, in _request_authentication
    auth_packet = self._read_packet()
  File "/home/mstfrs/Desktop/ozerpan/env/lib/python3.10/site-packages/pymysql/connections.py", line 775, in _read_packet
    packet.raise_for_error()
  File "/home/mstfrs/Desktop/ozerpan/env/lib/python3.10/site-packages/pymysql/protocol.py", line 219, in raise_for_error
    err.raise_mysql_exception(self._data)
  File "/home/mstfrs/Desktop/ozerpan/env/lib/python3.10/site-packages/pymysql/err.py", line 150, in raise_mysql_exception
    raise errorclass(errno, errval)
pymysql.err.OperationalError: (1049, "Unknown database '_be61cf5335d3ad96'")
2024-10-09 15:48:00,518 ERROR scheduler Exception in Enqueue Events for Site ozerpan
Traceback (most recent call last):
  File "/home/mstfrs/Desktop/ozerpan/apps/frappe/frappe/utils/scheduler.py", line 106, in enqueue_events_for_site
    if is_scheduler_inactive():
  File "/home/mstfrs/Desktop/ozerpan/apps/frappe/frappe/utils/scheduler.py", line 150, in is_scheduler_inactive
    if is_scheduler_disabled(verbose=verbose):
  File "/home/mstfrs/Desktop/ozerpan/apps/frappe/frappe/utils/scheduler.py", line 163, in is_scheduler_disabled
    frappe.db.get_single_value("System Settings", "enable_scheduler")
  File "/home/mstfrs/Desktop/ozerpan/apps/frappe/frappe/database/database.py", line 846, in get_single_value
    ).run()
  File "/home/mstfrs/Desktop/ozerpan/apps/frappe/frappe/query_builder/utils.py", line 84, in execute_query
    result = frappe.db.sql(query, params, *args, **kwargs)  # nosemgrep
  File "/home/mstfrs/Desktop/ozerpan/apps/frappe/frappe/database/database.py", line 213, in sql
    self.connect()
  File "/home/mstfrs/Desktop/ozerpan/apps/frappe/frappe/database/database.py", line 118, in connect
    self._conn: "MariadbConnection" | "PostgresConnection" = self.get_connection()
  File "/home/mstfrs/Desktop/ozerpan/apps/frappe/frappe/database/mariadb/database.py", line 107, in get_connection
    conn = self._get_connection()
  File "/home/mstfrs/Desktop/ozerpan/apps/frappe/frappe/database/mariadb/database.py", line 113, in _get_connection
    return self.create_connection()
  File "/home/mstfrs/Desktop/ozerpan/apps/frappe/frappe/database/mariadb/database.py", line 116, in create_connection
    return pymysql.connect(**self.get_connection_settings())
  File "/home/mstfrs/Desktop/ozerpan/env/lib/python3.10/site-packages/pymysql/connections.py", line 361, in __init__
    self.connect()
  File "/home/mstfrs/Desktop/ozerpan/env/lib/python3.10/site-packages/pymysql/connections.py", line 669, in connect
    self._request_authentication()
  File "/home/mstfrs/Desktop/ozerpan/env/lib/python3.10/site-packages/pymysql/connections.py", line 957, in _request_authentication
    auth_packet = self._read_packet()
  File "/home/mstfrs/Desktop/ozerpan/env/lib/python3.10/site-packages/pymysql/connections.py", line 775, in _read_packet
    packet.raise_for_error()
  File "/home/mstfrs/Desktop/ozerpan/env/lib/python3.10/site-packages/pymysql/protocol.py", line 219, in raise_for_error
    err.raise_mysql_exception(self._data)
  File "/home/mstfrs/Desktop/ozerpan/env/lib/python3.10/site-packages/pymysql/err.py", line 150, in raise_mysql_exception
    raise errorclass(errno, errval)
pymysql.err.OperationalError: (1049, "Unknown database '_be61cf5335d3ad96'")
2024-10-09 15:52:00,624 ERROR scheduler Exception in Enqueue Events for Site ozerpan
Traceback (most recent call last):
  File "/home/mstfrs/Desktop/ozerpan/apps/frappe/frappe/utils/scheduler.py", line 106, in enqueue_events_for_site
    if is_scheduler_inactive():
  File "/home/mstfrs/Desktop/ozerpan/apps/frappe/frappe/utils/scheduler.py", line 150, in is_scheduler_inactive
    if is_scheduler_disabled(verbose=verbose):
  File "/home/mstfrs/Desktop/ozerpan/apps/frappe/frappe/utils/scheduler.py", line 163, in is_scheduler_disabled
    frappe.db.get_single_value("System Settings", "enable_scheduler")
  File "/home/mstfrs/Desktop/ozerpan/apps/frappe/frappe/database/database.py", line 846, in get_single_value
    ).run()
  File "/home/mstfrs/Desktop/ozerpan/apps/frappe/frappe/query_builder/utils.py", line 84, in execute_query
    result = frappe.db.sql(query, params, *args, **kwargs)  # nosemgrep
  File "/home/mstfrs/Desktop/ozerpan/apps/frappe/frappe/database/database.py", line 213, in sql
    self.connect()
  File "/home/mstfrs/Desktop/ozerpan/apps/frappe/frappe/database/database.py", line 118, in connect
    self._conn: "MariadbConnection" | "PostgresConnection" = self.get_connection()
  File "/home/mstfrs/Desktop/ozerpan/apps/frappe/frappe/database/mariadb/database.py", line 107, in get_connection
    conn = self._get_connection()
  File "/home/mstfrs/Desktop/ozerpan/apps/frappe/frappe/database/mariadb/database.py", line 113, in _get_connection
    return self.create_connection()
  File "/home/mstfrs/Desktop/ozerpan/apps/frappe/frappe/database/mariadb/database.py", line 116, in create_connection
    return pymysql.connect(**self.get_connection_settings())
  File "/home/mstfrs/Desktop/ozerpan/env/lib/python3.10/site-packages/pymysql/connections.py", line 361, in __init__
    self.connect()
  File "/home/mstfrs/Desktop/ozerpan/env/lib/python3.10/site-packages/pymysql/connections.py", line 669, in connect
    self._request_authentication()
  File "/home/mstfrs/Desktop/ozerpan/env/lib/python3.10/site-packages/pymysql/connections.py", line 957, in _request_authentication
    auth_packet = self._read_packet()
  File "/home/mstfrs/Desktop/ozerpan/env/lib/python3.10/site-packages/pymysql/connections.py", line 775, in _read_packet
    packet.raise_for_error()
  File "/home/mstfrs/Desktop/ozerpan/env/lib/python3.10/site-packages/pymysql/protocol.py", line 219, in raise_for_error
    err.raise_mysql_exception(self._data)
  File "/home/mstfrs/Desktop/ozerpan/env/lib/python3.10/site-packages/pymysql/err.py", line 150, in raise_mysql_exception
    raise errorclass(errno, errval)
pymysql.err.OperationalError: (1049, "Unknown database '_be61cf5335d3ad96'")
2024-10-09 15:56:01,027 ERROR scheduler Exception in Enqueue Events for Site ozerpan
Traceback (most recent call last):
  File "/home/mstfrs/Desktop/ozerpan/apps/frappe/frappe/utils/scheduler.py", line 106, in enqueue_events_for_site
    if is_scheduler_inactive():
  File "/home/mstfrs/Desktop/ozerpan/apps/frappe/frappe/utils/scheduler.py", line 150, in is_scheduler_inactive
    if is_scheduler_disabled(verbose=verbose):
  File "/home/mstfrs/Desktop/ozerpan/apps/frappe/frappe/utils/scheduler.py", line 163, in is_scheduler_disabled
    frappe.db.get_single_value("System Settings", "enable_scheduler")
  File "/home/mstfrs/Desktop/ozerpan/apps/frappe/frappe/database/database.py", line 846, in get_single_value
    ).run()
  File "/home/mstfrs/Desktop/ozerpan/apps/frappe/frappe/query_builder/utils.py", line 84, in execute_query
    result = frappe.db.sql(query, params, *args, **kwargs)  # nosemgrep
  File "/home/mstfrs/Desktop/ozerpan/apps/frappe/frappe/database/database.py", line 213, in sql
    self.connect()
  File "/home/mstfrs/Desktop/ozerpan/apps/frappe/frappe/database/database.py", line 118, in connect
    self._conn: "MariadbConnection" | "PostgresConnection" = self.get_connection()
  File "/home/mstfrs/Desktop/ozerpan/apps/frappe/frappe/database/mariadb/database.py", line 107, in get_connection
    conn = self._get_connection()
  File "/home/mstfrs/Desktop/ozerpan/apps/frappe/frappe/database/mariadb/database.py", line 113, in _get_connection
    return self.create_connection()
  File "/home/mstfrs/Desktop/ozerpan/apps/frappe/frappe/database/mariadb/database.py", line 116, in create_connection
    return pymysql.connect(**self.get_connection_settings())
  File "/home/mstfrs/Desktop/ozerpan/env/lib/python3.10/site-packages/pymysql/connections.py", line 361, in __init__
    self.connect()
  File "/home/mstfrs/Desktop/ozerpan/env/lib/python3.10/site-packages/pymysql/connections.py", line 669, in connect
    self._request_authentication()
  File "/home/mstfrs/Desktop/ozerpan/env/lib/python3.10/site-packages/pymysql/connections.py", line 957, in _request_authentication
    auth_packet = self._read_packet()
  File "/home/mstfrs/Desktop/ozerpan/env/lib/python3.10/site-packages/pymysql/connections.py", line 775, in _read_packet
    packet.raise_for_error()
  File "/home/mstfrs/Desktop/ozerpan/env/lib/python3.10/site-packages/pymysql/protocol.py", line 219, in raise_for_error
    err.raise_mysql_exception(self._data)
  File "/home/mstfrs/Desktop/ozerpan/env/lib/python3.10/site-packages/pymysql/err.py", line 150, in raise_mysql_exception
    raise errorclass(errno, errval)
pymysql.err.OperationalError: (1049, "Unknown database '_be61cf5335d3ad96'")
2024-10-09 16:00:00,492 ERROR scheduler Exception in Enqueue Events for Site ozerpan
Traceback (most recent call last):
  File "/home/mstfrs/Desktop/ozerpan/apps/frappe/frappe/utils/scheduler.py", line 106, in enqueue_events_for_site
    if is_scheduler_inactive():
  File "/home/mstfrs/Desktop/ozerpan/apps/frappe/frappe/utils/scheduler.py", line 150, in is_scheduler_inactive
    if is_scheduler_disabled(verbose=verbose):
  File "/home/mstfrs/Desktop/ozerpan/apps/frappe/frappe/utils/scheduler.py", line 163, in is_scheduler_disabled
    frappe.db.get_single_value("System Settings", "enable_scheduler")
  File "/home/mstfrs/Desktop/ozerpan/apps/frappe/frappe/database/database.py", line 846, in get_single_value
    ).run()
  File "/home/mstfrs/Desktop/ozerpan/apps/frappe/frappe/query_builder/utils.py", line 84, in execute_query
    result = frappe.db.sql(query, params, *args, **kwargs)  # nosemgrep
  File "/home/mstfrs/Desktop/ozerpan/apps/frappe/frappe/database/database.py", line 213, in sql
    self.connect()
  File "/home/mstfrs/Desktop/ozerpan/apps/frappe/frappe/database/database.py", line 118, in connect
    self._conn: "MariadbConnection" | "PostgresConnection" = self.get_connection()
  File "/home/mstfrs/Desktop/ozerpan/apps/frappe/frappe/database/mariadb/database.py", line 107, in get_connection
    conn = self._get_connection()
  File "/home/mstfrs/Desktop/ozerpan/apps/frappe/frappe/database/mariadb/database.py", line 113, in _get_connection
    return self.create_connection()
  File "/home/mstfrs/Desktop/ozerpan/apps/frappe/frappe/database/mariadb/database.py", line 116, in create_connection
    return pymysql.connect(**self.get_connection_settings())
  File "/home/mstfrs/Desktop/ozerpan/env/lib/python3.10/site-packages/pymysql/connections.py", line 361, in __init__
    self.connect()
  File "/home/mstfrs/Desktop/ozerpan/env/lib/python3.10/site-packages/pymysql/connections.py", line 669, in connect
    self._request_authentication()
  File "/home/mstfrs/Desktop/ozerpan/env/lib/python3.10/site-packages/pymysql/connections.py", line 957, in _request_authentication
    auth_packet = self._read_packet()
  File "/home/mstfrs/Desktop/ozerpan/env/lib/python3.10/site-packages/pymysql/connections.py", line 775, in _read_packet
    packet.raise_for_error()
  File "/home/mstfrs/Desktop/ozerpan/env/lib/python3.10/site-packages/pymysql/protocol.py", line 219, in raise_for_error
    err.raise_mysql_exception(self._data)
  File "/home/mstfrs/Desktop/ozerpan/env/lib/python3.10/site-packages/pymysql/err.py", line 150, in raise_mysql_exception
    raise errorclass(errno, errval)
pymysql.err.OperationalError: (1049, "Unknown database '_be61cf5335d3ad96'")
2024-10-09 16:04:00,961 ERROR scheduler Exception in Enqueue Events for Site ozerpan
Traceback (most recent call last):
  File "/home/mstfrs/Desktop/ozerpan/apps/frappe/frappe/utils/scheduler.py", line 106, in enqueue_events_for_site
    if is_scheduler_inactive():
  File "/home/mstfrs/Desktop/ozerpan/apps/frappe/frappe/utils/scheduler.py", line 150, in is_scheduler_inactive
    if is_scheduler_disabled(verbose=verbose):
  File "/home/mstfrs/Desktop/ozerpan/apps/frappe/frappe/utils/scheduler.py", line 163, in is_scheduler_disabled
    frappe.db.get_single_value("System Settings", "enable_scheduler")
  File "/home/mstfrs/Desktop/ozerpan/apps/frappe/frappe/database/database.py", line 846, in get_single_value
    ).run()
  File "/home/mstfrs/Desktop/ozerpan/apps/frappe/frappe/query_builder/utils.py", line 84, in execute_query
    result = frappe.db.sql(query, params, *args, **kwargs)  # nosemgrep
  File "/home/mstfrs/Desktop/ozerpan/apps/frappe/frappe/database/database.py", line 213, in sql
    self.connect()
  File "/home/mstfrs/Desktop/ozerpan/apps/frappe/frappe/database/database.py", line 118, in connect
    self._conn: "MariadbConnection" | "PostgresConnection" = self.get_connection()
  File "/home/mstfrs/Desktop/ozerpan/apps/frappe/frappe/database/mariadb/database.py", line 107, in get_connection
    conn = self._get_connection()
  File "/home/mstfrs/Desktop/ozerpan/apps/frappe/frappe/database/mariadb/database.py", line 113, in _get_connection
    return self.create_connection()
  File "/home/mstfrs/Desktop/ozerpan/apps/frappe/frappe/database/mariadb/database.py", line 116, in create_connection
    return pymysql.connect(**self.get_connection_settings())
  File "/home/mstfrs/Desktop/ozerpan/env/lib/python3.10/site-packages/pymysql/connections.py", line 361, in __init__
    self.connect()
  File "/home/mstfrs/Desktop/ozerpan/env/lib/python3.10/site-packages/pymysql/connections.py", line 669, in connect
    self._request_authentication()
  File "/home/mstfrs/Desktop/ozerpan/env/lib/python3.10/site-packages/pymysql/connections.py", line 957, in _request_authentication
    auth_packet = self._read_packet()
  File "/home/mstfrs/Desktop/ozerpan/env/lib/python3.10/site-packages/pymysql/connections.py", line 775, in _read_packet
    packet.raise_for_error()
  File "/home/mstfrs/Desktop/ozerpan/env/lib/python3.10/site-packages/pymysql/protocol.py", line 219, in raise_for_error
    err.raise_mysql_exception(self._data)
  File "/home/mstfrs/Desktop/ozerpan/env/lib/python3.10/site-packages/pymysql/err.py", line 150, in raise_mysql_exception
    raise errorclass(errno, errval)
pymysql.err.OperationalError: (1049, "Unknown database '_be61cf5335d3ad96'")
2024-10-09 16:08:01,180 ERROR scheduler Exception in Enqueue Events for Site ozerpan
Traceback (most recent call last):
  File "/home/mstfrs/Desktop/ozerpan/apps/frappe/frappe/utils/scheduler.py", line 106, in enqueue_events_for_site
    if is_scheduler_inactive():
  File "/home/mstfrs/Desktop/ozerpan/apps/frappe/frappe/utils/scheduler.py", line 150, in is_scheduler_inactive
    if is_scheduler_disabled(verbose=verbose):
  File "/home/mstfrs/Desktop/ozerpan/apps/frappe/frappe/utils/scheduler.py", line 163, in is_scheduler_disabled
    frappe.db.get_single_value("System Settings", "enable_scheduler")
  File "/home/mstfrs/Desktop/ozerpan/apps/frappe/frappe/database/database.py", line 846, in get_single_value
    ).run()
  File "/home/mstfrs/Desktop/ozerpan/apps/frappe/frappe/query_builder/utils.py", line 84, in execute_query
    result = frappe.db.sql(query, params, *args, **kwargs)  # nosemgrep
  File "/home/mstfrs/Desktop/ozerpan/apps/frappe/frappe/database/database.py", line 213, in sql
    self.connect()
  File "/home/mstfrs/Desktop/ozerpan/apps/frappe/frappe/database/database.py", line 118, in connect
    self._conn: "MariadbConnection" | "PostgresConnection" = self.get_connection()
  File "/home/mstfrs/Desktop/ozerpan/apps/frappe/frappe/database/mariadb/database.py", line 107, in get_connection
    conn = self._get_connection()
  File "/home/mstfrs/Desktop/ozerpan/apps/frappe/frappe/database/mariadb/database.py", line 113, in _get_connection
    return self.create_connection()
  File "/home/mstfrs/Desktop/ozerpan/apps/frappe/frappe/database/mariadb/database.py", line 116, in create_connection
    return pymysql.connect(**self.get_connection_settings())
  File "/home/mstfrs/Desktop/ozerpan/env/lib/python3.10/site-packages/pymysql/connections.py", line 361, in __init__
    self.connect()
  File "/home/mstfrs/Desktop/ozerpan/env/lib/python3.10/site-packages/pymysql/connections.py", line 669, in connect
    self._request_authentication()
  File "/home/mstfrs/Desktop/ozerpan/env/lib/python3.10/site-packages/pymysql/connections.py", line 957, in _request_authentication
    auth_packet = self._read_packet()
  File "/home/mstfrs/Desktop/ozerpan/env/lib/python3.10/site-packages/pymysql/connections.py", line 775, in _read_packet
    packet.raise_for_error()
  File "/home/mstfrs/Desktop/ozerpan/env/lib/python3.10/site-packages/pymysql/protocol.py", line 219, in raise_for_error
    err.raise_mysql_exception(self._data)
  File "/home/mstfrs/Desktop/ozerpan/env/lib/python3.10/site-packages/pymysql/err.py", line 150, in raise_mysql_exception
    raise errorclass(errno, errval)
pymysql.err.OperationalError: (1049, "Unknown database '_be61cf5335d3ad96'")
2024-10-09 16:12:01,637 ERROR scheduler Exception in Enqueue Events for Site ozerpan
Traceback (most recent call last):
  File "/home/mstfrs/Desktop/ozerpan/apps/frappe/frappe/utils/scheduler.py", line 106, in enqueue_events_for_site
    if is_scheduler_inactive():
  File "/home/mstfrs/Desktop/ozerpan/apps/frappe/frappe/utils/scheduler.py", line 150, in is_scheduler_inactive
    if is_scheduler_disabled(verbose=verbose):
  File "/home/mstfrs/Desktop/ozerpan/apps/frappe/frappe/utils/scheduler.py", line 163, in is_scheduler_disabled
    frappe.db.get_single_value("System Settings", "enable_scheduler")
  File "/home/mstfrs/Desktop/ozerpan/apps/frappe/frappe/database/database.py", line 846, in get_single_value
    ).run()
  File "/home/mstfrs/Desktop/ozerpan/apps/frappe/frappe/query_builder/utils.py", line 84, in execute_query
    result = frappe.db.sql(query, params, *args, **kwargs)  # nosemgrep
  File "/home/mstfrs/Desktop/ozerpan/apps/frappe/frappe/database/database.py", line 213, in sql
    self.connect()
  File "/home/mstfrs/Desktop/ozerpan/apps/frappe/frappe/database/database.py", line 118, in connect
    self._conn: "MariadbConnection" | "PostgresConnection" = self.get_connection()
  File "/home/mstfrs/Desktop/ozerpan/apps/frappe/frappe/database/mariadb/database.py", line 107, in get_connection
    conn = self._get_connection()
  File "/home/mstfrs/Desktop/ozerpan/apps/frappe/frappe/database/mariadb/database.py", line 113, in _get_connection
    return self.create_connection()
  File "/home/mstfrs/Desktop/ozerpan/apps/frappe/frappe/database/mariadb/database.py", line 116, in create_connection
    return pymysql.connect(**self.get_connection_settings())
  File "/home/mstfrs/Desktop/ozerpan/env/lib/python3.10/site-packages/pymysql/connections.py", line 361, in __init__
    self.connect()
  File "/home/mstfrs/Desktop/ozerpan/env/lib/python3.10/site-packages/pymysql/connections.py", line 669, in connect
    self._request_authentication()
  File "/home/mstfrs/Desktop/ozerpan/env/lib/python3.10/site-packages/pymysql/connections.py", line 957, in _request_authentication
    auth_packet = self._read_packet()
  File "/home/mstfrs/Desktop/ozerpan/env/lib/python3.10/site-packages/pymysql/connections.py", line 775, in _read_packet
    packet.raise_for_error()
  File "/home/mstfrs/Desktop/ozerpan/env/lib/python3.10/site-packages/pymysql/protocol.py", line 219, in raise_for_error
    err.raise_mysql_exception(self._data)
  File "/home/mstfrs/Desktop/ozerpan/env/lib/python3.10/site-packages/pymysql/err.py", line 150, in raise_mysql_exception
    raise errorclass(errno, errval)
pymysql.err.OperationalError: (1049, "Unknown database '_be61cf5335d3ad96'")
2024-10-09 16:16:00,762 ERROR scheduler Exception in Enqueue Events for Site ozerpan
Traceback (most recent call last):
  File "/home/mstfrs/Desktop/ozerpan/apps/frappe/frappe/utils/scheduler.py", line 106, in enqueue_events_for_site
    if is_scheduler_inactive():
  File "/home/mstfrs/Desktop/ozerpan/apps/frappe/frappe/utils/scheduler.py", line 150, in is_scheduler_inactive
    if is_scheduler_disabled(verbose=verbose):
  File "/home/mstfrs/Desktop/ozerpan/apps/frappe/frappe/utils/scheduler.py", line 163, in is_scheduler_disabled
    frappe.db.get_single_value("System Settings", "enable_scheduler")
  File "/home/mstfrs/Desktop/ozerpan/apps/frappe/frappe/database/database.py", line 846, in get_single_value
    ).run()
  File "/home/mstfrs/Desktop/ozerpan/apps/frappe/frappe/query_builder/utils.py", line 84, in execute_query
    result = frappe.db.sql(query, params, *args, **kwargs)  # nosemgrep
  File "/home/mstfrs/Desktop/ozerpan/apps/frappe/frappe/database/database.py", line 213, in sql
    self.connect()
  File "/home/mstfrs/Desktop/ozerpan/apps/frappe/frappe/database/database.py", line 118, in connect
    self._conn: "MariadbConnection" | "PostgresConnection" = self.get_connection()
  File "/home/mstfrs/Desktop/ozerpan/apps/frappe/frappe/database/mariadb/database.py", line 107, in get_connection
    conn = self._get_connection()
  File "/home/mstfrs/Desktop/ozerpan/apps/frappe/frappe/database/mariadb/database.py", line 113, in _get_connection
    return self.create_connection()
  File "/home/mstfrs/Desktop/ozerpan/apps/frappe/frappe/database/mariadb/database.py", line 116, in create_connection
    return pymysql.connect(**self.get_connection_settings())
  File "/home/mstfrs/Desktop/ozerpan/env/lib/python3.10/site-packages/pymysql/connections.py", line 361, in __init__
    self.connect()
  File "/home/mstfrs/Desktop/ozerpan/env/lib/python3.10/site-packages/pymysql/connections.py", line 669, in connect
    self._request_authentication()
  File "/home/mstfrs/Desktop/ozerpan/env/lib/python3.10/site-packages/pymysql/connections.py", line 957, in _request_authentication
    auth_packet = self._read_packet()
  File "/home/mstfrs/Desktop/ozerpan/env/lib/python3.10/site-packages/pymysql/connections.py", line 775, in _read_packet
    packet.raise_for_error()
  File "/home/mstfrs/Desktop/ozerpan/env/lib/python3.10/site-packages/pymysql/protocol.py", line 219, in raise_for_error
    err.raise_mysql_exception(self._data)
  File "/home/mstfrs/Desktop/ozerpan/env/lib/python3.10/site-packages/pymysql/err.py", line 150, in raise_mysql_exception
    raise errorclass(errno, errval)
pymysql.err.OperationalError: (1049, "Unknown database '_be61cf5335d3ad96'")
2024-10-09 16:20:00,634 ERROR scheduler Exception in Enqueue Events for Site ozerpan
Traceback (most recent call last):
  File "/home/mstfrs/Desktop/ozerpan/apps/frappe/frappe/utils/scheduler.py", line 106, in enqueue_events_for_site
    if is_scheduler_inactive():
  File "/home/mstfrs/Desktop/ozerpan/apps/frappe/frappe/utils/scheduler.py", line 150, in is_scheduler_inactive
    if is_scheduler_disabled(verbose=verbose):
  File "/home/mstfrs/Desktop/ozerpan/apps/frappe/frappe/utils/scheduler.py", line 163, in is_scheduler_disabled
    frappe.db.get_single_value("System Settings", "enable_scheduler")
  File "/home/mstfrs/Desktop/ozerpan/apps/frappe/frappe/database/database.py", line 846, in get_single_value
    ).run()
  File "/home/mstfrs/Desktop/ozerpan/apps/frappe/frappe/query_builder/utils.py", line 84, in execute_query
    result = frappe.db.sql(query, params, *args, **kwargs)  # nosemgrep
  File "/home/mstfrs/Desktop/ozerpan/apps/frappe/frappe/database/database.py", line 213, in sql
    self.connect()
  File "/home/mstfrs/Desktop/ozerpan/apps/frappe/frappe/database/database.py", line 118, in connect
    self._conn: "MariadbConnection" | "PostgresConnection" = self.get_connection()
  File "/home/mstfrs/Desktop/ozerpan/apps/frappe/frappe/database/mariadb/database.py", line 107, in get_connection
    conn = self._get_connection()
  File "/home/mstfrs/Desktop/ozerpan/apps/frappe/frappe/database/mariadb/database.py", line 113, in _get_connection
    return self.create_connection()
  File "/home/mstfrs/Desktop/ozerpan/apps/frappe/frappe/database/mariadb/database.py", line 116, in create_connection
    return pymysql.connect(**self.get_connection_settings())
  File "/home/mstfrs/Desktop/ozerpan/env/lib/python3.10/site-packages/pymysql/connections.py", line 361, in __init__
    self.connect()
  File "/home/mstfrs/Desktop/ozerpan/env/lib/python3.10/site-packages/pymysql/connections.py", line 669, in connect
    self._request_authentication()
  File "/home/mstfrs/Desktop/ozerpan/env/lib/python3.10/site-packages/pymysql/connections.py", line 957, in _request_authentication
    auth_packet = self._read_packet()
  File "/home/mstfrs/Desktop/ozerpan/env/lib/python3.10/site-packages/pymysql/connections.py", line 775, in _read_packet
    packet.raise_for_error()
  File "/home/mstfrs/Desktop/ozerpan/env/lib/python3.10/site-packages/pymysql/protocol.py", line 219, in raise_for_error
    err.raise_mysql_exception(self._data)
  File "/home/mstfrs/Desktop/ozerpan/env/lib/python3.10/site-packages/pymysql/err.py", line 150, in raise_mysql_exception
    raise errorclass(errno, errval)
pymysql.err.OperationalError: (1049, "Unknown database '_be61cf5335d3ad96'")
2024-10-09 16:24:00,235 ERROR scheduler Exception in Enqueue Events for Site ozerpan
Traceback (most recent call last):
  File "/home/mstfrs/Desktop/ozerpan/apps/frappe/frappe/utils/scheduler.py", line 106, in enqueue_events_for_site
    if is_scheduler_inactive():
  File "/home/mstfrs/Desktop/ozerpan/apps/frappe/frappe/utils/scheduler.py", line 150, in is_scheduler_inactive
    if is_scheduler_disabled(verbose=verbose):
  File "/home/mstfrs/Desktop/ozerpan/apps/frappe/frappe/utils/scheduler.py", line 163, in is_scheduler_disabled
    frappe.db.get_single_value("System Settings", "enable_scheduler")
  File "/home/mstfrs/Desktop/ozerpan/apps/frappe/frappe/database/database.py", line 846, in get_single_value
    ).run()
  File "/home/mstfrs/Desktop/ozerpan/apps/frappe/frappe/query_builder/utils.py", line 84, in execute_query
    result = frappe.db.sql(query, params, *args, **kwargs)  # nosemgrep
  File "/home/mstfrs/Desktop/ozerpan/apps/frappe/frappe/database/database.py", line 213, in sql
    self.connect()
  File "/home/mstfrs/Desktop/ozerpan/apps/frappe/frappe/database/database.py", line 118, in connect
    self._conn: "MariadbConnection" | "PostgresConnection" = self.get_connection()
  File "/home/mstfrs/Desktop/ozerpan/apps/frappe/frappe/database/mariadb/database.py", line 107, in get_connection
    conn = self._get_connection()
  File "/home/mstfrs/Desktop/ozerpan/apps/frappe/frappe/database/mariadb/database.py", line 113, in _get_connection
    return self.create_connection()
  File "/home/mstfrs/Desktop/ozerpan/apps/frappe/frappe/database/mariadb/database.py", line 116, in create_connection
    return pymysql.connect(**self.get_connection_settings())
  File "/home/mstfrs/Desktop/ozerpan/env/lib/python3.10/site-packages/pymysql/connections.py", line 361, in __init__
    self.connect()
  File "/home/mstfrs/Desktop/ozerpan/env/lib/python3.10/site-packages/pymysql/connections.py", line 669, in connect
    self._request_authentication()
  File "/home/mstfrs/Desktop/ozerpan/env/lib/python3.10/site-packages/pymysql/connections.py", line 957, in _request_authentication
    auth_packet = self._read_packet()
  File "/home/mstfrs/Desktop/ozerpan/env/lib/python3.10/site-packages/pymysql/connections.py", line 775, in _read_packet
    packet.raise_for_error()
  File "/home/mstfrs/Desktop/ozerpan/env/lib/python3.10/site-packages/pymysql/protocol.py", line 219, in raise_for_error
    err.raise_mysql_exception(self._data)
  File "/home/mstfrs/Desktop/ozerpan/env/lib/python3.10/site-packages/pymysql/err.py", line 150, in raise_mysql_exception
    raise errorclass(errno, errval)
pymysql.err.OperationalError: (1049, "Unknown database '_be61cf5335d3ad96'")
2024-10-09 16:28:00,786 ERROR scheduler Exception in Enqueue Events for Site ozerpan
Traceback (most recent call last):
  File "/home/mstfrs/Desktop/ozerpan/apps/frappe/frappe/utils/scheduler.py", line 106, in enqueue_events_for_site
    if is_scheduler_inactive():
  File "/home/mstfrs/Desktop/ozerpan/apps/frappe/frappe/utils/scheduler.py", line 150, in is_scheduler_inactive
    if is_scheduler_disabled(verbose=verbose):
  File "/home/mstfrs/Desktop/ozerpan/apps/frappe/frappe/utils/scheduler.py", line 163, in is_scheduler_disabled
    frappe.db.get_single_value("System Settings", "enable_scheduler")
  File "/home/mstfrs/Desktop/ozerpan/apps/frappe/frappe/database/database.py", line 846, in get_single_value
    ).run()
  File "/home/mstfrs/Desktop/ozerpan/apps/frappe/frappe/query_builder/utils.py", line 84, in execute_query
    result = frappe.db.sql(query, params, *args, **kwargs)  # nosemgrep
  File "/home/mstfrs/Desktop/ozerpan/apps/frappe/frappe/database/database.py", line 213, in sql
    self.connect()
  File "/home/mstfrs/Desktop/ozerpan/apps/frappe/frappe/database/database.py", line 118, in connect
    self._conn: "MariadbConnection" | "PostgresConnection" = self.get_connection()
  File "/home/mstfrs/Desktop/ozerpan/apps/frappe/frappe/database/mariadb/database.py", line 107, in get_connection
    conn = self._get_connection()
  File "/home/mstfrs/Desktop/ozerpan/apps/frappe/frappe/database/mariadb/database.py", line 113, in _get_connection
    return self.create_connection()
  File "/home/mstfrs/Desktop/ozerpan/apps/frappe/frappe/database/mariadb/database.py", line 116, in create_connection
    return pymysql.connect(**self.get_connection_settings())
  File "/home/mstfrs/Desktop/ozerpan/env/lib/python3.10/site-packages/pymysql/connections.py", line 361, in __init__
    self.connect()
  File "/home/mstfrs/Desktop/ozerpan/env/lib/python3.10/site-packages/pymysql/connections.py", line 669, in connect
    self._request_authentication()
  File "/home/mstfrs/Desktop/ozerpan/env/lib/python3.10/site-packages/pymysql/connections.py", line 957, in _request_authentication
    auth_packet = self._read_packet()
  File "/home/mstfrs/Desktop/ozerpan/env/lib/python3.10/site-packages/pymysql/connections.py", line 775, in _read_packet
    packet.raise_for_error()
  File "/home/mstfrs/Desktop/ozerpan/env/lib/python3.10/site-packages/pymysql/protocol.py", line 219, in raise_for_error
    err.raise_mysql_exception(self._data)
  File "/home/mstfrs/Desktop/ozerpan/env/lib/python3.10/site-packages/pymysql/err.py", line 150, in raise_mysql_exception
    raise errorclass(errno, errval)
pymysql.err.OperationalError: (1049, "Unknown database '_be61cf5335d3ad96'")
2024-10-09 16:32:00,390 ERROR scheduler Exception in Enqueue Events for Site ozerpan
Traceback (most recent call last):
  File "/home/mstfrs/Desktop/ozerpan/apps/frappe/frappe/utils/scheduler.py", line 106, in enqueue_events_for_site
    if is_scheduler_inactive():
  File "/home/mstfrs/Desktop/ozerpan/apps/frappe/frappe/utils/scheduler.py", line 150, in is_scheduler_inactive
    if is_scheduler_disabled(verbose=verbose):
  File "/home/mstfrs/Desktop/ozerpan/apps/frappe/frappe/utils/scheduler.py", line 163, in is_scheduler_disabled
    frappe.db.get_single_value("System Settings", "enable_scheduler")
  File "/home/mstfrs/Desktop/ozerpan/apps/frappe/frappe/database/database.py", line 846, in get_single_value
    ).run()
  File "/home/mstfrs/Desktop/ozerpan/apps/frappe/frappe/query_builder/utils.py", line 84, in execute_query
    result = frappe.db.sql(query, params, *args, **kwargs)  # nosemgrep
  File "/home/mstfrs/Desktop/ozerpan/apps/frappe/frappe/database/database.py", line 213, in sql
    self.connect()
  File "/home/mstfrs/Desktop/ozerpan/apps/frappe/frappe/database/database.py", line 118, in connect
    self._conn: "MariadbConnection" | "PostgresConnection" = self.get_connection()
  File "/home/mstfrs/Desktop/ozerpan/apps/frappe/frappe/database/mariadb/database.py", line 107, in get_connection
    conn = self._get_connection()
  File "/home/mstfrs/Desktop/ozerpan/apps/frappe/frappe/database/mariadb/database.py", line 113, in _get_connection
    return self.create_connection()
  File "/home/mstfrs/Desktop/ozerpan/apps/frappe/frappe/database/mariadb/database.py", line 116, in create_connection
    return pymysql.connect(**self.get_connection_settings())
  File "/home/mstfrs/Desktop/ozerpan/env/lib/python3.10/site-packages/pymysql/connections.py", line 361, in __init__
    self.connect()
  File "/home/mstfrs/Desktop/ozerpan/env/lib/python3.10/site-packages/pymysql/connections.py", line 669, in connect
    self._request_authentication()
  File "/home/mstfrs/Desktop/ozerpan/env/lib/python3.10/site-packages/pymysql/connections.py", line 957, in _request_authentication
    auth_packet = self._read_packet()
  File "/home/mstfrs/Desktop/ozerpan/env/lib/python3.10/site-packages/pymysql/connections.py", line 775, in _read_packet
    packet.raise_for_error()
  File "/home/mstfrs/Desktop/ozerpan/env/lib/python3.10/site-packages/pymysql/protocol.py", line 219, in raise_for_error
    err.raise_mysql_exception(self._data)
  File "/home/mstfrs/Desktop/ozerpan/env/lib/python3.10/site-packages/pymysql/err.py", line 150, in raise_mysql_exception
    raise errorclass(errno, errval)
pymysql.err.OperationalError: (1049, "Unknown database '_be61cf5335d3ad96'")
2024-10-09 16:36:01,161 ERROR scheduler Exception in Enqueue Events for Site ozerpan
Traceback (most recent call last):
  File "/home/mstfrs/Desktop/ozerpan/apps/frappe/frappe/utils/scheduler.py", line 106, in enqueue_events_for_site
    if is_scheduler_inactive():
  File "/home/mstfrs/Desktop/ozerpan/apps/frappe/frappe/utils/scheduler.py", line 150, in is_scheduler_inactive
    if is_scheduler_disabled(verbose=verbose):
  File "/home/mstfrs/Desktop/ozerpan/apps/frappe/frappe/utils/scheduler.py", line 163, in is_scheduler_disabled
    frappe.db.get_single_value("System Settings", "enable_scheduler")
  File "/home/mstfrs/Desktop/ozerpan/apps/frappe/frappe/database/database.py", line 846, in get_single_value
    ).run()
  File "/home/mstfrs/Desktop/ozerpan/apps/frappe/frappe/query_builder/utils.py", line 84, in execute_query
    result = frappe.db.sql(query, params, *args, **kwargs)  # nosemgrep
  File "/home/mstfrs/Desktop/ozerpan/apps/frappe/frappe/database/database.py", line 213, in sql
    self.connect()
  File "/home/mstfrs/Desktop/ozerpan/apps/frappe/frappe/database/database.py", line 118, in connect
    self._conn: "MariadbConnection" | "PostgresConnection" = self.get_connection()
  File "/home/mstfrs/Desktop/ozerpan/apps/frappe/frappe/database/mariadb/database.py", line 107, in get_connection
    conn = self._get_connection()
  File "/home/mstfrs/Desktop/ozerpan/apps/frappe/frappe/database/mariadb/database.py", line 113, in _get_connection
    return self.create_connection()
  File "/home/mstfrs/Desktop/ozerpan/apps/frappe/frappe/database/mariadb/database.py", line 116, in create_connection
    return pymysql.connect(**self.get_connection_settings())
  File "/home/mstfrs/Desktop/ozerpan/env/lib/python3.10/site-packages/pymysql/connections.py", line 361, in __init__
    self.connect()
  File "/home/mstfrs/Desktop/ozerpan/env/lib/python3.10/site-packages/pymysql/connections.py", line 669, in connect
    self._request_authentication()
  File "/home/mstfrs/Desktop/ozerpan/env/lib/python3.10/site-packages/pymysql/connections.py", line 957, in _request_authentication
    auth_packet = self._read_packet()
  File "/home/mstfrs/Desktop/ozerpan/env/lib/python3.10/site-packages/pymysql/connections.py", line 775, in _read_packet
    packet.raise_for_error()
  File "/home/mstfrs/Desktop/ozerpan/env/lib/python3.10/site-packages/pymysql/protocol.py", line 219, in raise_for_error
    err.raise_mysql_exception(self._data)
  File "/home/mstfrs/Desktop/ozerpan/env/lib/python3.10/site-packages/pymysql/err.py", line 150, in raise_mysql_exception
    raise errorclass(errno, errval)
pymysql.err.OperationalError: (1049, "Unknown database '_be61cf5335d3ad96'")
2024-10-09 16:40:00,288 ERROR scheduler Exception in Enqueue Events for Site ozerpan
Traceback (most recent call last):
  File "/home/mstfrs/Desktop/ozerpan/apps/frappe/frappe/utils/scheduler.py", line 106, in enqueue_events_for_site
    if is_scheduler_inactive():
  File "/home/mstfrs/Desktop/ozerpan/apps/frappe/frappe/utils/scheduler.py", line 150, in is_scheduler_inactive
    if is_scheduler_disabled(verbose=verbose):
  File "/home/mstfrs/Desktop/ozerpan/apps/frappe/frappe/utils/scheduler.py", line 163, in is_scheduler_disabled
    frappe.db.get_single_value("System Settings", "enable_scheduler")
  File "/home/mstfrs/Desktop/ozerpan/apps/frappe/frappe/database/database.py", line 846, in get_single_value
    ).run()
  File "/home/mstfrs/Desktop/ozerpan/apps/frappe/frappe/query_builder/utils.py", line 84, in execute_query
    result = frappe.db.sql(query, params, *args, **kwargs)  # nosemgrep
  File "/home/mstfrs/Desktop/ozerpan/apps/frappe/frappe/database/database.py", line 213, in sql
    self.connect()
  File "/home/mstfrs/Desktop/ozerpan/apps/frappe/frappe/database/database.py", line 118, in connect
    self._conn: "MariadbConnection" | "PostgresConnection" = self.get_connection()
  File "/home/mstfrs/Desktop/ozerpan/apps/frappe/frappe/database/mariadb/database.py", line 107, in get_connection
    conn = self._get_connection()
  File "/home/mstfrs/Desktop/ozerpan/apps/frappe/frappe/database/mariadb/database.py", line 113, in _get_connection
    return self.create_connection()
  File "/home/mstfrs/Desktop/ozerpan/apps/frappe/frappe/database/mariadb/database.py", line 116, in create_connection
    return pymysql.connect(**self.get_connection_settings())
  File "/home/mstfrs/Desktop/ozerpan/env/lib/python3.10/site-packages/pymysql/connections.py", line 361, in __init__
    self.connect()
  File "/home/mstfrs/Desktop/ozerpan/env/lib/python3.10/site-packages/pymysql/connections.py", line 669, in connect
    self._request_authentication()
  File "/home/mstfrs/Desktop/ozerpan/env/lib/python3.10/site-packages/pymysql/connections.py", line 957, in _request_authentication
    auth_packet = self._read_packet()
  File "/home/mstfrs/Desktop/ozerpan/env/lib/python3.10/site-packages/pymysql/connections.py", line 775, in _read_packet
    packet.raise_for_error()
  File "/home/mstfrs/Desktop/ozerpan/env/lib/python3.10/site-packages/pymysql/protocol.py", line 219, in raise_for_error
    err.raise_mysql_exception(self._data)
  File "/home/mstfrs/Desktop/ozerpan/env/lib/python3.10/site-packages/pymysql/err.py", line 150, in raise_mysql_exception
    raise errorclass(errno, errval)
pymysql.err.OperationalError: (1049, "Unknown database '_be61cf5335d3ad96'")
2024-10-09 16:44:01,136 ERROR scheduler Exception in Enqueue Events for Site ozerpan
Traceback (most recent call last):
  File "/home/mstfrs/Desktop/ozerpan/apps/frappe/frappe/utils/scheduler.py", line 106, in enqueue_events_for_site
    if is_scheduler_inactive():
  File "/home/mstfrs/Desktop/ozerpan/apps/frappe/frappe/utils/scheduler.py", line 150, in is_scheduler_inactive
    if is_scheduler_disabled(verbose=verbose):
  File "/home/mstfrs/Desktop/ozerpan/apps/frappe/frappe/utils/scheduler.py", line 163, in is_scheduler_disabled
    frappe.db.get_single_value("System Settings", "enable_scheduler")
  File "/home/mstfrs/Desktop/ozerpan/apps/frappe/frappe/database/database.py", line 846, in get_single_value
    ).run()
  File "/home/mstfrs/Desktop/ozerpan/apps/frappe/frappe/query_builder/utils.py", line 84, in execute_query
    result = frappe.db.sql(query, params, *args, **kwargs)  # nosemgrep
  File "/home/mstfrs/Desktop/ozerpan/apps/frappe/frappe/database/database.py", line 213, in sql
    self.connect()
  File "/home/mstfrs/Desktop/ozerpan/apps/frappe/frappe/database/database.py", line 118, in connect
    self._conn: "MariadbConnection" | "PostgresConnection" = self.get_connection()
  File "/home/mstfrs/Desktop/ozerpan/apps/frappe/frappe/database/mariadb/database.py", line 107, in get_connection
    conn = self._get_connection()
  File "/home/mstfrs/Desktop/ozerpan/apps/frappe/frappe/database/mariadb/database.py", line 113, in _get_connection
    return self.create_connection()
  File "/home/mstfrs/Desktop/ozerpan/apps/frappe/frappe/database/mariadb/database.py", line 116, in create_connection
    return pymysql.connect(**self.get_connection_settings())
  File "/home/mstfrs/Desktop/ozerpan/env/lib/python3.10/site-packages/pymysql/connections.py", line 361, in __init__
    self.connect()
  File "/home/mstfrs/Desktop/ozerpan/env/lib/python3.10/site-packages/pymysql/connections.py", line 669, in connect
    self._request_authentication()
  File "/home/mstfrs/Desktop/ozerpan/env/lib/python3.10/site-packages/pymysql/connections.py", line 957, in _request_authentication
    auth_packet = self._read_packet()
  File "/home/mstfrs/Desktop/ozerpan/env/lib/python3.10/site-packages/pymysql/connections.py", line 775, in _read_packet
    packet.raise_for_error()
  File "/home/mstfrs/Desktop/ozerpan/env/lib/python3.10/site-packages/pymysql/protocol.py", line 219, in raise_for_error
    err.raise_mysql_exception(self._data)
  File "/home/mstfrs/Desktop/ozerpan/env/lib/python3.10/site-packages/pymysql/err.py", line 150, in raise_mysql_exception
    raise errorclass(errno, errval)
pymysql.err.OperationalError: (1049, "Unknown database '_be61cf5335d3ad96'")
2024-10-09 16:48:00,860 ERROR scheduler Exception in Enqueue Events for Site ozerpan
Traceback (most recent call last):
  File "/home/mstfrs/Desktop/ozerpan/apps/frappe/frappe/utils/scheduler.py", line 106, in enqueue_events_for_site
    if is_scheduler_inactive():
  File "/home/mstfrs/Desktop/ozerpan/apps/frappe/frappe/utils/scheduler.py", line 150, in is_scheduler_inactive
    if is_scheduler_disabled(verbose=verbose):
  File "/home/mstfrs/Desktop/ozerpan/apps/frappe/frappe/utils/scheduler.py", line 163, in is_scheduler_disabled
    frappe.db.get_single_value("System Settings", "enable_scheduler")
  File "/home/mstfrs/Desktop/ozerpan/apps/frappe/frappe/database/database.py", line 846, in get_single_value
    ).run()
  File "/home/mstfrs/Desktop/ozerpan/apps/frappe/frappe/query_builder/utils.py", line 84, in execute_query
    result = frappe.db.sql(query, params, *args, **kwargs)  # nosemgrep
  File "/home/mstfrs/Desktop/ozerpan/apps/frappe/frappe/database/database.py", line 213, in sql
    self.connect()
  File "/home/mstfrs/Desktop/ozerpan/apps/frappe/frappe/database/database.py", line 118, in connect
    self._conn: "MariadbConnection" | "PostgresConnection" = self.get_connection()
  File "/home/mstfrs/Desktop/ozerpan/apps/frappe/frappe/database/mariadb/database.py", line 107, in get_connection
    conn = self._get_connection()
  File "/home/mstfrs/Desktop/ozerpan/apps/frappe/frappe/database/mariadb/database.py", line 113, in _get_connection
    return self.create_connection()
  File "/home/mstfrs/Desktop/ozerpan/apps/frappe/frappe/database/mariadb/database.py", line 116, in create_connection
    return pymysql.connect(**self.get_connection_settings())
  File "/home/mstfrs/Desktop/ozerpan/env/lib/python3.10/site-packages/pymysql/connections.py", line 361, in __init__
    self.connect()
  File "/home/mstfrs/Desktop/ozerpan/env/lib/python3.10/site-packages/pymysql/connections.py", line 669, in connect
    self._request_authentication()
  File "/home/mstfrs/Desktop/ozerpan/env/lib/python3.10/site-packages/pymysql/connections.py", line 957, in _request_authentication
    auth_packet = self._read_packet()
  File "/home/mstfrs/Desktop/ozerpan/env/lib/python3.10/site-packages/pymysql/connections.py", line 775, in _read_packet
    packet.raise_for_error()
  File "/home/mstfrs/Desktop/ozerpan/env/lib/python3.10/site-packages/pymysql/protocol.py", line 219, in raise_for_error
    err.raise_mysql_exception(self._data)
  File "/home/mstfrs/Desktop/ozerpan/env/lib/python3.10/site-packages/pymysql/err.py", line 150, in raise_mysql_exception
    raise errorclass(errno, errval)
pymysql.err.OperationalError: (1049, "Unknown database '_be61cf5335d3ad96'")
2024-10-09 16:52:00,893 ERROR scheduler Exception in Enqueue Events for Site ozerpan
Traceback (most recent call last):
  File "/home/mstfrs/Desktop/ozerpan/apps/frappe/frappe/utils/scheduler.py", line 106, in enqueue_events_for_site
    if is_scheduler_inactive():
  File "/home/mstfrs/Desktop/ozerpan/apps/frappe/frappe/utils/scheduler.py", line 150, in is_scheduler_inactive
    if is_scheduler_disabled(verbose=verbose):
  File "/home/mstfrs/Desktop/ozerpan/apps/frappe/frappe/utils/scheduler.py", line 163, in is_scheduler_disabled
    frappe.db.get_single_value("System Settings", "enable_scheduler")
  File "/home/mstfrs/Desktop/ozerpan/apps/frappe/frappe/database/database.py", line 846, in get_single_value
    ).run()
  File "/home/mstfrs/Desktop/ozerpan/apps/frappe/frappe/query_builder/utils.py", line 84, in execute_query
    result = frappe.db.sql(query, params, *args, **kwargs)  # nosemgrep
  File "/home/mstfrs/Desktop/ozerpan/apps/frappe/frappe/database/database.py", line 213, in sql
    self.connect()
  File "/home/mstfrs/Desktop/ozerpan/apps/frappe/frappe/database/database.py", line 118, in connect
    self._conn: "MariadbConnection" | "PostgresConnection" = self.get_connection()
  File "/home/mstfrs/Desktop/ozerpan/apps/frappe/frappe/database/mariadb/database.py", line 107, in get_connection
    conn = self._get_connection()
  File "/home/mstfrs/Desktop/ozerpan/apps/frappe/frappe/database/mariadb/database.py", line 113, in _get_connection
    return self.create_connection()
  File "/home/mstfrs/Desktop/ozerpan/apps/frappe/frappe/database/mariadb/database.py", line 116, in create_connection
    return pymysql.connect(**self.get_connection_settings())
  File "/home/mstfrs/Desktop/ozerpan/env/lib/python3.10/site-packages/pymysql/connections.py", line 361, in __init__
    self.connect()
  File "/home/mstfrs/Desktop/ozerpan/env/lib/python3.10/site-packages/pymysql/connections.py", line 669, in connect
    self._request_authentication()
  File "/home/mstfrs/Desktop/ozerpan/env/lib/python3.10/site-packages/pymysql/connections.py", line 957, in _request_authentication
    auth_packet = self._read_packet()
  File "/home/mstfrs/Desktop/ozerpan/env/lib/python3.10/site-packages/pymysql/connections.py", line 775, in _read_packet
    packet.raise_for_error()
  File "/home/mstfrs/Desktop/ozerpan/env/lib/python3.10/site-packages/pymysql/protocol.py", line 219, in raise_for_error
    err.raise_mysql_exception(self._data)
  File "/home/mstfrs/Desktop/ozerpan/env/lib/python3.10/site-packages/pymysql/err.py", line 150, in raise_mysql_exception
    raise errorclass(errno, errval)
pymysql.err.OperationalError: (1049, "Unknown database '_be61cf5335d3ad96'")
2024-10-09 16:56:00,459 ERROR scheduler Exception in Enqueue Events for Site ozerpan
Traceback (most recent call last):
  File "/home/mstfrs/Desktop/ozerpan/apps/frappe/frappe/utils/scheduler.py", line 106, in enqueue_events_for_site
    if is_scheduler_inactive():
  File "/home/mstfrs/Desktop/ozerpan/apps/frappe/frappe/utils/scheduler.py", line 150, in is_scheduler_inactive
    if is_scheduler_disabled(verbose=verbose):
  File "/home/mstfrs/Desktop/ozerpan/apps/frappe/frappe/utils/scheduler.py", line 163, in is_scheduler_disabled
    frappe.db.get_single_value("System Settings", "enable_scheduler")
  File "/home/mstfrs/Desktop/ozerpan/apps/frappe/frappe/database/database.py", line 846, in get_single_value
    ).run()
  File "/home/mstfrs/Desktop/ozerpan/apps/frappe/frappe/query_builder/utils.py", line 84, in execute_query
    result = frappe.db.sql(query, params, *args, **kwargs)  # nosemgrep
  File "/home/mstfrs/Desktop/ozerpan/apps/frappe/frappe/database/database.py", line 213, in sql
    self.connect()
  File "/home/mstfrs/Desktop/ozerpan/apps/frappe/frappe/database/database.py", line 118, in connect
    self._conn: "MariadbConnection" | "PostgresConnection" = self.get_connection()
  File "/home/mstfrs/Desktop/ozerpan/apps/frappe/frappe/database/mariadb/database.py", line 107, in get_connection
    conn = self._get_connection()
  File "/home/mstfrs/Desktop/ozerpan/apps/frappe/frappe/database/mariadb/database.py", line 113, in _get_connection
    return self.create_connection()
  File "/home/mstfrs/Desktop/ozerpan/apps/frappe/frappe/database/mariadb/database.py", line 116, in create_connection
    return pymysql.connect(**self.get_connection_settings())
  File "/home/mstfrs/Desktop/ozerpan/env/lib/python3.10/site-packages/pymysql/connections.py", line 361, in __init__
    self.connect()
  File "/home/mstfrs/Desktop/ozerpan/env/lib/python3.10/site-packages/pymysql/connections.py", line 669, in connect
    self._request_authentication()
  File "/home/mstfrs/Desktop/ozerpan/env/lib/python3.10/site-packages/pymysql/connections.py", line 957, in _request_authentication
    auth_packet = self._read_packet()
  File "/home/mstfrs/Desktop/ozerpan/env/lib/python3.10/site-packages/pymysql/connections.py", line 775, in _read_packet
    packet.raise_for_error()
  File "/home/mstfrs/Desktop/ozerpan/env/lib/python3.10/site-packages/pymysql/protocol.py", line 219, in raise_for_error
    err.raise_mysql_exception(self._data)
  File "/home/mstfrs/Desktop/ozerpan/env/lib/python3.10/site-packages/pymysql/err.py", line 150, in raise_mysql_exception
    raise errorclass(errno, errval)
pymysql.err.OperationalError: (1049, "Unknown database '_be61cf5335d3ad96'")
2024-10-09 17:00:00,767 ERROR scheduler Exception in Enqueue Events for Site ozerpan
Traceback (most recent call last):
  File "/home/mstfrs/Desktop/ozerpan/apps/frappe/frappe/utils/scheduler.py", line 106, in enqueue_events_for_site
    if is_scheduler_inactive():
  File "/home/mstfrs/Desktop/ozerpan/apps/frappe/frappe/utils/scheduler.py", line 150, in is_scheduler_inactive
    if is_scheduler_disabled(verbose=verbose):
  File "/home/mstfrs/Desktop/ozerpan/apps/frappe/frappe/utils/scheduler.py", line 163, in is_scheduler_disabled
    frappe.db.get_single_value("System Settings", "enable_scheduler")
  File "/home/mstfrs/Desktop/ozerpan/apps/frappe/frappe/database/database.py", line 846, in get_single_value
    ).run()
  File "/home/mstfrs/Desktop/ozerpan/apps/frappe/frappe/query_builder/utils.py", line 84, in execute_query
    result = frappe.db.sql(query, params, *args, **kwargs)  # nosemgrep
  File "/home/mstfrs/Desktop/ozerpan/apps/frappe/frappe/database/database.py", line 213, in sql
    self.connect()
  File "/home/mstfrs/Desktop/ozerpan/apps/frappe/frappe/database/database.py", line 118, in connect
    self._conn: "MariadbConnection" | "PostgresConnection" = self.get_connection()
  File "/home/mstfrs/Desktop/ozerpan/apps/frappe/frappe/database/mariadb/database.py", line 107, in get_connection
    conn = self._get_connection()
  File "/home/mstfrs/Desktop/ozerpan/apps/frappe/frappe/database/mariadb/database.py", line 113, in _get_connection
    return self.create_connection()
  File "/home/mstfrs/Desktop/ozerpan/apps/frappe/frappe/database/mariadb/database.py", line 116, in create_connection
    return pymysql.connect(**self.get_connection_settings())
  File "/home/mstfrs/Desktop/ozerpan/env/lib/python3.10/site-packages/pymysql/connections.py", line 361, in __init__
    self.connect()
  File "/home/mstfrs/Desktop/ozerpan/env/lib/python3.10/site-packages/pymysql/connections.py", line 669, in connect
    self._request_authentication()
  File "/home/mstfrs/Desktop/ozerpan/env/lib/python3.10/site-packages/pymysql/connections.py", line 957, in _request_authentication
    auth_packet = self._read_packet()
  File "/home/mstfrs/Desktop/ozerpan/env/lib/python3.10/site-packages/pymysql/connections.py", line 775, in _read_packet
    packet.raise_for_error()
  File "/home/mstfrs/Desktop/ozerpan/env/lib/python3.10/site-packages/pymysql/protocol.py", line 219, in raise_for_error
    err.raise_mysql_exception(self._data)
  File "/home/mstfrs/Desktop/ozerpan/env/lib/python3.10/site-packages/pymysql/err.py", line 150, in raise_mysql_exception
    raise errorclass(errno, errval)
pymysql.err.OperationalError: (1049, "Unknown database '_be61cf5335d3ad96'")
2024-10-09 17:04:02,072 ERROR scheduler Exception in Enqueue Events for Site ozerpan
Traceback (most recent call last):
  File "/home/mstfrs/Desktop/ozerpan/apps/frappe/frappe/utils/scheduler.py", line 106, in enqueue_events_for_site
    if is_scheduler_inactive():
  File "/home/mstfrs/Desktop/ozerpan/apps/frappe/frappe/utils/scheduler.py", line 150, in is_scheduler_inactive
    if is_scheduler_disabled(verbose=verbose):
  File "/home/mstfrs/Desktop/ozerpan/apps/frappe/frappe/utils/scheduler.py", line 163, in is_scheduler_disabled
    frappe.db.get_single_value("System Settings", "enable_scheduler")
  File "/home/mstfrs/Desktop/ozerpan/apps/frappe/frappe/database/database.py", line 846, in get_single_value
    ).run()
  File "/home/mstfrs/Desktop/ozerpan/apps/frappe/frappe/query_builder/utils.py", line 84, in execute_query
    result = frappe.db.sql(query, params, *args, **kwargs)  # nosemgrep
  File "/home/mstfrs/Desktop/ozerpan/apps/frappe/frappe/database/database.py", line 213, in sql
    self.connect()
  File "/home/mstfrs/Desktop/ozerpan/apps/frappe/frappe/database/database.py", line 118, in connect
    self._conn: "MariadbConnection" | "PostgresConnection" = self.get_connection()
  File "/home/mstfrs/Desktop/ozerpan/apps/frappe/frappe/database/mariadb/database.py", line 107, in get_connection
    conn = self._get_connection()
  File "/home/mstfrs/Desktop/ozerpan/apps/frappe/frappe/database/mariadb/database.py", line 113, in _get_connection
    return self.create_connection()
  File "/home/mstfrs/Desktop/ozerpan/apps/frappe/frappe/database/mariadb/database.py", line 116, in create_connection
    return pymysql.connect(**self.get_connection_settings())
  File "/home/mstfrs/Desktop/ozerpan/env/lib/python3.10/site-packages/pymysql/connections.py", line 361, in __init__
    self.connect()
  File "/home/mstfrs/Desktop/ozerpan/env/lib/python3.10/site-packages/pymysql/connections.py", line 669, in connect
    self._request_authentication()
  File "/home/mstfrs/Desktop/ozerpan/env/lib/python3.10/site-packages/pymysql/connections.py", line 957, in _request_authentication
    auth_packet = self._read_packet()
  File "/home/mstfrs/Desktop/ozerpan/env/lib/python3.10/site-packages/pymysql/connections.py", line 775, in _read_packet
    packet.raise_for_error()
  File "/home/mstfrs/Desktop/ozerpan/env/lib/python3.10/site-packages/pymysql/protocol.py", line 219, in raise_for_error
    err.raise_mysql_exception(self._data)
  File "/home/mstfrs/Desktop/ozerpan/env/lib/python3.10/site-packages/pymysql/err.py", line 150, in raise_mysql_exception
    raise errorclass(errno, errval)
pymysql.err.OperationalError: (1049, "Unknown database '_be61cf5335d3ad96'")
2024-10-09 17:08:05,794 ERROR scheduler Exception in Enqueue Events for Site ozerpan
Traceback (most recent call last):
  File "/home/mstfrs/Desktop/ozerpan/apps/frappe/frappe/utils/scheduler.py", line 106, in enqueue_events_for_site
    if is_scheduler_inactive():
  File "/home/mstfrs/Desktop/ozerpan/apps/frappe/frappe/utils/scheduler.py", line 150, in is_scheduler_inactive
    if is_scheduler_disabled(verbose=verbose):
  File "/home/mstfrs/Desktop/ozerpan/apps/frappe/frappe/utils/scheduler.py", line 163, in is_scheduler_disabled
    frappe.db.get_single_value("System Settings", "enable_scheduler")
  File "/home/mstfrs/Desktop/ozerpan/apps/frappe/frappe/database/database.py", line 846, in get_single_value
    ).run()
  File "/home/mstfrs/Desktop/ozerpan/apps/frappe/frappe/query_builder/utils.py", line 84, in execute_query
    result = frappe.db.sql(query, params, *args, **kwargs)  # nosemgrep
  File "/home/mstfrs/Desktop/ozerpan/apps/frappe/frappe/database/database.py", line 213, in sql
    self.connect()
  File "/home/mstfrs/Desktop/ozerpan/apps/frappe/frappe/database/database.py", line 118, in connect
    self._conn: "MariadbConnection" | "PostgresConnection" = self.get_connection()
  File "/home/mstfrs/Desktop/ozerpan/apps/frappe/frappe/database/mariadb/database.py", line 107, in get_connection
    conn = self._get_connection()
  File "/home/mstfrs/Desktop/ozerpan/apps/frappe/frappe/database/mariadb/database.py", line 113, in _get_connection
    return self.create_connection()
  File "/home/mstfrs/Desktop/ozerpan/apps/frappe/frappe/database/mariadb/database.py", line 116, in create_connection
    return pymysql.connect(**self.get_connection_settings())
  File "/home/mstfrs/Desktop/ozerpan/env/lib/python3.10/site-packages/pymysql/connections.py", line 361, in __init__
    self.connect()
  File "/home/mstfrs/Desktop/ozerpan/env/lib/python3.10/site-packages/pymysql/connections.py", line 669, in connect
    self._request_authentication()
  File "/home/mstfrs/Desktop/ozerpan/env/lib/python3.10/site-packages/pymysql/connections.py", line 957, in _request_authentication
    auth_packet = self._read_packet()
  File "/home/mstfrs/Desktop/ozerpan/env/lib/python3.10/site-packages/pymysql/connections.py", line 775, in _read_packet
    packet.raise_for_error()
  File "/home/mstfrs/Desktop/ozerpan/env/lib/python3.10/site-packages/pymysql/protocol.py", line 219, in raise_for_error
    err.raise_mysql_exception(self._data)
  File "/home/mstfrs/Desktop/ozerpan/env/lib/python3.10/site-packages/pymysql/err.py", line 150, in raise_mysql_exception
    raise errorclass(errno, errval)
pymysql.err.OperationalError: (1049, "Unknown database '_be61cf5335d3ad96'")
2024-10-09 17:12:00,322 ERROR scheduler Exception in Enqueue Events for Site ozerpan
Traceback (most recent call last):
  File "/home/mstfrs/Desktop/ozerpan/apps/frappe/frappe/utils/scheduler.py", line 106, in enqueue_events_for_site
    if is_scheduler_inactive():
  File "/home/mstfrs/Desktop/ozerpan/apps/frappe/frappe/utils/scheduler.py", line 150, in is_scheduler_inactive
    if is_scheduler_disabled(verbose=verbose):
  File "/home/mstfrs/Desktop/ozerpan/apps/frappe/frappe/utils/scheduler.py", line 163, in is_scheduler_disabled
    frappe.db.get_single_value("System Settings", "enable_scheduler")
  File "/home/mstfrs/Desktop/ozerpan/apps/frappe/frappe/database/database.py", line 846, in get_single_value
    ).run()
  File "/home/mstfrs/Desktop/ozerpan/apps/frappe/frappe/query_builder/utils.py", line 84, in execute_query
    result = frappe.db.sql(query, params, *args, **kwargs)  # nosemgrep
  File "/home/mstfrs/Desktop/ozerpan/apps/frappe/frappe/database/database.py", line 213, in sql
    self.connect()
  File "/home/mstfrs/Desktop/ozerpan/apps/frappe/frappe/database/database.py", line 118, in connect
    self._conn: "MariadbConnection" | "PostgresConnection" = self.get_connection()
  File "/home/mstfrs/Desktop/ozerpan/apps/frappe/frappe/database/mariadb/database.py", line 107, in get_connection
    conn = self._get_connection()
  File "/home/mstfrs/Desktop/ozerpan/apps/frappe/frappe/database/mariadb/database.py", line 113, in _get_connection
    return self.create_connection()
  File "/home/mstfrs/Desktop/ozerpan/apps/frappe/frappe/database/mariadb/database.py", line 116, in create_connection
    return pymysql.connect(**self.get_connection_settings())
  File "/home/mstfrs/Desktop/ozerpan/env/lib/python3.10/site-packages/pymysql/connections.py", line 361, in __init__
    self.connect()
  File "/home/mstfrs/Desktop/ozerpan/env/lib/python3.10/site-packages/pymysql/connections.py", line 669, in connect
    self._request_authentication()
  File "/home/mstfrs/Desktop/ozerpan/env/lib/python3.10/site-packages/pymysql/connections.py", line 957, in _request_authentication
    auth_packet = self._read_packet()
  File "/home/mstfrs/Desktop/ozerpan/env/lib/python3.10/site-packages/pymysql/connections.py", line 775, in _read_packet
    packet.raise_for_error()
  File "/home/mstfrs/Desktop/ozerpan/env/lib/python3.10/site-packages/pymysql/protocol.py", line 219, in raise_for_error
    err.raise_mysql_exception(self._data)
  File "/home/mstfrs/Desktop/ozerpan/env/lib/python3.10/site-packages/pymysql/err.py", line 150, in raise_mysql_exception
    raise errorclass(errno, errval)
pymysql.err.OperationalError: (1049, "Unknown database '_be61cf5335d3ad96'")
2024-10-09 17:16:01,296 ERROR scheduler Exception in Enqueue Events for Site ozerpan
Traceback (most recent call last):
  File "/home/mstfrs/Desktop/ozerpan/apps/frappe/frappe/utils/scheduler.py", line 106, in enqueue_events_for_site
    if is_scheduler_inactive():
  File "/home/mstfrs/Desktop/ozerpan/apps/frappe/frappe/utils/scheduler.py", line 150, in is_scheduler_inactive
    if is_scheduler_disabled(verbose=verbose):
  File "/home/mstfrs/Desktop/ozerpan/apps/frappe/frappe/utils/scheduler.py", line 163, in is_scheduler_disabled
    frappe.db.get_single_value("System Settings", "enable_scheduler")
  File "/home/mstfrs/Desktop/ozerpan/apps/frappe/frappe/database/database.py", line 846, in get_single_value
    ).run()
  File "/home/mstfrs/Desktop/ozerpan/apps/frappe/frappe/query_builder/utils.py", line 84, in execute_query
    result = frappe.db.sql(query, params, *args, **kwargs)  # nosemgrep
  File "/home/mstfrs/Desktop/ozerpan/apps/frappe/frappe/database/database.py", line 213, in sql
    self.connect()
  File "/home/mstfrs/Desktop/ozerpan/apps/frappe/frappe/database/database.py", line 118, in connect
    self._conn: "MariadbConnection" | "PostgresConnection" = self.get_connection()
  File "/home/mstfrs/Desktop/ozerpan/apps/frappe/frappe/database/mariadb/database.py", line 107, in get_connection
    conn = self._get_connection()
  File "/home/mstfrs/Desktop/ozerpan/apps/frappe/frappe/database/mariadb/database.py", line 113, in _get_connection
    return self.create_connection()
  File "/home/mstfrs/Desktop/ozerpan/apps/frappe/frappe/database/mariadb/database.py", line 116, in create_connection
    return pymysql.connect(**self.get_connection_settings())
  File "/home/mstfrs/Desktop/ozerpan/env/lib/python3.10/site-packages/pymysql/connections.py", line 361, in __init__
    self.connect()
  File "/home/mstfrs/Desktop/ozerpan/env/lib/python3.10/site-packages/pymysql/connections.py", line 669, in connect
    self._request_authentication()
  File "/home/mstfrs/Desktop/ozerpan/env/lib/python3.10/site-packages/pymysql/connections.py", line 957, in _request_authentication
    auth_packet = self._read_packet()
  File "/home/mstfrs/Desktop/ozerpan/env/lib/python3.10/site-packages/pymysql/connections.py", line 775, in _read_packet
    packet.raise_for_error()
  File "/home/mstfrs/Desktop/ozerpan/env/lib/python3.10/site-packages/pymysql/protocol.py", line 219, in raise_for_error
    err.raise_mysql_exception(self._data)
  File "/home/mstfrs/Desktop/ozerpan/env/lib/python3.10/site-packages/pymysql/err.py", line 150, in raise_mysql_exception
    raise errorclass(errno, errval)
pymysql.err.OperationalError: (1049, "Unknown database '_be61cf5335d3ad96'")
2024-10-09 17:20:00,399 ERROR scheduler Exception in Enqueue Events for Site ozerpan
Traceback (most recent call last):
  File "/home/mstfrs/Desktop/ozerpan/apps/frappe/frappe/utils/scheduler.py", line 106, in enqueue_events_for_site
    if is_scheduler_inactive():
  File "/home/mstfrs/Desktop/ozerpan/apps/frappe/frappe/utils/scheduler.py", line 150, in is_scheduler_inactive
    if is_scheduler_disabled(verbose=verbose):
  File "/home/mstfrs/Desktop/ozerpan/apps/frappe/frappe/utils/scheduler.py", line 163, in is_scheduler_disabled
    frappe.db.get_single_value("System Settings", "enable_scheduler")
  File "/home/mstfrs/Desktop/ozerpan/apps/frappe/frappe/database/database.py", line 846, in get_single_value
    ).run()
  File "/home/mstfrs/Desktop/ozerpan/apps/frappe/frappe/query_builder/utils.py", line 84, in execute_query
    result = frappe.db.sql(query, params, *args, **kwargs)  # nosemgrep
  File "/home/mstfrs/Desktop/ozerpan/apps/frappe/frappe/database/database.py", line 213, in sql
    self.connect()
  File "/home/mstfrs/Desktop/ozerpan/apps/frappe/frappe/database/database.py", line 118, in connect
    self._conn: "MariadbConnection" | "PostgresConnection" = self.get_connection()
  File "/home/mstfrs/Desktop/ozerpan/apps/frappe/frappe/database/mariadb/database.py", line 107, in get_connection
    conn = self._get_connection()
  File "/home/mstfrs/Desktop/ozerpan/apps/frappe/frappe/database/mariadb/database.py", line 113, in _get_connection
    return self.create_connection()
  File "/home/mstfrs/Desktop/ozerpan/apps/frappe/frappe/database/mariadb/database.py", line 116, in create_connection
    return pymysql.connect(**self.get_connection_settings())
  File "/home/mstfrs/Desktop/ozerpan/env/lib/python3.10/site-packages/pymysql/connections.py", line 361, in __init__
    self.connect()
  File "/home/mstfrs/Desktop/ozerpan/env/lib/python3.10/site-packages/pymysql/connections.py", line 669, in connect
    self._request_authentication()
  File "/home/mstfrs/Desktop/ozerpan/env/lib/python3.10/site-packages/pymysql/connections.py", line 957, in _request_authentication
    auth_packet = self._read_packet()
  File "/home/mstfrs/Desktop/ozerpan/env/lib/python3.10/site-packages/pymysql/connections.py", line 775, in _read_packet
    packet.raise_for_error()
  File "/home/mstfrs/Desktop/ozerpan/env/lib/python3.10/site-packages/pymysql/protocol.py", line 219, in raise_for_error
    err.raise_mysql_exception(self._data)
  File "/home/mstfrs/Desktop/ozerpan/env/lib/python3.10/site-packages/pymysql/err.py", line 150, in raise_mysql_exception
    raise errorclass(errno, errval)
pymysql.err.OperationalError: (1049, "Unknown database '_be61cf5335d3ad96'")
2024-10-09 17:24:01,140 ERROR scheduler Exception in Enqueue Events for Site ozerpan
Traceback (most recent call last):
  File "/home/mstfrs/Desktop/ozerpan/apps/frappe/frappe/utils/scheduler.py", line 106, in enqueue_events_for_site
    if is_scheduler_inactive():
  File "/home/mstfrs/Desktop/ozerpan/apps/frappe/frappe/utils/scheduler.py", line 150, in is_scheduler_inactive
    if is_scheduler_disabled(verbose=verbose):
  File "/home/mstfrs/Desktop/ozerpan/apps/frappe/frappe/utils/scheduler.py", line 163, in is_scheduler_disabled
    frappe.db.get_single_value("System Settings", "enable_scheduler")
  File "/home/mstfrs/Desktop/ozerpan/apps/frappe/frappe/database/database.py", line 846, in get_single_value
    ).run()
  File "/home/mstfrs/Desktop/ozerpan/apps/frappe/frappe/query_builder/utils.py", line 84, in execute_query
    result = frappe.db.sql(query, params, *args, **kwargs)  # nosemgrep
  File "/home/mstfrs/Desktop/ozerpan/apps/frappe/frappe/database/database.py", line 213, in sql
    self.connect()
  File "/home/mstfrs/Desktop/ozerpan/apps/frappe/frappe/database/database.py", line 118, in connect
    self._conn: "MariadbConnection" | "PostgresConnection" = self.get_connection()
  File "/home/mstfrs/Desktop/ozerpan/apps/frappe/frappe/database/mariadb/database.py", line 107, in get_connection
    conn = self._get_connection()
  File "/home/mstfrs/Desktop/ozerpan/apps/frappe/frappe/database/mariadb/database.py", line 113, in _get_connection
    return self.create_connection()
  File "/home/mstfrs/Desktop/ozerpan/apps/frappe/frappe/database/mariadb/database.py", line 116, in create_connection
    return pymysql.connect(**self.get_connection_settings())
  File "/home/mstfrs/Desktop/ozerpan/env/lib/python3.10/site-packages/pymysql/connections.py", line 361, in __init__
    self.connect()
  File "/home/mstfrs/Desktop/ozerpan/env/lib/python3.10/site-packages/pymysql/connections.py", line 669, in connect
    self._request_authentication()
  File "/home/mstfrs/Desktop/ozerpan/env/lib/python3.10/site-packages/pymysql/connections.py", line 957, in _request_authentication
    auth_packet = self._read_packet()
  File "/home/mstfrs/Desktop/ozerpan/env/lib/python3.10/site-packages/pymysql/connections.py", line 775, in _read_packet
    packet.raise_for_error()
  File "/home/mstfrs/Desktop/ozerpan/env/lib/python3.10/site-packages/pymysql/protocol.py", line 219, in raise_for_error
    err.raise_mysql_exception(self._data)
  File "/home/mstfrs/Desktop/ozerpan/env/lib/python3.10/site-packages/pymysql/err.py", line 150, in raise_mysql_exception
    raise errorclass(errno, errval)
pymysql.err.OperationalError: (1049, "Unknown database '_be61cf5335d3ad96'")
2024-10-09 17:28:00,595 ERROR scheduler Exception in Enqueue Events for Site ozerpan
Traceback (most recent call last):
  File "/home/mstfrs/Desktop/ozerpan/apps/frappe/frappe/utils/scheduler.py", line 106, in enqueue_events_for_site
    if is_scheduler_inactive():
  File "/home/mstfrs/Desktop/ozerpan/apps/frappe/frappe/utils/scheduler.py", line 150, in is_scheduler_inactive
    if is_scheduler_disabled(verbose=verbose):
  File "/home/mstfrs/Desktop/ozerpan/apps/frappe/frappe/utils/scheduler.py", line 163, in is_scheduler_disabled
    frappe.db.get_single_value("System Settings", "enable_scheduler")
  File "/home/mstfrs/Desktop/ozerpan/apps/frappe/frappe/database/database.py", line 846, in get_single_value
    ).run()
  File "/home/mstfrs/Desktop/ozerpan/apps/frappe/frappe/query_builder/utils.py", line 84, in execute_query
    result = frappe.db.sql(query, params, *args, **kwargs)  # nosemgrep
  File "/home/mstfrs/Desktop/ozerpan/apps/frappe/frappe/database/database.py", line 213, in sql
    self.connect()
  File "/home/mstfrs/Desktop/ozerpan/apps/frappe/frappe/database/database.py", line 118, in connect
    self._conn: "MariadbConnection" | "PostgresConnection" = self.get_connection()
  File "/home/mstfrs/Desktop/ozerpan/apps/frappe/frappe/database/mariadb/database.py", line 107, in get_connection
    conn = self._get_connection()
  File "/home/mstfrs/Desktop/ozerpan/apps/frappe/frappe/database/mariadb/database.py", line 113, in _get_connection
    return self.create_connection()
  File "/home/mstfrs/Desktop/ozerpan/apps/frappe/frappe/database/mariadb/database.py", line 116, in create_connection
    return pymysql.connect(**self.get_connection_settings())
  File "/home/mstfrs/Desktop/ozerpan/env/lib/python3.10/site-packages/pymysql/connections.py", line 361, in __init__
    self.connect()
  File "/home/mstfrs/Desktop/ozerpan/env/lib/python3.10/site-packages/pymysql/connections.py", line 669, in connect
    self._request_authentication()
  File "/home/mstfrs/Desktop/ozerpan/env/lib/python3.10/site-packages/pymysql/connections.py", line 957, in _request_authentication
    auth_packet = self._read_packet()
  File "/home/mstfrs/Desktop/ozerpan/env/lib/python3.10/site-packages/pymysql/connections.py", line 775, in _read_packet
    packet.raise_for_error()
  File "/home/mstfrs/Desktop/ozerpan/env/lib/python3.10/site-packages/pymysql/protocol.py", line 219, in raise_for_error
    err.raise_mysql_exception(self._data)
  File "/home/mstfrs/Desktop/ozerpan/env/lib/python3.10/site-packages/pymysql/err.py", line 150, in raise_mysql_exception
    raise errorclass(errno, errval)
pymysql.err.OperationalError: (1049, "Unknown database '_be61cf5335d3ad96'")
2024-10-09 17:32:01,058 ERROR scheduler Exception in Enqueue Events for Site ozerpan
Traceback (most recent call last):
  File "/home/mstfrs/Desktop/ozerpan/apps/frappe/frappe/utils/scheduler.py", line 106, in enqueue_events_for_site
    if is_scheduler_inactive():
  File "/home/mstfrs/Desktop/ozerpan/apps/frappe/frappe/utils/scheduler.py", line 150, in is_scheduler_inactive
    if is_scheduler_disabled(verbose=verbose):
  File "/home/mstfrs/Desktop/ozerpan/apps/frappe/frappe/utils/scheduler.py", line 163, in is_scheduler_disabled
    frappe.db.get_single_value("System Settings", "enable_scheduler")
  File "/home/mstfrs/Desktop/ozerpan/apps/frappe/frappe/database/database.py", line 846, in get_single_value
    ).run()
  File "/home/mstfrs/Desktop/ozerpan/apps/frappe/frappe/query_builder/utils.py", line 84, in execute_query
    result = frappe.db.sql(query, params, *args, **kwargs)  # nosemgrep
  File "/home/mstfrs/Desktop/ozerpan/apps/frappe/frappe/database/database.py", line 213, in sql
    self.connect()
  File "/home/mstfrs/Desktop/ozerpan/apps/frappe/frappe/database/database.py", line 118, in connect
    self._conn: "MariadbConnection" | "PostgresConnection" = self.get_connection()
  File "/home/mstfrs/Desktop/ozerpan/apps/frappe/frappe/database/mariadb/database.py", line 107, in get_connection
    conn = self._get_connection()
  File "/home/mstfrs/Desktop/ozerpan/apps/frappe/frappe/database/mariadb/database.py", line 113, in _get_connection
    return self.create_connection()
  File "/home/mstfrs/Desktop/ozerpan/apps/frappe/frappe/database/mariadb/database.py", line 116, in create_connection
    return pymysql.connect(**self.get_connection_settings())
  File "/home/mstfrs/Desktop/ozerpan/env/lib/python3.10/site-packages/pymysql/connections.py", line 361, in __init__
    self.connect()
  File "/home/mstfrs/Desktop/ozerpan/env/lib/python3.10/site-packages/pymysql/connections.py", line 669, in connect
    self._request_authentication()
  File "/home/mstfrs/Desktop/ozerpan/env/lib/python3.10/site-packages/pymysql/connections.py", line 957, in _request_authentication
    auth_packet = self._read_packet()
  File "/home/mstfrs/Desktop/ozerpan/env/lib/python3.10/site-packages/pymysql/connections.py", line 775, in _read_packet
    packet.raise_for_error()
  File "/home/mstfrs/Desktop/ozerpan/env/lib/python3.10/site-packages/pymysql/protocol.py", line 219, in raise_for_error
    err.raise_mysql_exception(self._data)
  File "/home/mstfrs/Desktop/ozerpan/env/lib/python3.10/site-packages/pymysql/err.py", line 150, in raise_mysql_exception
    raise errorclass(errno, errval)
pymysql.err.OperationalError: (1049, "Unknown database '_be61cf5335d3ad96'")
2024-10-09 17:36:00,514 ERROR scheduler Exception in Enqueue Events for Site ozerpan
Traceback (most recent call last):
  File "/home/mstfrs/Desktop/ozerpan/apps/frappe/frappe/utils/scheduler.py", line 106, in enqueue_events_for_site
    if is_scheduler_inactive():
  File "/home/mstfrs/Desktop/ozerpan/apps/frappe/frappe/utils/scheduler.py", line 150, in is_scheduler_inactive
    if is_scheduler_disabled(verbose=verbose):
  File "/home/mstfrs/Desktop/ozerpan/apps/frappe/frappe/utils/scheduler.py", line 163, in is_scheduler_disabled
    frappe.db.get_single_value("System Settings", "enable_scheduler")
  File "/home/mstfrs/Desktop/ozerpan/apps/frappe/frappe/database/database.py", line 846, in get_single_value
    ).run()
  File "/home/mstfrs/Desktop/ozerpan/apps/frappe/frappe/query_builder/utils.py", line 84, in execute_query
    result = frappe.db.sql(query, params, *args, **kwargs)  # nosemgrep
  File "/home/mstfrs/Desktop/ozerpan/apps/frappe/frappe/database/database.py", line 213, in sql
    self.connect()
  File "/home/mstfrs/Desktop/ozerpan/apps/frappe/frappe/database/database.py", line 118, in connect
    self._conn: "MariadbConnection" | "PostgresConnection" = self.get_connection()
  File "/home/mstfrs/Desktop/ozerpan/apps/frappe/frappe/database/mariadb/database.py", line 107, in get_connection
    conn = self._get_connection()
  File "/home/mstfrs/Desktop/ozerpan/apps/frappe/frappe/database/mariadb/database.py", line 113, in _get_connection
    return self.create_connection()
  File "/home/mstfrs/Desktop/ozerpan/apps/frappe/frappe/database/mariadb/database.py", line 116, in create_connection
    return pymysql.connect(**self.get_connection_settings())
  File "/home/mstfrs/Desktop/ozerpan/env/lib/python3.10/site-packages/pymysql/connections.py", line 361, in __init__
    self.connect()
  File "/home/mstfrs/Desktop/ozerpan/env/lib/python3.10/site-packages/pymysql/connections.py", line 669, in connect
    self._request_authentication()
  File "/home/mstfrs/Desktop/ozerpan/env/lib/python3.10/site-packages/pymysql/connections.py", line 957, in _request_authentication
    auth_packet = self._read_packet()
  File "/home/mstfrs/Desktop/ozerpan/env/lib/python3.10/site-packages/pymysql/connections.py", line 775, in _read_packet
    packet.raise_for_error()
  File "/home/mstfrs/Desktop/ozerpan/env/lib/python3.10/site-packages/pymysql/protocol.py", line 219, in raise_for_error
    err.raise_mysql_exception(self._data)
  File "/home/mstfrs/Desktop/ozerpan/env/lib/python3.10/site-packages/pymysql/err.py", line 150, in raise_mysql_exception
    raise errorclass(errno, errval)
pymysql.err.OperationalError: (1049, "Unknown database '_be61cf5335d3ad96'")
2024-10-09 17:40:00,617 ERROR scheduler Exception in Enqueue Events for Site ozerpan
Traceback (most recent call last):
  File "/home/mstfrs/Desktop/ozerpan/apps/frappe/frappe/utils/scheduler.py", line 106, in enqueue_events_for_site
    if is_scheduler_inactive():
  File "/home/mstfrs/Desktop/ozerpan/apps/frappe/frappe/utils/scheduler.py", line 150, in is_scheduler_inactive
    if is_scheduler_disabled(verbose=verbose):
  File "/home/mstfrs/Desktop/ozerpan/apps/frappe/frappe/utils/scheduler.py", line 163, in is_scheduler_disabled
    frappe.db.get_single_value("System Settings", "enable_scheduler")
  File "/home/mstfrs/Desktop/ozerpan/apps/frappe/frappe/database/database.py", line 846, in get_single_value
    ).run()
  File "/home/mstfrs/Desktop/ozerpan/apps/frappe/frappe/query_builder/utils.py", line 84, in execute_query
    result = frappe.db.sql(query, params, *args, **kwargs)  # nosemgrep
  File "/home/mstfrs/Desktop/ozerpan/apps/frappe/frappe/database/database.py", line 213, in sql
    self.connect()
  File "/home/mstfrs/Desktop/ozerpan/apps/frappe/frappe/database/database.py", line 118, in connect
    self._conn: "MariadbConnection" | "PostgresConnection" = self.get_connection()
  File "/home/mstfrs/Desktop/ozerpan/apps/frappe/frappe/database/mariadb/database.py", line 107, in get_connection
    conn = self._get_connection()
  File "/home/mstfrs/Desktop/ozerpan/apps/frappe/frappe/database/mariadb/database.py", line 113, in _get_connection
    return self.create_connection()
  File "/home/mstfrs/Desktop/ozerpan/apps/frappe/frappe/database/mariadb/database.py", line 116, in create_connection
    return pymysql.connect(**self.get_connection_settings())
  File "/home/mstfrs/Desktop/ozerpan/env/lib/python3.10/site-packages/pymysql/connections.py", line 361, in __init__
    self.connect()
  File "/home/mstfrs/Desktop/ozerpan/env/lib/python3.10/site-packages/pymysql/connections.py", line 669, in connect
    self._request_authentication()
  File "/home/mstfrs/Desktop/ozerpan/env/lib/python3.10/site-packages/pymysql/connections.py", line 957, in _request_authentication
    auth_packet = self._read_packet()
  File "/home/mstfrs/Desktop/ozerpan/env/lib/python3.10/site-packages/pymysql/connections.py", line 775, in _read_packet
    packet.raise_for_error()
  File "/home/mstfrs/Desktop/ozerpan/env/lib/python3.10/site-packages/pymysql/protocol.py", line 219, in raise_for_error
    err.raise_mysql_exception(self._data)
  File "/home/mstfrs/Desktop/ozerpan/env/lib/python3.10/site-packages/pymysql/err.py", line 150, in raise_mysql_exception
    raise errorclass(errno, errval)
pymysql.err.OperationalError: (1049, "Unknown database '_be61cf5335d3ad96'")
2024-10-09 17:44:01,003 ERROR scheduler Exception in Enqueue Events for Site ozerpan
Traceback (most recent call last):
  File "/home/mstfrs/Desktop/ozerpan/apps/frappe/frappe/utils/scheduler.py", line 106, in enqueue_events_for_site
    if is_scheduler_inactive():
  File "/home/mstfrs/Desktop/ozerpan/apps/frappe/frappe/utils/scheduler.py", line 150, in is_scheduler_inactive
    if is_scheduler_disabled(verbose=verbose):
  File "/home/mstfrs/Desktop/ozerpan/apps/frappe/frappe/utils/scheduler.py", line 163, in is_scheduler_disabled
    frappe.db.get_single_value("System Settings", "enable_scheduler")
  File "/home/mstfrs/Desktop/ozerpan/apps/frappe/frappe/database/database.py", line 846, in get_single_value
    ).run()
  File "/home/mstfrs/Desktop/ozerpan/apps/frappe/frappe/query_builder/utils.py", line 84, in execute_query
    result = frappe.db.sql(query, params, *args, **kwargs)  # nosemgrep
  File "/home/mstfrs/Desktop/ozerpan/apps/frappe/frappe/database/database.py", line 213, in sql
    self.connect()
  File "/home/mstfrs/Desktop/ozerpan/apps/frappe/frappe/database/database.py", line 118, in connect
    self._conn: "MariadbConnection" | "PostgresConnection" = self.get_connection()
  File "/home/mstfrs/Desktop/ozerpan/apps/frappe/frappe/database/mariadb/database.py", line 107, in get_connection
    conn = self._get_connection()
  File "/home/mstfrs/Desktop/ozerpan/apps/frappe/frappe/database/mariadb/database.py", line 113, in _get_connection
    return self.create_connection()
  File "/home/mstfrs/Desktop/ozerpan/apps/frappe/frappe/database/mariadb/database.py", line 116, in create_connection
    return pymysql.connect(**self.get_connection_settings())
  File "/home/mstfrs/Desktop/ozerpan/env/lib/python3.10/site-packages/pymysql/connections.py", line 361, in __init__
    self.connect()
  File "/home/mstfrs/Desktop/ozerpan/env/lib/python3.10/site-packages/pymysql/connections.py", line 669, in connect
    self._request_authentication()
  File "/home/mstfrs/Desktop/ozerpan/env/lib/python3.10/site-packages/pymysql/connections.py", line 957, in _request_authentication
    auth_packet = self._read_packet()
  File "/home/mstfrs/Desktop/ozerpan/env/lib/python3.10/site-packages/pymysql/connections.py", line 775, in _read_packet
    packet.raise_for_error()
  File "/home/mstfrs/Desktop/ozerpan/env/lib/python3.10/site-packages/pymysql/protocol.py", line 219, in raise_for_error
    err.raise_mysql_exception(self._data)
  File "/home/mstfrs/Desktop/ozerpan/env/lib/python3.10/site-packages/pymysql/err.py", line 150, in raise_mysql_exception
    raise errorclass(errno, errval)
pymysql.err.OperationalError: (1049, "Unknown database '_be61cf5335d3ad96'")
2024-10-09 17:48:00,364 ERROR scheduler Exception in Enqueue Events for Site ozerpan
Traceback (most recent call last):
  File "/home/mstfrs/Desktop/ozerpan/apps/frappe/frappe/utils/scheduler.py", line 106, in enqueue_events_for_site
    if is_scheduler_inactive():
  File "/home/mstfrs/Desktop/ozerpan/apps/frappe/frappe/utils/scheduler.py", line 150, in is_scheduler_inactive
    if is_scheduler_disabled(verbose=verbose):
  File "/home/mstfrs/Desktop/ozerpan/apps/frappe/frappe/utils/scheduler.py", line 163, in is_scheduler_disabled
    frappe.db.get_single_value("System Settings", "enable_scheduler")
  File "/home/mstfrs/Desktop/ozerpan/apps/frappe/frappe/database/database.py", line 846, in get_single_value
    ).run()
  File "/home/mstfrs/Desktop/ozerpan/apps/frappe/frappe/query_builder/utils.py", line 84, in execute_query
    result = frappe.db.sql(query, params, *args, **kwargs)  # nosemgrep
  File "/home/mstfrs/Desktop/ozerpan/apps/frappe/frappe/database/database.py", line 213, in sql
    self.connect()
  File "/home/mstfrs/Desktop/ozerpan/apps/frappe/frappe/database/database.py", line 118, in connect
    self._conn: "MariadbConnection" | "PostgresConnection" = self.get_connection()
  File "/home/mstfrs/Desktop/ozerpan/apps/frappe/frappe/database/mariadb/database.py", line 107, in get_connection
    conn = self._get_connection()
  File "/home/mstfrs/Desktop/ozerpan/apps/frappe/frappe/database/mariadb/database.py", line 113, in _get_connection
    return self.create_connection()
  File "/home/mstfrs/Desktop/ozerpan/apps/frappe/frappe/database/mariadb/database.py", line 116, in create_connection
    return pymysql.connect(**self.get_connection_settings())
  File "/home/mstfrs/Desktop/ozerpan/env/lib/python3.10/site-packages/pymysql/connections.py", line 361, in __init__
    self.connect()
  File "/home/mstfrs/Desktop/ozerpan/env/lib/python3.10/site-packages/pymysql/connections.py", line 669, in connect
    self._request_authentication()
  File "/home/mstfrs/Desktop/ozerpan/env/lib/python3.10/site-packages/pymysql/connections.py", line 957, in _request_authentication
    auth_packet = self._read_packet()
  File "/home/mstfrs/Desktop/ozerpan/env/lib/python3.10/site-packages/pymysql/connections.py", line 775, in _read_packet
    packet.raise_for_error()
  File "/home/mstfrs/Desktop/ozerpan/env/lib/python3.10/site-packages/pymysql/protocol.py", line 219, in raise_for_error
    err.raise_mysql_exception(self._data)
  File "/home/mstfrs/Desktop/ozerpan/env/lib/python3.10/site-packages/pymysql/err.py", line 150, in raise_mysql_exception
    raise errorclass(errno, errval)
pymysql.err.OperationalError: (1049, "Unknown database '_be61cf5335d3ad96'")
2024-10-09 17:52:00,801 ERROR scheduler Exception in Enqueue Events for Site ozerpan
Traceback (most recent call last):
  File "/home/mstfrs/Desktop/ozerpan/apps/frappe/frappe/utils/scheduler.py", line 106, in enqueue_events_for_site
    if is_scheduler_inactive():
  File "/home/mstfrs/Desktop/ozerpan/apps/frappe/frappe/utils/scheduler.py", line 150, in is_scheduler_inactive
    if is_scheduler_disabled(verbose=verbose):
  File "/home/mstfrs/Desktop/ozerpan/apps/frappe/frappe/utils/scheduler.py", line 163, in is_scheduler_disabled
    frappe.db.get_single_value("System Settings", "enable_scheduler")
  File "/home/mstfrs/Desktop/ozerpan/apps/frappe/frappe/database/database.py", line 846, in get_single_value
    ).run()
  File "/home/mstfrs/Desktop/ozerpan/apps/frappe/frappe/query_builder/utils.py", line 84, in execute_query
    result = frappe.db.sql(query, params, *args, **kwargs)  # nosemgrep
  File "/home/mstfrs/Desktop/ozerpan/apps/frappe/frappe/database/database.py", line 213, in sql
    self.connect()
  File "/home/mstfrs/Desktop/ozerpan/apps/frappe/frappe/database/database.py", line 118, in connect
    self._conn: "MariadbConnection" | "PostgresConnection" = self.get_connection()
  File "/home/mstfrs/Desktop/ozerpan/apps/frappe/frappe/database/mariadb/database.py", line 107, in get_connection
    conn = self._get_connection()
  File "/home/mstfrs/Desktop/ozerpan/apps/frappe/frappe/database/mariadb/database.py", line 113, in _get_connection
    return self.create_connection()
  File "/home/mstfrs/Desktop/ozerpan/apps/frappe/frappe/database/mariadb/database.py", line 116, in create_connection
    return pymysql.connect(**self.get_connection_settings())
  File "/home/mstfrs/Desktop/ozerpan/env/lib/python3.10/site-packages/pymysql/connections.py", line 361, in __init__
    self.connect()
  File "/home/mstfrs/Desktop/ozerpan/env/lib/python3.10/site-packages/pymysql/connections.py", line 669, in connect
    self._request_authentication()
  File "/home/mstfrs/Desktop/ozerpan/env/lib/python3.10/site-packages/pymysql/connections.py", line 957, in _request_authentication
    auth_packet = self._read_packet()
  File "/home/mstfrs/Desktop/ozerpan/env/lib/python3.10/site-packages/pymysql/connections.py", line 775, in _read_packet
    packet.raise_for_error()
  File "/home/mstfrs/Desktop/ozerpan/env/lib/python3.10/site-packages/pymysql/protocol.py", line 219, in raise_for_error
    err.raise_mysql_exception(self._data)
  File "/home/mstfrs/Desktop/ozerpan/env/lib/python3.10/site-packages/pymysql/err.py", line 150, in raise_mysql_exception
    raise errorclass(errno, errval)
pymysql.err.OperationalError: (1049, "Unknown database '_be61cf5335d3ad96'")
2024-10-09 17:56:00,269 ERROR scheduler Exception in Enqueue Events for Site ozerpan
Traceback (most recent call last):
  File "/home/mstfrs/Desktop/ozerpan/apps/frappe/frappe/utils/scheduler.py", line 106, in enqueue_events_for_site
    if is_scheduler_inactive():
  File "/home/mstfrs/Desktop/ozerpan/apps/frappe/frappe/utils/scheduler.py", line 150, in is_scheduler_inactive
    if is_scheduler_disabled(verbose=verbose):
  File "/home/mstfrs/Desktop/ozerpan/apps/frappe/frappe/utils/scheduler.py", line 163, in is_scheduler_disabled
    frappe.db.get_single_value("System Settings", "enable_scheduler")
  File "/home/mstfrs/Desktop/ozerpan/apps/frappe/frappe/database/database.py", line 846, in get_single_value
    ).run()
  File "/home/mstfrs/Desktop/ozerpan/apps/frappe/frappe/query_builder/utils.py", line 84, in execute_query
    result = frappe.db.sql(query, params, *args, **kwargs)  # nosemgrep
  File "/home/mstfrs/Desktop/ozerpan/apps/frappe/frappe/database/database.py", line 213, in sql
    self.connect()
  File "/home/mstfrs/Desktop/ozerpan/apps/frappe/frappe/database/database.py", line 118, in connect
    self._conn: "MariadbConnection" | "PostgresConnection" = self.get_connection()
  File "/home/mstfrs/Desktop/ozerpan/apps/frappe/frappe/database/mariadb/database.py", line 107, in get_connection
    conn = self._get_connection()
  File "/home/mstfrs/Desktop/ozerpan/apps/frappe/frappe/database/mariadb/database.py", line 113, in _get_connection
    return self.create_connection()
  File "/home/mstfrs/Desktop/ozerpan/apps/frappe/frappe/database/mariadb/database.py", line 116, in create_connection
    return pymysql.connect(**self.get_connection_settings())
  File "/home/mstfrs/Desktop/ozerpan/env/lib/python3.10/site-packages/pymysql/connections.py", line 361, in __init__
    self.connect()
  File "/home/mstfrs/Desktop/ozerpan/env/lib/python3.10/site-packages/pymysql/connections.py", line 669, in connect
    self._request_authentication()
  File "/home/mstfrs/Desktop/ozerpan/env/lib/python3.10/site-packages/pymysql/connections.py", line 957, in _request_authentication
    auth_packet = self._read_packet()
  File "/home/mstfrs/Desktop/ozerpan/env/lib/python3.10/site-packages/pymysql/connections.py", line 775, in _read_packet
    packet.raise_for_error()
  File "/home/mstfrs/Desktop/ozerpan/env/lib/python3.10/site-packages/pymysql/protocol.py", line 219, in raise_for_error
    err.raise_mysql_exception(self._data)
  File "/home/mstfrs/Desktop/ozerpan/env/lib/python3.10/site-packages/pymysql/err.py", line 150, in raise_mysql_exception
    raise errorclass(errno, errval)
pymysql.err.OperationalError: (1049, "Unknown database '_be61cf5335d3ad96'")
2024-10-09 18:00:00,707 ERROR scheduler Exception in Enqueue Events for Site ozerpan
Traceback (most recent call last):
  File "/home/mstfrs/Desktop/ozerpan/apps/frappe/frappe/utils/scheduler.py", line 106, in enqueue_events_for_site
    if is_scheduler_inactive():
  File "/home/mstfrs/Desktop/ozerpan/apps/frappe/frappe/utils/scheduler.py", line 150, in is_scheduler_inactive
    if is_scheduler_disabled(verbose=verbose):
  File "/home/mstfrs/Desktop/ozerpan/apps/frappe/frappe/utils/scheduler.py", line 163, in is_scheduler_disabled
    frappe.db.get_single_value("System Settings", "enable_scheduler")
  File "/home/mstfrs/Desktop/ozerpan/apps/frappe/frappe/database/database.py", line 846, in get_single_value
    ).run()
  File "/home/mstfrs/Desktop/ozerpan/apps/frappe/frappe/query_builder/utils.py", line 84, in execute_query
    result = frappe.db.sql(query, params, *args, **kwargs)  # nosemgrep
  File "/home/mstfrs/Desktop/ozerpan/apps/frappe/frappe/database/database.py", line 213, in sql
    self.connect()
  File "/home/mstfrs/Desktop/ozerpan/apps/frappe/frappe/database/database.py", line 118, in connect
    self._conn: "MariadbConnection" | "PostgresConnection" = self.get_connection()
  File "/home/mstfrs/Desktop/ozerpan/apps/frappe/frappe/database/mariadb/database.py", line 107, in get_connection
    conn = self._get_connection()
  File "/home/mstfrs/Desktop/ozerpan/apps/frappe/frappe/database/mariadb/database.py", line 113, in _get_connection
    return self.create_connection()
  File "/home/mstfrs/Desktop/ozerpan/apps/frappe/frappe/database/mariadb/database.py", line 116, in create_connection
    return pymysql.connect(**self.get_connection_settings())
  File "/home/mstfrs/Desktop/ozerpan/env/lib/python3.10/site-packages/pymysql/connections.py", line 361, in __init__
    self.connect()
  File "/home/mstfrs/Desktop/ozerpan/env/lib/python3.10/site-packages/pymysql/connections.py", line 669, in connect
    self._request_authentication()
  File "/home/mstfrs/Desktop/ozerpan/env/lib/python3.10/site-packages/pymysql/connections.py", line 957, in _request_authentication
    auth_packet = self._read_packet()
  File "/home/mstfrs/Desktop/ozerpan/env/lib/python3.10/site-packages/pymysql/connections.py", line 775, in _read_packet
    packet.raise_for_error()
  File "/home/mstfrs/Desktop/ozerpan/env/lib/python3.10/site-packages/pymysql/protocol.py", line 219, in raise_for_error
    err.raise_mysql_exception(self._data)
  File "/home/mstfrs/Desktop/ozerpan/env/lib/python3.10/site-packages/pymysql/err.py", line 150, in raise_mysql_exception
    raise errorclass(errno, errval)
pymysql.err.OperationalError: (1049, "Unknown database '_be61cf5335d3ad96'")
