2024-10-09 00:04:02,571 ERROR scheduler Exception in Enqueue Events for Site ozerpan
Traceback (most recent call last):
  File "/home/mstfrs/Desktop/ozerpan/apps/frappe/frappe/utils/scheduler.py", line 106, in enqueue_events_for_site
    if is_scheduler_inactive():
  File "/home/mstfrs/Desktop/ozerpan/apps/frappe/frappe/utils/scheduler.py", line 150, in is_scheduler_inactive
    if is_scheduler_disabled(verbose=verbose):
  File "/home/mstfrs/Desktop/ozerpan/apps/frappe/frappe/utils/scheduler.py", line 163, in is_scheduler_disabled
    frappe.db.get_single_value("System Settings", "enable_scheduler")
  File "/home/mstfrs/Desktop/ozerpan/apps/frappe/frappe/database/database.py", line 846, in get_single_value
    ).run()
  File "/home/mstfrs/Desktop/ozerpan/apps/frappe/frappe/query_builder/utils.py", line 84, in execute_query
    result = frappe.db.sql(query, params, *args, **kwargs)  # nosemgrep
  File "/home/mstfrs/Desktop/ozerpan/apps/frappe/frappe/database/database.py", line 213, in sql
    self.connect()
  File "/home/mstfrs/Desktop/ozerpan/apps/frappe/frappe/database/database.py", line 118, in connect
    self._conn: "MariadbConnection" | "PostgresConnection" = self.get_connection()
  File "/home/mstfrs/Desktop/ozerpan/apps/frappe/frappe/database/mariadb/database.py", line 107, in get_connection
    conn = self._get_connection()
  File "/home/mstfrs/Desktop/ozerpan/apps/frappe/frappe/database/mariadb/database.py", line 113, in _get_connection
    return self.create_connection()
  File "/home/mstfrs/Desktop/ozerpan/apps/frappe/frappe/database/mariadb/database.py", line 116, in create_connection
    return pymysql.connect(**self.get_connection_settings())
  File "/home/mstfrs/Desktop/ozerpan/env/lib/python3.10/site-packages/pymysql/connections.py", line 361, in __init__
    self.connect()
  File "/home/mstfrs/Desktop/ozerpan/env/lib/python3.10/site-packages/pymysql/connections.py", line 669, in connect
    self._request_authentication()
  File "/home/mstfrs/Desktop/ozerpan/env/lib/python3.10/site-packages/pymysql/connections.py", line 957, in _request_authentication
    auth_packet = self._read_packet()
  File "/home/mstfrs/Desktop/ozerpan/env/lib/python3.10/site-packages/pymysql/connections.py", line 775, in _read_packet
    packet.raise_for_error()
  File "/home/mstfrs/Desktop/ozerpan/env/lib/python3.10/site-packages/pymysql/protocol.py", line 219, in raise_for_error
    err.raise_mysql_exception(self._data)
  File "/home/mstfrs/Desktop/ozerpan/env/lib/python3.10/site-packages/pymysql/err.py", line 150, in raise_mysql_exception
    raise errorclass(errno, errval)
pymysql.err.OperationalError: (1049, "Unknown database '_be61cf5335d3ad96'")
2024-10-09 00:12:10,658 ERROR scheduler Exception in Enqueue Events for Site ozerpan.local
Traceback (most recent call last):
  File "/home/mstfrs/Desktop/ozerpan/apps/frappe/frappe/utils/scheduler.py", line 106, in enqueue_events_for_site
    if is_scheduler_inactive():
  File "/home/mstfrs/Desktop/ozerpan/apps/frappe/frappe/utils/scheduler.py", line 150, in is_scheduler_inactive
    if is_scheduler_disabled(verbose=verbose):
  File "/home/mstfrs/Desktop/ozerpan/apps/frappe/frappe/utils/scheduler.py", line 163, in is_scheduler_disabled
    frappe.db.get_single_value("System Settings", "enable_scheduler")
  File "/home/mstfrs/Desktop/ozerpan/apps/frappe/frappe/database/database.py", line 846, in get_single_value
    ).run()
  File "/home/mstfrs/Desktop/ozerpan/apps/frappe/frappe/query_builder/utils.py", line 84, in execute_query
    result = frappe.db.sql(query, params, *args, **kwargs)  # nosemgrep
  File "/home/mstfrs/Desktop/ozerpan/apps/frappe/frappe/database/database.py", line 213, in sql
    self.connect()
  File "/home/mstfrs/Desktop/ozerpan/apps/frappe/frappe/database/database.py", line 118, in connect
    self._conn: "MariadbConnection" | "PostgresConnection" = self.get_connection()
  File "/home/mstfrs/Desktop/ozerpan/apps/frappe/frappe/database/mariadb/database.py", line 107, in get_connection
    conn = self._get_connection()
  File "/home/mstfrs/Desktop/ozerpan/apps/frappe/frappe/database/mariadb/database.py", line 113, in _get_connection
    return self.create_connection()
  File "/home/mstfrs/Desktop/ozerpan/apps/frappe/frappe/database/mariadb/database.py", line 116, in create_connection
    return pymysql.connect(**self.get_connection_settings())
  File "/home/mstfrs/Desktop/ozerpan/env/lib/python3.10/site-packages/pymysql/connections.py", line 361, in __init__
    self.connect()
  File "/home/mstfrs/Desktop/ozerpan/env/lib/python3.10/site-packages/pymysql/connections.py", line 669, in connect
    self._request_authentication()
  File "/home/mstfrs/Desktop/ozerpan/env/lib/python3.10/site-packages/pymysql/connections.py", line 957, in _request_authentication
    auth_packet = self._read_packet()
  File "/home/mstfrs/Desktop/ozerpan/env/lib/python3.10/site-packages/pymysql/connections.py", line 775, in _read_packet
    packet.raise_for_error()
  File "/home/mstfrs/Desktop/ozerpan/env/lib/python3.10/site-packages/pymysql/protocol.py", line 219, in raise_for_error
    err.raise_mysql_exception(self._data)
  File "/home/mstfrs/Desktop/ozerpan/env/lib/python3.10/site-packages/pymysql/err.py", line 150, in raise_mysql_exception
    raise errorclass(errno, errval)
pymysql.err.OperationalError: (1045, "Access denied for user '_c85c2ca7b22cd0b1'@'localhost' (using password: YES)")
2024-10-09 00:12:13,636 ERROR scheduler Exception in Enqueue Events for Site ozerpan
Traceback (most recent call last):
  File "/home/mstfrs/Desktop/ozerpan/apps/frappe/frappe/utils/scheduler.py", line 106, in enqueue_events_for_site
    if is_scheduler_inactive():
  File "/home/mstfrs/Desktop/ozerpan/apps/frappe/frappe/utils/scheduler.py", line 150, in is_scheduler_inactive
    if is_scheduler_disabled(verbose=verbose):
  File "/home/mstfrs/Desktop/ozerpan/apps/frappe/frappe/utils/scheduler.py", line 163, in is_scheduler_disabled
    frappe.db.get_single_value("System Settings", "enable_scheduler")
  File "/home/mstfrs/Desktop/ozerpan/apps/frappe/frappe/database/database.py", line 846, in get_single_value
    ).run()
  File "/home/mstfrs/Desktop/ozerpan/apps/frappe/frappe/query_builder/utils.py", line 84, in execute_query
    result = frappe.db.sql(query, params, *args, **kwargs)  # nosemgrep
  File "/home/mstfrs/Desktop/ozerpan/apps/frappe/frappe/database/database.py", line 213, in sql
    self.connect()
  File "/home/mstfrs/Desktop/ozerpan/apps/frappe/frappe/database/database.py", line 118, in connect
    self._conn: "MariadbConnection" | "PostgresConnection" = self.get_connection()
  File "/home/mstfrs/Desktop/ozerpan/apps/frappe/frappe/database/mariadb/database.py", line 107, in get_connection
    conn = self._get_connection()
  File "/home/mstfrs/Desktop/ozerpan/apps/frappe/frappe/database/mariadb/database.py", line 113, in _get_connection
    return self.create_connection()
  File "/home/mstfrs/Desktop/ozerpan/apps/frappe/frappe/database/mariadb/database.py", line 116, in create_connection
    return pymysql.connect(**self.get_connection_settings())
  File "/home/mstfrs/Desktop/ozerpan/env/lib/python3.10/site-packages/pymysql/connections.py", line 361, in __init__
    self.connect()
  File "/home/mstfrs/Desktop/ozerpan/env/lib/python3.10/site-packages/pymysql/connections.py", line 669, in connect
    self._request_authentication()
  File "/home/mstfrs/Desktop/ozerpan/env/lib/python3.10/site-packages/pymysql/connections.py", line 957, in _request_authentication
    auth_packet = self._read_packet()
  File "/home/mstfrs/Desktop/ozerpan/env/lib/python3.10/site-packages/pymysql/connections.py", line 775, in _read_packet
    packet.raise_for_error()
  File "/home/mstfrs/Desktop/ozerpan/env/lib/python3.10/site-packages/pymysql/protocol.py", line 219, in raise_for_error
    err.raise_mysql_exception(self._data)
  File "/home/mstfrs/Desktop/ozerpan/env/lib/python3.10/site-packages/pymysql/err.py", line 150, in raise_mysql_exception
    raise errorclass(errno, errval)
pymysql.err.OperationalError: (1049, "Unknown database '_be61cf5335d3ad96'")
2024-10-09 09:52:03,520 ERROR scheduler Exception in Enqueue Events for Site ozerpan.local
Traceback (most recent call last):
  File "/home/mstfrs/Desktop/ozerpan/apps/frappe/frappe/utils/scheduler.py", line 106, in enqueue_events_for_site
    if is_scheduler_inactive():
  File "/home/mstfrs/Desktop/ozerpan/apps/frappe/frappe/utils/scheduler.py", line 150, in is_scheduler_inactive
    if is_scheduler_disabled(verbose=verbose):
  File "/home/mstfrs/Desktop/ozerpan/apps/frappe/frappe/utils/scheduler.py", line 163, in is_scheduler_disabled
    frappe.db.get_single_value("System Settings", "enable_scheduler")
  File "/home/mstfrs/Desktop/ozerpan/apps/frappe/frappe/database/database.py", line 846, in get_single_value
    ).run()
  File "/home/mstfrs/Desktop/ozerpan/apps/frappe/frappe/query_builder/utils.py", line 84, in execute_query
    result = frappe.db.sql(query, params, *args, **kwargs)  # nosemgrep
  File "/home/mstfrs/Desktop/ozerpan/apps/frappe/frappe/database/database.py", line 213, in sql
    self.connect()
  File "/home/mstfrs/Desktop/ozerpan/apps/frappe/frappe/database/database.py", line 118, in connect
    self._conn: "MariadbConnection" | "PostgresConnection" = self.get_connection()
  File "/home/mstfrs/Desktop/ozerpan/apps/frappe/frappe/database/mariadb/database.py", line 107, in get_connection
    conn = self._get_connection()
  File "/home/mstfrs/Desktop/ozerpan/apps/frappe/frappe/database/mariadb/database.py", line 113, in _get_connection
    return self.create_connection()
  File "/home/mstfrs/Desktop/ozerpan/apps/frappe/frappe/database/mariadb/database.py", line 116, in create_connection
    return pymysql.connect(**self.get_connection_settings())
  File "/home/mstfrs/Desktop/ozerpan/env/lib/python3.10/site-packages/pymysql/connections.py", line 361, in __init__
    self.connect()
  File "/home/mstfrs/Desktop/ozerpan/env/lib/python3.10/site-packages/pymysql/connections.py", line 669, in connect
    self._request_authentication()
  File "/home/mstfrs/Desktop/ozerpan/env/lib/python3.10/site-packages/pymysql/connections.py", line 957, in _request_authentication
    auth_packet = self._read_packet()
  File "/home/mstfrs/Desktop/ozerpan/env/lib/python3.10/site-packages/pymysql/connections.py", line 775, in _read_packet
    packet.raise_for_error()
  File "/home/mstfrs/Desktop/ozerpan/env/lib/python3.10/site-packages/pymysql/protocol.py", line 219, in raise_for_error
    err.raise_mysql_exception(self._data)
  File "/home/mstfrs/Desktop/ozerpan/env/lib/python3.10/site-packages/pymysql/err.py", line 150, in raise_mysql_exception
    raise errorclass(errno, errval)
pymysql.err.OperationalError: (1045, "Access denied for user '_c85c2ca7b22cd0b1'@'localhost' (using password: YES)")
2024-10-09 09:52:03,740 ERROR scheduler Exception in Enqueue Events for Site ozerpan
Traceback (most recent call last):
  File "/home/mstfrs/Desktop/ozerpan/apps/frappe/frappe/utils/scheduler.py", line 106, in enqueue_events_for_site
    if is_scheduler_inactive():
  File "/home/mstfrs/Desktop/ozerpan/apps/frappe/frappe/utils/scheduler.py", line 150, in is_scheduler_inactive
    if is_scheduler_disabled(verbose=verbose):
  File "/home/mstfrs/Desktop/ozerpan/apps/frappe/frappe/utils/scheduler.py", line 163, in is_scheduler_disabled
    frappe.db.get_single_value("System Settings", "enable_scheduler")
  File "/home/mstfrs/Desktop/ozerpan/apps/frappe/frappe/database/database.py", line 846, in get_single_value
    ).run()
  File "/home/mstfrs/Desktop/ozerpan/apps/frappe/frappe/query_builder/utils.py", line 84, in execute_query
    result = frappe.db.sql(query, params, *args, **kwargs)  # nosemgrep
  File "/home/mstfrs/Desktop/ozerpan/apps/frappe/frappe/database/database.py", line 213, in sql
    self.connect()
  File "/home/mstfrs/Desktop/ozerpan/apps/frappe/frappe/database/database.py", line 118, in connect
    self._conn: "MariadbConnection" | "PostgresConnection" = self.get_connection()
  File "/home/mstfrs/Desktop/ozerpan/apps/frappe/frappe/database/mariadb/database.py", line 107, in get_connection
    conn = self._get_connection()
  File "/home/mstfrs/Desktop/ozerpan/apps/frappe/frappe/database/mariadb/database.py", line 113, in _get_connection
    return self.create_connection()
  File "/home/mstfrs/Desktop/ozerpan/apps/frappe/frappe/database/mariadb/database.py", line 116, in create_connection
    return pymysql.connect(**self.get_connection_settings())
  File "/home/mstfrs/Desktop/ozerpan/env/lib/python3.10/site-packages/pymysql/connections.py", line 361, in __init__
    self.connect()
  File "/home/mstfrs/Desktop/ozerpan/env/lib/python3.10/site-packages/pymysql/connections.py", line 669, in connect
    self._request_authentication()
  File "/home/mstfrs/Desktop/ozerpan/env/lib/python3.10/site-packages/pymysql/connections.py", line 957, in _request_authentication
    auth_packet = self._read_packet()
  File "/home/mstfrs/Desktop/ozerpan/env/lib/python3.10/site-packages/pymysql/connections.py", line 775, in _read_packet
    packet.raise_for_error()
  File "/home/mstfrs/Desktop/ozerpan/env/lib/python3.10/site-packages/pymysql/protocol.py", line 219, in raise_for_error
    err.raise_mysql_exception(self._data)
  File "/home/mstfrs/Desktop/ozerpan/env/lib/python3.10/site-packages/pymysql/err.py", line 150, in raise_mysql_exception
    raise errorclass(errno, errval)
pymysql.err.OperationalError: (1049, "Unknown database '_be61cf5335d3ad96'")
2024-10-09 09:56:01,219 ERROR scheduler Exception in Enqueue Events for Site ozerpan.local
Traceback (most recent call last):
  File "/home/mstfrs/Desktop/ozerpan/apps/frappe/frappe/utils/scheduler.py", line 106, in enqueue_events_for_site
    if is_scheduler_inactive():
  File "/home/mstfrs/Desktop/ozerpan/apps/frappe/frappe/utils/scheduler.py", line 150, in is_scheduler_inactive
    if is_scheduler_disabled(verbose=verbose):
  File "/home/mstfrs/Desktop/ozerpan/apps/frappe/frappe/utils/scheduler.py", line 163, in is_scheduler_disabled
    frappe.db.get_single_value("System Settings", "enable_scheduler")
  File "/home/mstfrs/Desktop/ozerpan/apps/frappe/frappe/database/database.py", line 846, in get_single_value
    ).run()
  File "/home/mstfrs/Desktop/ozerpan/apps/frappe/frappe/query_builder/utils.py", line 84, in execute_query
    result = frappe.db.sql(query, params, *args, **kwargs)  # nosemgrep
  File "/home/mstfrs/Desktop/ozerpan/apps/frappe/frappe/database/database.py", line 213, in sql
    self.connect()
  File "/home/mstfrs/Desktop/ozerpan/apps/frappe/frappe/database/database.py", line 118, in connect
    self._conn: "MariadbConnection" | "PostgresConnection" = self.get_connection()
  File "/home/mstfrs/Desktop/ozerpan/apps/frappe/frappe/database/mariadb/database.py", line 107, in get_connection
    conn = self._get_connection()
  File "/home/mstfrs/Desktop/ozerpan/apps/frappe/frappe/database/mariadb/database.py", line 113, in _get_connection
    return self.create_connection()
  File "/home/mstfrs/Desktop/ozerpan/apps/frappe/frappe/database/mariadb/database.py", line 116, in create_connection
    return pymysql.connect(**self.get_connection_settings())
  File "/home/mstfrs/Desktop/ozerpan/env/lib/python3.10/site-packages/pymysql/connections.py", line 361, in __init__
    self.connect()
  File "/home/mstfrs/Desktop/ozerpan/env/lib/python3.10/site-packages/pymysql/connections.py", line 669, in connect
    self._request_authentication()
  File "/home/mstfrs/Desktop/ozerpan/env/lib/python3.10/site-packages/pymysql/connections.py", line 957, in _request_authentication
    auth_packet = self._read_packet()
  File "/home/mstfrs/Desktop/ozerpan/env/lib/python3.10/site-packages/pymysql/connections.py", line 775, in _read_packet
    packet.raise_for_error()
  File "/home/mstfrs/Desktop/ozerpan/env/lib/python3.10/site-packages/pymysql/protocol.py", line 219, in raise_for_error
    err.raise_mysql_exception(self._data)
  File "/home/mstfrs/Desktop/ozerpan/env/lib/python3.10/site-packages/pymysql/err.py", line 150, in raise_mysql_exception
    raise errorclass(errno, errval)
pymysql.err.OperationalError: (1045, "Access denied for user '_c85c2ca7b22cd0b1'@'localhost' (using password: YES)")
2024-10-09 09:56:01,556 ERROR scheduler Exception in Enqueue Events for Site ozerpan
Traceback (most recent call last):
  File "/home/mstfrs/Desktop/ozerpan/apps/frappe/frappe/utils/scheduler.py", line 106, in enqueue_events_for_site
    if is_scheduler_inactive():
  File "/home/mstfrs/Desktop/ozerpan/apps/frappe/frappe/utils/scheduler.py", line 150, in is_scheduler_inactive
    if is_scheduler_disabled(verbose=verbose):
  File "/home/mstfrs/Desktop/ozerpan/apps/frappe/frappe/utils/scheduler.py", line 163, in is_scheduler_disabled
    frappe.db.get_single_value("System Settings", "enable_scheduler")
  File "/home/mstfrs/Desktop/ozerpan/apps/frappe/frappe/database/database.py", line 846, in get_single_value
    ).run()
  File "/home/mstfrs/Desktop/ozerpan/apps/frappe/frappe/query_builder/utils.py", line 84, in execute_query
    result = frappe.db.sql(query, params, *args, **kwargs)  # nosemgrep
  File "/home/mstfrs/Desktop/ozerpan/apps/frappe/frappe/database/database.py", line 213, in sql
    self.connect()
  File "/home/mstfrs/Desktop/ozerpan/apps/frappe/frappe/database/database.py", line 118, in connect
    self._conn: "MariadbConnection" | "PostgresConnection" = self.get_connection()
  File "/home/mstfrs/Desktop/ozerpan/apps/frappe/frappe/database/mariadb/database.py", line 107, in get_connection
    conn = self._get_connection()
  File "/home/mstfrs/Desktop/ozerpan/apps/frappe/frappe/database/mariadb/database.py", line 113, in _get_connection
    return self.create_connection()
  File "/home/mstfrs/Desktop/ozerpan/apps/frappe/frappe/database/mariadb/database.py", line 116, in create_connection
    return pymysql.connect(**self.get_connection_settings())
  File "/home/mstfrs/Desktop/ozerpan/env/lib/python3.10/site-packages/pymysql/connections.py", line 361, in __init__
    self.connect()
  File "/home/mstfrs/Desktop/ozerpan/env/lib/python3.10/site-packages/pymysql/connections.py", line 669, in connect
    self._request_authentication()
  File "/home/mstfrs/Desktop/ozerpan/env/lib/python3.10/site-packages/pymysql/connections.py", line 957, in _request_authentication
    auth_packet = self._read_packet()
  File "/home/mstfrs/Desktop/ozerpan/env/lib/python3.10/site-packages/pymysql/connections.py", line 775, in _read_packet
    packet.raise_for_error()
  File "/home/mstfrs/Desktop/ozerpan/env/lib/python3.10/site-packages/pymysql/protocol.py", line 219, in raise_for_error
    err.raise_mysql_exception(self._data)
  File "/home/mstfrs/Desktop/ozerpan/env/lib/python3.10/site-packages/pymysql/err.py", line 150, in raise_mysql_exception
    raise errorclass(errno, errval)
pymysql.err.OperationalError: (1049, "Unknown database '_be61cf5335d3ad96'")
2024-10-09 10:00:00,711 ERROR scheduler Exception in Enqueue Events for Site ozerpan.local
Traceback (most recent call last):
  File "/home/mstfrs/Desktop/ozerpan/apps/frappe/frappe/utils/scheduler.py", line 106, in enqueue_events_for_site
    if is_scheduler_inactive():
  File "/home/mstfrs/Desktop/ozerpan/apps/frappe/frappe/utils/scheduler.py", line 150, in is_scheduler_inactive
    if is_scheduler_disabled(verbose=verbose):
  File "/home/mstfrs/Desktop/ozerpan/apps/frappe/frappe/utils/scheduler.py", line 163, in is_scheduler_disabled
    frappe.db.get_single_value("System Settings", "enable_scheduler")
  File "/home/mstfrs/Desktop/ozerpan/apps/frappe/frappe/database/database.py", line 846, in get_single_value
    ).run()
  File "/home/mstfrs/Desktop/ozerpan/apps/frappe/frappe/query_builder/utils.py", line 84, in execute_query
    result = frappe.db.sql(query, params, *args, **kwargs)  # nosemgrep
  File "/home/mstfrs/Desktop/ozerpan/apps/frappe/frappe/database/database.py", line 213, in sql
    self.connect()
  File "/home/mstfrs/Desktop/ozerpan/apps/frappe/frappe/database/database.py", line 118, in connect
    self._conn: "MariadbConnection" | "PostgresConnection" = self.get_connection()
  File "/home/mstfrs/Desktop/ozerpan/apps/frappe/frappe/database/mariadb/database.py", line 107, in get_connection
    conn = self._get_connection()
  File "/home/mstfrs/Desktop/ozerpan/apps/frappe/frappe/database/mariadb/database.py", line 113, in _get_connection
    return self.create_connection()
  File "/home/mstfrs/Desktop/ozerpan/apps/frappe/frappe/database/mariadb/database.py", line 116, in create_connection
    return pymysql.connect(**self.get_connection_settings())
  File "/home/mstfrs/Desktop/ozerpan/env/lib/python3.10/site-packages/pymysql/connections.py", line 361, in __init__
    self.connect()
  File "/home/mstfrs/Desktop/ozerpan/env/lib/python3.10/site-packages/pymysql/connections.py", line 669, in connect
    self._request_authentication()
  File "/home/mstfrs/Desktop/ozerpan/env/lib/python3.10/site-packages/pymysql/connections.py", line 957, in _request_authentication
    auth_packet = self._read_packet()
  File "/home/mstfrs/Desktop/ozerpan/env/lib/python3.10/site-packages/pymysql/connections.py", line 775, in _read_packet
    packet.raise_for_error()
  File "/home/mstfrs/Desktop/ozerpan/env/lib/python3.10/site-packages/pymysql/protocol.py", line 219, in raise_for_error
    err.raise_mysql_exception(self._data)
  File "/home/mstfrs/Desktop/ozerpan/env/lib/python3.10/site-packages/pymysql/err.py", line 150, in raise_mysql_exception
    raise errorclass(errno, errval)
pymysql.err.OperationalError: (1045, "Access denied for user '_c85c2ca7b22cd0b1'@'localhost' (using password: YES)")
2024-10-09 10:00:00,741 ERROR scheduler Exception in Enqueue Events for Site ozerpan
Traceback (most recent call last):
  File "/home/mstfrs/Desktop/ozerpan/apps/frappe/frappe/utils/scheduler.py", line 106, in enqueue_events_for_site
    if is_scheduler_inactive():
  File "/home/mstfrs/Desktop/ozerpan/apps/frappe/frappe/utils/scheduler.py", line 150, in is_scheduler_inactive
    if is_scheduler_disabled(verbose=verbose):
  File "/home/mstfrs/Desktop/ozerpan/apps/frappe/frappe/utils/scheduler.py", line 163, in is_scheduler_disabled
    frappe.db.get_single_value("System Settings", "enable_scheduler")
  File "/home/mstfrs/Desktop/ozerpan/apps/frappe/frappe/database/database.py", line 846, in get_single_value
    ).run()
  File "/home/mstfrs/Desktop/ozerpan/apps/frappe/frappe/query_builder/utils.py", line 84, in execute_query
    result = frappe.db.sql(query, params, *args, **kwargs)  # nosemgrep
  File "/home/mstfrs/Desktop/ozerpan/apps/frappe/frappe/database/database.py", line 213, in sql
    self.connect()
  File "/home/mstfrs/Desktop/ozerpan/apps/frappe/frappe/database/database.py", line 118, in connect
    self._conn: "MariadbConnection" | "PostgresConnection" = self.get_connection()
  File "/home/mstfrs/Desktop/ozerpan/apps/frappe/frappe/database/mariadb/database.py", line 107, in get_connection
    conn = self._get_connection()
  File "/home/mstfrs/Desktop/ozerpan/apps/frappe/frappe/database/mariadb/database.py", line 113, in _get_connection
    return self.create_connection()
  File "/home/mstfrs/Desktop/ozerpan/apps/frappe/frappe/database/mariadb/database.py", line 116, in create_connection
    return pymysql.connect(**self.get_connection_settings())
  File "/home/mstfrs/Desktop/ozerpan/env/lib/python3.10/site-packages/pymysql/connections.py", line 361, in __init__
    self.connect()
  File "/home/mstfrs/Desktop/ozerpan/env/lib/python3.10/site-packages/pymysql/connections.py", line 669, in connect
    self._request_authentication()
  File "/home/mstfrs/Desktop/ozerpan/env/lib/python3.10/site-packages/pymysql/connections.py", line 957, in _request_authentication
    auth_packet = self._read_packet()
  File "/home/mstfrs/Desktop/ozerpan/env/lib/python3.10/site-packages/pymysql/connections.py", line 775, in _read_packet
    packet.raise_for_error()
  File "/home/mstfrs/Desktop/ozerpan/env/lib/python3.10/site-packages/pymysql/protocol.py", line 219, in raise_for_error
    err.raise_mysql_exception(self._data)
  File "/home/mstfrs/Desktop/ozerpan/env/lib/python3.10/site-packages/pymysql/err.py", line 150, in raise_mysql_exception
    raise errorclass(errno, errval)
pymysql.err.OperationalError: (1049, "Unknown database '_be61cf5335d3ad96'")
2024-10-09 10:04:00,258 ERROR scheduler Exception in Enqueue Events for Site ozerpan.local
Traceback (most recent call last):
  File "/home/mstfrs/Desktop/ozerpan/apps/frappe/frappe/utils/scheduler.py", line 106, in enqueue_events_for_site
    if is_scheduler_inactive():
  File "/home/mstfrs/Desktop/ozerpan/apps/frappe/frappe/utils/scheduler.py", line 150, in is_scheduler_inactive
    if is_scheduler_disabled(verbose=verbose):
  File "/home/mstfrs/Desktop/ozerpan/apps/frappe/frappe/utils/scheduler.py", line 163, in is_scheduler_disabled
    frappe.db.get_single_value("System Settings", "enable_scheduler")
  File "/home/mstfrs/Desktop/ozerpan/apps/frappe/frappe/database/database.py", line 846, in get_single_value
    ).run()
  File "/home/mstfrs/Desktop/ozerpan/apps/frappe/frappe/query_builder/utils.py", line 84, in execute_query
    result = frappe.db.sql(query, params, *args, **kwargs)  # nosemgrep
  File "/home/mstfrs/Desktop/ozerpan/apps/frappe/frappe/database/database.py", line 213, in sql
    self.connect()
  File "/home/mstfrs/Desktop/ozerpan/apps/frappe/frappe/database/database.py", line 118, in connect
    self._conn: "MariadbConnection" | "PostgresConnection" = self.get_connection()
  File "/home/mstfrs/Desktop/ozerpan/apps/frappe/frappe/database/mariadb/database.py", line 107, in get_connection
    conn = self._get_connection()
  File "/home/mstfrs/Desktop/ozerpan/apps/frappe/frappe/database/mariadb/database.py", line 113, in _get_connection
    return self.create_connection()
  File "/home/mstfrs/Desktop/ozerpan/apps/frappe/frappe/database/mariadb/database.py", line 116, in create_connection
    return pymysql.connect(**self.get_connection_settings())
  File "/home/mstfrs/Desktop/ozerpan/env/lib/python3.10/site-packages/pymysql/connections.py", line 361, in __init__
    self.connect()
  File "/home/mstfrs/Desktop/ozerpan/env/lib/python3.10/site-packages/pymysql/connections.py", line 669, in connect
    self._request_authentication()
  File "/home/mstfrs/Desktop/ozerpan/env/lib/python3.10/site-packages/pymysql/connections.py", line 957, in _request_authentication
    auth_packet = self._read_packet()
  File "/home/mstfrs/Desktop/ozerpan/env/lib/python3.10/site-packages/pymysql/connections.py", line 775, in _read_packet
    packet.raise_for_error()
  File "/home/mstfrs/Desktop/ozerpan/env/lib/python3.10/site-packages/pymysql/protocol.py", line 219, in raise_for_error
    err.raise_mysql_exception(self._data)
  File "/home/mstfrs/Desktop/ozerpan/env/lib/python3.10/site-packages/pymysql/err.py", line 150, in raise_mysql_exception
    raise errorclass(errno, errval)
pymysql.err.OperationalError: (1045, "Access denied for user '_c85c2ca7b22cd0b1'@'localhost' (using password: YES)")
2024-10-09 10:04:00,260 ERROR scheduler Exception in Enqueue Events for Site ozerpan
Traceback (most recent call last):
  File "/home/mstfrs/Desktop/ozerpan/apps/frappe/frappe/utils/scheduler.py", line 106, in enqueue_events_for_site
    if is_scheduler_inactive():
  File "/home/mstfrs/Desktop/ozerpan/apps/frappe/frappe/utils/scheduler.py", line 150, in is_scheduler_inactive
    if is_scheduler_disabled(verbose=verbose):
  File "/home/mstfrs/Desktop/ozerpan/apps/frappe/frappe/utils/scheduler.py", line 163, in is_scheduler_disabled
    frappe.db.get_single_value("System Settings", "enable_scheduler")
  File "/home/mstfrs/Desktop/ozerpan/apps/frappe/frappe/database/database.py", line 846, in get_single_value
    ).run()
  File "/home/mstfrs/Desktop/ozerpan/apps/frappe/frappe/query_builder/utils.py", line 84, in execute_query
    result = frappe.db.sql(query, params, *args, **kwargs)  # nosemgrep
  File "/home/mstfrs/Desktop/ozerpan/apps/frappe/frappe/database/database.py", line 213, in sql
    self.connect()
  File "/home/mstfrs/Desktop/ozerpan/apps/frappe/frappe/database/database.py", line 118, in connect
    self._conn: "MariadbConnection" | "PostgresConnection" = self.get_connection()
  File "/home/mstfrs/Desktop/ozerpan/apps/frappe/frappe/database/mariadb/database.py", line 107, in get_connection
    conn = self._get_connection()
  File "/home/mstfrs/Desktop/ozerpan/apps/frappe/frappe/database/mariadb/database.py", line 113, in _get_connection
    return self.create_connection()
  File "/home/mstfrs/Desktop/ozerpan/apps/frappe/frappe/database/mariadb/database.py", line 116, in create_connection
    return pymysql.connect(**self.get_connection_settings())
  File "/home/mstfrs/Desktop/ozerpan/env/lib/python3.10/site-packages/pymysql/connections.py", line 361, in __init__
    self.connect()
  File "/home/mstfrs/Desktop/ozerpan/env/lib/python3.10/site-packages/pymysql/connections.py", line 669, in connect
    self._request_authentication()
  File "/home/mstfrs/Desktop/ozerpan/env/lib/python3.10/site-packages/pymysql/connections.py", line 957, in _request_authentication
    auth_packet = self._read_packet()
  File "/home/mstfrs/Desktop/ozerpan/env/lib/python3.10/site-packages/pymysql/connections.py", line 775, in _read_packet
    packet.raise_for_error()
  File "/home/mstfrs/Desktop/ozerpan/env/lib/python3.10/site-packages/pymysql/protocol.py", line 219, in raise_for_error
    err.raise_mysql_exception(self._data)
  File "/home/mstfrs/Desktop/ozerpan/env/lib/python3.10/site-packages/pymysql/err.py", line 150, in raise_mysql_exception
    raise errorclass(errno, errval)
pymysql.err.OperationalError: (1049, "Unknown database '_be61cf5335d3ad96'")
2024-10-09 10:08:01,007 ERROR scheduler Exception in Enqueue Events for Site ozerpan.local
Traceback (most recent call last):
  File "/home/mstfrs/Desktop/ozerpan/apps/frappe/frappe/utils/scheduler.py", line 106, in enqueue_events_for_site
    if is_scheduler_inactive():
  File "/home/mstfrs/Desktop/ozerpan/apps/frappe/frappe/utils/scheduler.py", line 150, in is_scheduler_inactive
    if is_scheduler_disabled(verbose=verbose):
  File "/home/mstfrs/Desktop/ozerpan/apps/frappe/frappe/utils/scheduler.py", line 163, in is_scheduler_disabled
    frappe.db.get_single_value("System Settings", "enable_scheduler")
  File "/home/mstfrs/Desktop/ozerpan/apps/frappe/frappe/database/database.py", line 846, in get_single_value
    ).run()
  File "/home/mstfrs/Desktop/ozerpan/apps/frappe/frappe/query_builder/utils.py", line 84, in execute_query
    result = frappe.db.sql(query, params, *args, **kwargs)  # nosemgrep
  File "/home/mstfrs/Desktop/ozerpan/apps/frappe/frappe/database/database.py", line 213, in sql
    self.connect()
  File "/home/mstfrs/Desktop/ozerpan/apps/frappe/frappe/database/database.py", line 118, in connect
    self._conn: "MariadbConnection" | "PostgresConnection" = self.get_connection()
  File "/home/mstfrs/Desktop/ozerpan/apps/frappe/frappe/database/mariadb/database.py", line 107, in get_connection
    conn = self._get_connection()
  File "/home/mstfrs/Desktop/ozerpan/apps/frappe/frappe/database/mariadb/database.py", line 113, in _get_connection
    return self.create_connection()
  File "/home/mstfrs/Desktop/ozerpan/apps/frappe/frappe/database/mariadb/database.py", line 116, in create_connection
    return pymysql.connect(**self.get_connection_settings())
  File "/home/mstfrs/Desktop/ozerpan/env/lib/python3.10/site-packages/pymysql/connections.py", line 361, in __init__
    self.connect()
  File "/home/mstfrs/Desktop/ozerpan/env/lib/python3.10/site-packages/pymysql/connections.py", line 669, in connect
    self._request_authentication()
  File "/home/mstfrs/Desktop/ozerpan/env/lib/python3.10/site-packages/pymysql/connections.py", line 957, in _request_authentication
    auth_packet = self._read_packet()
  File "/home/mstfrs/Desktop/ozerpan/env/lib/python3.10/site-packages/pymysql/connections.py", line 775, in _read_packet
    packet.raise_for_error()
  File "/home/mstfrs/Desktop/ozerpan/env/lib/python3.10/site-packages/pymysql/protocol.py", line 219, in raise_for_error
    err.raise_mysql_exception(self._data)
  File "/home/mstfrs/Desktop/ozerpan/env/lib/python3.10/site-packages/pymysql/err.py", line 150, in raise_mysql_exception
    raise errorclass(errno, errval)
pymysql.err.OperationalError: (1045, "Access denied for user '_c85c2ca7b22cd0b1'@'localhost' (using password: YES)")
2024-10-09 10:08:01,058 ERROR scheduler Exception in Enqueue Events for Site ozerpan
Traceback (most recent call last):
  File "/home/mstfrs/Desktop/ozerpan/apps/frappe/frappe/utils/scheduler.py", line 106, in enqueue_events_for_site
    if is_scheduler_inactive():
  File "/home/mstfrs/Desktop/ozerpan/apps/frappe/frappe/utils/scheduler.py", line 150, in is_scheduler_inactive
    if is_scheduler_disabled(verbose=verbose):
  File "/home/mstfrs/Desktop/ozerpan/apps/frappe/frappe/utils/scheduler.py", line 163, in is_scheduler_disabled
    frappe.db.get_single_value("System Settings", "enable_scheduler")
  File "/home/mstfrs/Desktop/ozerpan/apps/frappe/frappe/database/database.py", line 846, in get_single_value
    ).run()
  File "/home/mstfrs/Desktop/ozerpan/apps/frappe/frappe/query_builder/utils.py", line 84, in execute_query
    result = frappe.db.sql(query, params, *args, **kwargs)  # nosemgrep
  File "/home/mstfrs/Desktop/ozerpan/apps/frappe/frappe/database/database.py", line 213, in sql
    self.connect()
  File "/home/mstfrs/Desktop/ozerpan/apps/frappe/frappe/database/database.py", line 118, in connect
    self._conn: "MariadbConnection" | "PostgresConnection" = self.get_connection()
  File "/home/mstfrs/Desktop/ozerpan/apps/frappe/frappe/database/mariadb/database.py", line 107, in get_connection
    conn = self._get_connection()
  File "/home/mstfrs/Desktop/ozerpan/apps/frappe/frappe/database/mariadb/database.py", line 113, in _get_connection
    return self.create_connection()
  File "/home/mstfrs/Desktop/ozerpan/apps/frappe/frappe/database/mariadb/database.py", line 116, in create_connection
    return pymysql.connect(**self.get_connection_settings())
  File "/home/mstfrs/Desktop/ozerpan/env/lib/python3.10/site-packages/pymysql/connections.py", line 361, in __init__
    self.connect()
  File "/home/mstfrs/Desktop/ozerpan/env/lib/python3.10/site-packages/pymysql/connections.py", line 669, in connect
    self._request_authentication()
  File "/home/mstfrs/Desktop/ozerpan/env/lib/python3.10/site-packages/pymysql/connections.py", line 957, in _request_authentication
    auth_packet = self._read_packet()
  File "/home/mstfrs/Desktop/ozerpan/env/lib/python3.10/site-packages/pymysql/connections.py", line 775, in _read_packet
    packet.raise_for_error()
  File "/home/mstfrs/Desktop/ozerpan/env/lib/python3.10/site-packages/pymysql/protocol.py", line 219, in raise_for_error
    err.raise_mysql_exception(self._data)
  File "/home/mstfrs/Desktop/ozerpan/env/lib/python3.10/site-packages/pymysql/err.py", line 150, in raise_mysql_exception
    raise errorclass(errno, errval)
pymysql.err.OperationalError: (1049, "Unknown database '_be61cf5335d3ad96'")
2024-10-09 10:12:00,685 ERROR scheduler Exception in Enqueue Events for Site ozerpan
Traceback (most recent call last):
  File "/home/mstfrs/Desktop/ozerpan/apps/frappe/frappe/utils/scheduler.py", line 106, in enqueue_events_for_site
    if is_scheduler_inactive():
  File "/home/mstfrs/Desktop/ozerpan/apps/frappe/frappe/utils/scheduler.py", line 150, in is_scheduler_inactive
    if is_scheduler_disabled(verbose=verbose):
  File "/home/mstfrs/Desktop/ozerpan/apps/frappe/frappe/utils/scheduler.py", line 163, in is_scheduler_disabled
    frappe.db.get_single_value("System Settings", "enable_scheduler")
  File "/home/mstfrs/Desktop/ozerpan/apps/frappe/frappe/database/database.py", line 846, in get_single_value
    ).run()
  File "/home/mstfrs/Desktop/ozerpan/apps/frappe/frappe/query_builder/utils.py", line 84, in execute_query
    result = frappe.db.sql(query, params, *args, **kwargs)  # nosemgrep
  File "/home/mstfrs/Desktop/ozerpan/apps/frappe/frappe/database/database.py", line 213, in sql
    self.connect()
  File "/home/mstfrs/Desktop/ozerpan/apps/frappe/frappe/database/database.py", line 118, in connect
    self._conn: "MariadbConnection" | "PostgresConnection" = self.get_connection()
  File "/home/mstfrs/Desktop/ozerpan/apps/frappe/frappe/database/mariadb/database.py", line 107, in get_connection
    conn = self._get_connection()
  File "/home/mstfrs/Desktop/ozerpan/apps/frappe/frappe/database/mariadb/database.py", line 113, in _get_connection
    return self.create_connection()
  File "/home/mstfrs/Desktop/ozerpan/apps/frappe/frappe/database/mariadb/database.py", line 116, in create_connection
    return pymysql.connect(**self.get_connection_settings())
  File "/home/mstfrs/Desktop/ozerpan/env/lib/python3.10/site-packages/pymysql/connections.py", line 361, in __init__
    self.connect()
  File "/home/mstfrs/Desktop/ozerpan/env/lib/python3.10/site-packages/pymysql/connections.py", line 669, in connect
    self._request_authentication()
  File "/home/mstfrs/Desktop/ozerpan/env/lib/python3.10/site-packages/pymysql/connections.py", line 957, in _request_authentication
    auth_packet = self._read_packet()
  File "/home/mstfrs/Desktop/ozerpan/env/lib/python3.10/site-packages/pymysql/connections.py", line 775, in _read_packet
    packet.raise_for_error()
  File "/home/mstfrs/Desktop/ozerpan/env/lib/python3.10/site-packages/pymysql/protocol.py", line 219, in raise_for_error
    err.raise_mysql_exception(self._data)
  File "/home/mstfrs/Desktop/ozerpan/env/lib/python3.10/site-packages/pymysql/err.py", line 150, in raise_mysql_exception
    raise errorclass(errno, errval)
pymysql.err.OperationalError: (1049, "Unknown database '_be61cf5335d3ad96'")
2024-10-09 10:12:00,724 ERROR scheduler Exception in Enqueue Events for Site ozerpan.local
Traceback (most recent call last):
  File "/home/mstfrs/Desktop/ozerpan/apps/frappe/frappe/utils/scheduler.py", line 106, in enqueue_events_for_site
    if is_scheduler_inactive():
  File "/home/mstfrs/Desktop/ozerpan/apps/frappe/frappe/utils/scheduler.py", line 150, in is_scheduler_inactive
    if is_scheduler_disabled(verbose=verbose):
  File "/home/mstfrs/Desktop/ozerpan/apps/frappe/frappe/utils/scheduler.py", line 163, in is_scheduler_disabled
    frappe.db.get_single_value("System Settings", "enable_scheduler")
  File "/home/mstfrs/Desktop/ozerpan/apps/frappe/frappe/database/database.py", line 846, in get_single_value
    ).run()
  File "/home/mstfrs/Desktop/ozerpan/apps/frappe/frappe/query_builder/utils.py", line 84, in execute_query
    result = frappe.db.sql(query, params, *args, **kwargs)  # nosemgrep
  File "/home/mstfrs/Desktop/ozerpan/apps/frappe/frappe/database/database.py", line 213, in sql
    self.connect()
  File "/home/mstfrs/Desktop/ozerpan/apps/frappe/frappe/database/database.py", line 118, in connect
    self._conn: "MariadbConnection" | "PostgresConnection" = self.get_connection()
  File "/home/mstfrs/Desktop/ozerpan/apps/frappe/frappe/database/mariadb/database.py", line 107, in get_connection
    conn = self._get_connection()
  File "/home/mstfrs/Desktop/ozerpan/apps/frappe/frappe/database/mariadb/database.py", line 113, in _get_connection
    return self.create_connection()
  File "/home/mstfrs/Desktop/ozerpan/apps/frappe/frappe/database/mariadb/database.py", line 116, in create_connection
    return pymysql.connect(**self.get_connection_settings())
  File "/home/mstfrs/Desktop/ozerpan/env/lib/python3.10/site-packages/pymysql/connections.py", line 361, in __init__
    self.connect()
  File "/home/mstfrs/Desktop/ozerpan/env/lib/python3.10/site-packages/pymysql/connections.py", line 669, in connect
    self._request_authentication()
  File "/home/mstfrs/Desktop/ozerpan/env/lib/python3.10/site-packages/pymysql/connections.py", line 957, in _request_authentication
    auth_packet = self._read_packet()
  File "/home/mstfrs/Desktop/ozerpan/env/lib/python3.10/site-packages/pymysql/connections.py", line 775, in _read_packet
    packet.raise_for_error()
  File "/home/mstfrs/Desktop/ozerpan/env/lib/python3.10/site-packages/pymysql/protocol.py", line 219, in raise_for_error
    err.raise_mysql_exception(self._data)
  File "/home/mstfrs/Desktop/ozerpan/env/lib/python3.10/site-packages/pymysql/err.py", line 150, in raise_mysql_exception
    raise errorclass(errno, errval)
pymysql.err.OperationalError: (1045, "Access denied for user '_c85c2ca7b22cd0b1'@'localhost' (using password: YES)")
2024-10-09 10:16:01,186 ERROR scheduler Exception in Enqueue Events for Site ozerpan.local
Traceback (most recent call last):
  File "/home/mstfrs/Desktop/ozerpan/apps/frappe/frappe/utils/scheduler.py", line 106, in enqueue_events_for_site
    if is_scheduler_inactive():
  File "/home/mstfrs/Desktop/ozerpan/apps/frappe/frappe/utils/scheduler.py", line 150, in is_scheduler_inactive
    if is_scheduler_disabled(verbose=verbose):
  File "/home/mstfrs/Desktop/ozerpan/apps/frappe/frappe/utils/scheduler.py", line 163, in is_scheduler_disabled
    frappe.db.get_single_value("System Settings", "enable_scheduler")
  File "/home/mstfrs/Desktop/ozerpan/apps/frappe/frappe/database/database.py", line 846, in get_single_value
    ).run()
  File "/home/mstfrs/Desktop/ozerpan/apps/frappe/frappe/query_builder/utils.py", line 84, in execute_query
    result = frappe.db.sql(query, params, *args, **kwargs)  # nosemgrep
  File "/home/mstfrs/Desktop/ozerpan/apps/frappe/frappe/database/database.py", line 213, in sql
    self.connect()
  File "/home/mstfrs/Desktop/ozerpan/apps/frappe/frappe/database/database.py", line 118, in connect
    self._conn: "MariadbConnection" | "PostgresConnection" = self.get_connection()
  File "/home/mstfrs/Desktop/ozerpan/apps/frappe/frappe/database/mariadb/database.py", line 107, in get_connection
    conn = self._get_connection()
  File "/home/mstfrs/Desktop/ozerpan/apps/frappe/frappe/database/mariadb/database.py", line 113, in _get_connection
    return self.create_connection()
  File "/home/mstfrs/Desktop/ozerpan/apps/frappe/frappe/database/mariadb/database.py", line 116, in create_connection
    return pymysql.connect(**self.get_connection_settings())
  File "/home/mstfrs/Desktop/ozerpan/env/lib/python3.10/site-packages/pymysql/connections.py", line 361, in __init__
    self.connect()
  File "/home/mstfrs/Desktop/ozerpan/env/lib/python3.10/site-packages/pymysql/connections.py", line 669, in connect
    self._request_authentication()
  File "/home/mstfrs/Desktop/ozerpan/env/lib/python3.10/site-packages/pymysql/connections.py", line 957, in _request_authentication
    auth_packet = self._read_packet()
  File "/home/mstfrs/Desktop/ozerpan/env/lib/python3.10/site-packages/pymysql/connections.py", line 775, in _read_packet
    packet.raise_for_error()
  File "/home/mstfrs/Desktop/ozerpan/env/lib/python3.10/site-packages/pymysql/protocol.py", line 219, in raise_for_error
    err.raise_mysql_exception(self._data)
  File "/home/mstfrs/Desktop/ozerpan/env/lib/python3.10/site-packages/pymysql/err.py", line 150, in raise_mysql_exception
    raise errorclass(errno, errval)
pymysql.err.OperationalError: (1045, "Access denied for user '_c85c2ca7b22cd0b1'@'localhost' (using password: YES)")
2024-10-09 10:16:01,189 ERROR scheduler Exception in Enqueue Events for Site ozerpan
Traceback (most recent call last):
  File "/home/mstfrs/Desktop/ozerpan/apps/frappe/frappe/utils/scheduler.py", line 106, in enqueue_events_for_site
    if is_scheduler_inactive():
  File "/home/mstfrs/Desktop/ozerpan/apps/frappe/frappe/utils/scheduler.py", line 150, in is_scheduler_inactive
    if is_scheduler_disabled(verbose=verbose):
  File "/home/mstfrs/Desktop/ozerpan/apps/frappe/frappe/utils/scheduler.py", line 163, in is_scheduler_disabled
    frappe.db.get_single_value("System Settings", "enable_scheduler")
  File "/home/mstfrs/Desktop/ozerpan/apps/frappe/frappe/database/database.py", line 846, in get_single_value
    ).run()
  File "/home/mstfrs/Desktop/ozerpan/apps/frappe/frappe/query_builder/utils.py", line 84, in execute_query
    result = frappe.db.sql(query, params, *args, **kwargs)  # nosemgrep
  File "/home/mstfrs/Desktop/ozerpan/apps/frappe/frappe/database/database.py", line 213, in sql
    self.connect()
  File "/home/mstfrs/Desktop/ozerpan/apps/frappe/frappe/database/database.py", line 118, in connect
    self._conn: "MariadbConnection" | "PostgresConnection" = self.get_connection()
  File "/home/mstfrs/Desktop/ozerpan/apps/frappe/frappe/database/mariadb/database.py", line 107, in get_connection
    conn = self._get_connection()
  File "/home/mstfrs/Desktop/ozerpan/apps/frappe/frappe/database/mariadb/database.py", line 113, in _get_connection
    return self.create_connection()
  File "/home/mstfrs/Desktop/ozerpan/apps/frappe/frappe/database/mariadb/database.py", line 116, in create_connection
    return pymysql.connect(**self.get_connection_settings())
  File "/home/mstfrs/Desktop/ozerpan/env/lib/python3.10/site-packages/pymysql/connections.py", line 361, in __init__
    self.connect()
  File "/home/mstfrs/Desktop/ozerpan/env/lib/python3.10/site-packages/pymysql/connections.py", line 669, in connect
    self._request_authentication()
  File "/home/mstfrs/Desktop/ozerpan/env/lib/python3.10/site-packages/pymysql/connections.py", line 957, in _request_authentication
    auth_packet = self._read_packet()
  File "/home/mstfrs/Desktop/ozerpan/env/lib/python3.10/site-packages/pymysql/connections.py", line 775, in _read_packet
    packet.raise_for_error()
  File "/home/mstfrs/Desktop/ozerpan/env/lib/python3.10/site-packages/pymysql/protocol.py", line 219, in raise_for_error
    err.raise_mysql_exception(self._data)
  File "/home/mstfrs/Desktop/ozerpan/env/lib/python3.10/site-packages/pymysql/err.py", line 150, in raise_mysql_exception
    raise errorclass(errno, errval)
pymysql.err.OperationalError: (1049, "Unknown database '_be61cf5335d3ad96'")
2024-10-09 10:20:00,332 ERROR scheduler Exception in Enqueue Events for Site ozerpan
Traceback (most recent call last):
  File "/home/mstfrs/Desktop/ozerpan/apps/frappe/frappe/utils/scheduler.py", line 106, in enqueue_events_for_site
    if is_scheduler_inactive():
  File "/home/mstfrs/Desktop/ozerpan/apps/frappe/frappe/utils/scheduler.py", line 150, in is_scheduler_inactive
    if is_scheduler_disabled(verbose=verbose):
  File "/home/mstfrs/Desktop/ozerpan/apps/frappe/frappe/utils/scheduler.py", line 163, in is_scheduler_disabled
    frappe.db.get_single_value("System Settings", "enable_scheduler")
  File "/home/mstfrs/Desktop/ozerpan/apps/frappe/frappe/database/database.py", line 846, in get_single_value
    ).run()
  File "/home/mstfrs/Desktop/ozerpan/apps/frappe/frappe/query_builder/utils.py", line 84, in execute_query
    result = frappe.db.sql(query, params, *args, **kwargs)  # nosemgrep
  File "/home/mstfrs/Desktop/ozerpan/apps/frappe/frappe/database/database.py", line 213, in sql
    self.connect()
  File "/home/mstfrs/Desktop/ozerpan/apps/frappe/frappe/database/database.py", line 118, in connect
    self._conn: "MariadbConnection" | "PostgresConnection" = self.get_connection()
  File "/home/mstfrs/Desktop/ozerpan/apps/frappe/frappe/database/mariadb/database.py", line 107, in get_connection
    conn = self._get_connection()
  File "/home/mstfrs/Desktop/ozerpan/apps/frappe/frappe/database/mariadb/database.py", line 113, in _get_connection
    return self.create_connection()
  File "/home/mstfrs/Desktop/ozerpan/apps/frappe/frappe/database/mariadb/database.py", line 116, in create_connection
    return pymysql.connect(**self.get_connection_settings())
  File "/home/mstfrs/Desktop/ozerpan/env/lib/python3.10/site-packages/pymysql/connections.py", line 361, in __init__
    self.connect()
  File "/home/mstfrs/Desktop/ozerpan/env/lib/python3.10/site-packages/pymysql/connections.py", line 669, in connect
    self._request_authentication()
  File "/home/mstfrs/Desktop/ozerpan/env/lib/python3.10/site-packages/pymysql/connections.py", line 957, in _request_authentication
    auth_packet = self._read_packet()
  File "/home/mstfrs/Desktop/ozerpan/env/lib/python3.10/site-packages/pymysql/connections.py", line 775, in _read_packet
    packet.raise_for_error()
  File "/home/mstfrs/Desktop/ozerpan/env/lib/python3.10/site-packages/pymysql/protocol.py", line 219, in raise_for_error
    err.raise_mysql_exception(self._data)
  File "/home/mstfrs/Desktop/ozerpan/env/lib/python3.10/site-packages/pymysql/err.py", line 150, in raise_mysql_exception
    raise errorclass(errno, errval)
pymysql.err.OperationalError: (1049, "Unknown database '_be61cf5335d3ad96'")
2024-10-09 10:20:00,911 ERROR scheduler Exception in Enqueue Events for Site ozerpan.local
Traceback (most recent call last):
  File "/home/mstfrs/Desktop/ozerpan/apps/frappe/frappe/utils/scheduler.py", line 106, in enqueue_events_for_site
    if is_scheduler_inactive():
  File "/home/mstfrs/Desktop/ozerpan/apps/frappe/frappe/utils/scheduler.py", line 150, in is_scheduler_inactive
    if is_scheduler_disabled(verbose=verbose):
  File "/home/mstfrs/Desktop/ozerpan/apps/frappe/frappe/utils/scheduler.py", line 163, in is_scheduler_disabled
    frappe.db.get_single_value("System Settings", "enable_scheduler")
  File "/home/mstfrs/Desktop/ozerpan/apps/frappe/frappe/database/database.py", line 846, in get_single_value
    ).run()
  File "/home/mstfrs/Desktop/ozerpan/apps/frappe/frappe/query_builder/utils.py", line 84, in execute_query
    result = frappe.db.sql(query, params, *args, **kwargs)  # nosemgrep
  File "/home/mstfrs/Desktop/ozerpan/apps/frappe/frappe/database/database.py", line 213, in sql
    self.connect()
  File "/home/mstfrs/Desktop/ozerpan/apps/frappe/frappe/database/database.py", line 118, in connect
    self._conn: "MariadbConnection" | "PostgresConnection" = self.get_connection()
  File "/home/mstfrs/Desktop/ozerpan/apps/frappe/frappe/database/mariadb/database.py", line 107, in get_connection
    conn = self._get_connection()
  File "/home/mstfrs/Desktop/ozerpan/apps/frappe/frappe/database/mariadb/database.py", line 113, in _get_connection
    return self.create_connection()
  File "/home/mstfrs/Desktop/ozerpan/apps/frappe/frappe/database/mariadb/database.py", line 116, in create_connection
    return pymysql.connect(**self.get_connection_settings())
  File "/home/mstfrs/Desktop/ozerpan/env/lib/python3.10/site-packages/pymysql/connections.py", line 361, in __init__
    self.connect()
  File "/home/mstfrs/Desktop/ozerpan/env/lib/python3.10/site-packages/pymysql/connections.py", line 669, in connect
    self._request_authentication()
  File "/home/mstfrs/Desktop/ozerpan/env/lib/python3.10/site-packages/pymysql/connections.py", line 957, in _request_authentication
    auth_packet = self._read_packet()
  File "/home/mstfrs/Desktop/ozerpan/env/lib/python3.10/site-packages/pymysql/connections.py", line 775, in _read_packet
    packet.raise_for_error()
  File "/home/mstfrs/Desktop/ozerpan/env/lib/python3.10/site-packages/pymysql/protocol.py", line 219, in raise_for_error
    err.raise_mysql_exception(self._data)
  File "/home/mstfrs/Desktop/ozerpan/env/lib/python3.10/site-packages/pymysql/err.py", line 150, in raise_mysql_exception
    raise errorclass(errno, errval)
pymysql.err.OperationalError: (1045, "Access denied for user '_c85c2ca7b22cd0b1'@'localhost' (using password: YES)")
2024-10-09 10:24:01,039 ERROR scheduler Exception in Enqueue Events for Site ozerpan
Traceback (most recent call last):
  File "/home/mstfrs/Desktop/ozerpan/apps/frappe/frappe/utils/scheduler.py", line 106, in enqueue_events_for_site
    if is_scheduler_inactive():
  File "/home/mstfrs/Desktop/ozerpan/apps/frappe/frappe/utils/scheduler.py", line 150, in is_scheduler_inactive
    if is_scheduler_disabled(verbose=verbose):
  File "/home/mstfrs/Desktop/ozerpan/apps/frappe/frappe/utils/scheduler.py", line 163, in is_scheduler_disabled
    frappe.db.get_single_value("System Settings", "enable_scheduler")
  File "/home/mstfrs/Desktop/ozerpan/apps/frappe/frappe/database/database.py", line 846, in get_single_value
    ).run()
  File "/home/mstfrs/Desktop/ozerpan/apps/frappe/frappe/query_builder/utils.py", line 84, in execute_query
    result = frappe.db.sql(query, params, *args, **kwargs)  # nosemgrep
  File "/home/mstfrs/Desktop/ozerpan/apps/frappe/frappe/database/database.py", line 213, in sql
    self.connect()
  File "/home/mstfrs/Desktop/ozerpan/apps/frappe/frappe/database/database.py", line 118, in connect
    self._conn: "MariadbConnection" | "PostgresConnection" = self.get_connection()
  File "/home/mstfrs/Desktop/ozerpan/apps/frappe/frappe/database/mariadb/database.py", line 107, in get_connection
    conn = self._get_connection()
  File "/home/mstfrs/Desktop/ozerpan/apps/frappe/frappe/database/mariadb/database.py", line 113, in _get_connection
    return self.create_connection()
  File "/home/mstfrs/Desktop/ozerpan/apps/frappe/frappe/database/mariadb/database.py", line 116, in create_connection
    return pymysql.connect(**self.get_connection_settings())
  File "/home/mstfrs/Desktop/ozerpan/env/lib/python3.10/site-packages/pymysql/connections.py", line 361, in __init__
    self.connect()
  File "/home/mstfrs/Desktop/ozerpan/env/lib/python3.10/site-packages/pymysql/connections.py", line 669, in connect
    self._request_authentication()
  File "/home/mstfrs/Desktop/ozerpan/env/lib/python3.10/site-packages/pymysql/connections.py", line 957, in _request_authentication
    auth_packet = self._read_packet()
  File "/home/mstfrs/Desktop/ozerpan/env/lib/python3.10/site-packages/pymysql/connections.py", line 775, in _read_packet
    packet.raise_for_error()
  File "/home/mstfrs/Desktop/ozerpan/env/lib/python3.10/site-packages/pymysql/protocol.py", line 219, in raise_for_error
    err.raise_mysql_exception(self._data)
  File "/home/mstfrs/Desktop/ozerpan/env/lib/python3.10/site-packages/pymysql/err.py", line 150, in raise_mysql_exception
    raise errorclass(errno, errval)
pymysql.err.OperationalError: (1049, "Unknown database '_be61cf5335d3ad96'")
2024-10-09 10:24:01,098 ERROR scheduler Exception in Enqueue Events for Site ozerpan.local
Traceback (most recent call last):
  File "/home/mstfrs/Desktop/ozerpan/apps/frappe/frappe/utils/scheduler.py", line 106, in enqueue_events_for_site
    if is_scheduler_inactive():
  File "/home/mstfrs/Desktop/ozerpan/apps/frappe/frappe/utils/scheduler.py", line 150, in is_scheduler_inactive
    if is_scheduler_disabled(verbose=verbose):
  File "/home/mstfrs/Desktop/ozerpan/apps/frappe/frappe/utils/scheduler.py", line 163, in is_scheduler_disabled
    frappe.db.get_single_value("System Settings", "enable_scheduler")
  File "/home/mstfrs/Desktop/ozerpan/apps/frappe/frappe/database/database.py", line 846, in get_single_value
    ).run()
  File "/home/mstfrs/Desktop/ozerpan/apps/frappe/frappe/query_builder/utils.py", line 84, in execute_query
    result = frappe.db.sql(query, params, *args, **kwargs)  # nosemgrep
  File "/home/mstfrs/Desktop/ozerpan/apps/frappe/frappe/database/database.py", line 213, in sql
    self.connect()
  File "/home/mstfrs/Desktop/ozerpan/apps/frappe/frappe/database/database.py", line 118, in connect
    self._conn: "MariadbConnection" | "PostgresConnection" = self.get_connection()
  File "/home/mstfrs/Desktop/ozerpan/apps/frappe/frappe/database/mariadb/database.py", line 107, in get_connection
    conn = self._get_connection()
  File "/home/mstfrs/Desktop/ozerpan/apps/frappe/frappe/database/mariadb/database.py", line 113, in _get_connection
    return self.create_connection()
  File "/home/mstfrs/Desktop/ozerpan/apps/frappe/frappe/database/mariadb/database.py", line 116, in create_connection
    return pymysql.connect(**self.get_connection_settings())
  File "/home/mstfrs/Desktop/ozerpan/env/lib/python3.10/site-packages/pymysql/connections.py", line 361, in __init__
    self.connect()
  File "/home/mstfrs/Desktop/ozerpan/env/lib/python3.10/site-packages/pymysql/connections.py", line 669, in connect
    self._request_authentication()
  File "/home/mstfrs/Desktop/ozerpan/env/lib/python3.10/site-packages/pymysql/connections.py", line 957, in _request_authentication
    auth_packet = self._read_packet()
  File "/home/mstfrs/Desktop/ozerpan/env/lib/python3.10/site-packages/pymysql/connections.py", line 775, in _read_packet
    packet.raise_for_error()
  File "/home/mstfrs/Desktop/ozerpan/env/lib/python3.10/site-packages/pymysql/protocol.py", line 219, in raise_for_error
    err.raise_mysql_exception(self._data)
  File "/home/mstfrs/Desktop/ozerpan/env/lib/python3.10/site-packages/pymysql/err.py", line 150, in raise_mysql_exception
    raise errorclass(errno, errval)
pymysql.err.OperationalError: (1045, "Access denied for user '_c85c2ca7b22cd0b1'@'localhost' (using password: YES)")
2024-10-09 10:28:00,706 ERROR scheduler Exception in Enqueue Events for Site ozerpan
Traceback (most recent call last):
  File "/home/mstfrs/Desktop/ozerpan/apps/frappe/frappe/utils/scheduler.py", line 106, in enqueue_events_for_site
    if is_scheduler_inactive():
  File "/home/mstfrs/Desktop/ozerpan/apps/frappe/frappe/utils/scheduler.py", line 150, in is_scheduler_inactive
    if is_scheduler_disabled(verbose=verbose):
  File "/home/mstfrs/Desktop/ozerpan/apps/frappe/frappe/utils/scheduler.py", line 163, in is_scheduler_disabled
    frappe.db.get_single_value("System Settings", "enable_scheduler")
  File "/home/mstfrs/Desktop/ozerpan/apps/frappe/frappe/database/database.py", line 846, in get_single_value
    ).run()
  File "/home/mstfrs/Desktop/ozerpan/apps/frappe/frappe/query_builder/utils.py", line 84, in execute_query
    result = frappe.db.sql(query, params, *args, **kwargs)  # nosemgrep
  File "/home/mstfrs/Desktop/ozerpan/apps/frappe/frappe/database/database.py", line 213, in sql
    self.connect()
  File "/home/mstfrs/Desktop/ozerpan/apps/frappe/frappe/database/database.py", line 118, in connect
    self._conn: "MariadbConnection" | "PostgresConnection" = self.get_connection()
  File "/home/mstfrs/Desktop/ozerpan/apps/frappe/frappe/database/mariadb/database.py", line 107, in get_connection
    conn = self._get_connection()
  File "/home/mstfrs/Desktop/ozerpan/apps/frappe/frappe/database/mariadb/database.py", line 113, in _get_connection
    return self.create_connection()
  File "/home/mstfrs/Desktop/ozerpan/apps/frappe/frappe/database/mariadb/database.py", line 116, in create_connection
    return pymysql.connect(**self.get_connection_settings())
  File "/home/mstfrs/Desktop/ozerpan/env/lib/python3.10/site-packages/pymysql/connections.py", line 361, in __init__
    self.connect()
  File "/home/mstfrs/Desktop/ozerpan/env/lib/python3.10/site-packages/pymysql/connections.py", line 669, in connect
    self._request_authentication()
  File "/home/mstfrs/Desktop/ozerpan/env/lib/python3.10/site-packages/pymysql/connections.py", line 957, in _request_authentication
    auth_packet = self._read_packet()
  File "/home/mstfrs/Desktop/ozerpan/env/lib/python3.10/site-packages/pymysql/connections.py", line 775, in _read_packet
    packet.raise_for_error()
  File "/home/mstfrs/Desktop/ozerpan/env/lib/python3.10/site-packages/pymysql/protocol.py", line 219, in raise_for_error
    err.raise_mysql_exception(self._data)
  File "/home/mstfrs/Desktop/ozerpan/env/lib/python3.10/site-packages/pymysql/err.py", line 150, in raise_mysql_exception
    raise errorclass(errno, errval)
pymysql.err.OperationalError: (1049, "Unknown database '_be61cf5335d3ad96'")
2024-10-09 10:28:01,119 ERROR scheduler Exception in Enqueue Events for Site ozerpan.local
Traceback (most recent call last):
  File "/home/mstfrs/Desktop/ozerpan/apps/frappe/frappe/utils/scheduler.py", line 106, in enqueue_events_for_site
    if is_scheduler_inactive():
  File "/home/mstfrs/Desktop/ozerpan/apps/frappe/frappe/utils/scheduler.py", line 150, in is_scheduler_inactive
    if is_scheduler_disabled(verbose=verbose):
  File "/home/mstfrs/Desktop/ozerpan/apps/frappe/frappe/utils/scheduler.py", line 163, in is_scheduler_disabled
    frappe.db.get_single_value("System Settings", "enable_scheduler")
  File "/home/mstfrs/Desktop/ozerpan/apps/frappe/frappe/database/database.py", line 846, in get_single_value
    ).run()
  File "/home/mstfrs/Desktop/ozerpan/apps/frappe/frappe/query_builder/utils.py", line 84, in execute_query
    result = frappe.db.sql(query, params, *args, **kwargs)  # nosemgrep
  File "/home/mstfrs/Desktop/ozerpan/apps/frappe/frappe/database/database.py", line 213, in sql
    self.connect()
  File "/home/mstfrs/Desktop/ozerpan/apps/frappe/frappe/database/database.py", line 118, in connect
    self._conn: "MariadbConnection" | "PostgresConnection" = self.get_connection()
  File "/home/mstfrs/Desktop/ozerpan/apps/frappe/frappe/database/mariadb/database.py", line 107, in get_connection
    conn = self._get_connection()
  File "/home/mstfrs/Desktop/ozerpan/apps/frappe/frappe/database/mariadb/database.py", line 113, in _get_connection
    return self.create_connection()
  File "/home/mstfrs/Desktop/ozerpan/apps/frappe/frappe/database/mariadb/database.py", line 116, in create_connection
    return pymysql.connect(**self.get_connection_settings())
  File "/home/mstfrs/Desktop/ozerpan/env/lib/python3.10/site-packages/pymysql/connections.py", line 361, in __init__
    self.connect()
  File "/home/mstfrs/Desktop/ozerpan/env/lib/python3.10/site-packages/pymysql/connections.py", line 669, in connect
    self._request_authentication()
  File "/home/mstfrs/Desktop/ozerpan/env/lib/python3.10/site-packages/pymysql/connections.py", line 957, in _request_authentication
    auth_packet = self._read_packet()
  File "/home/mstfrs/Desktop/ozerpan/env/lib/python3.10/site-packages/pymysql/connections.py", line 775, in _read_packet
    packet.raise_for_error()
  File "/home/mstfrs/Desktop/ozerpan/env/lib/python3.10/site-packages/pymysql/protocol.py", line 219, in raise_for_error
    err.raise_mysql_exception(self._data)
  File "/home/mstfrs/Desktop/ozerpan/env/lib/python3.10/site-packages/pymysql/err.py", line 150, in raise_mysql_exception
    raise errorclass(errno, errval)
pymysql.err.OperationalError: (1045, "Access denied for user '_c85c2ca7b22cd0b1'@'localhost' (using password: YES)")
2024-10-09 10:32:00,215 ERROR scheduler Exception in Enqueue Events for Site ozerpan
Traceback (most recent call last):
  File "/home/mstfrs/Desktop/ozerpan/apps/frappe/frappe/utils/scheduler.py", line 106, in enqueue_events_for_site
    if is_scheduler_inactive():
  File "/home/mstfrs/Desktop/ozerpan/apps/frappe/frappe/utils/scheduler.py", line 150, in is_scheduler_inactive
    if is_scheduler_disabled(verbose=verbose):
  File "/home/mstfrs/Desktop/ozerpan/apps/frappe/frappe/utils/scheduler.py", line 163, in is_scheduler_disabled
    frappe.db.get_single_value("System Settings", "enable_scheduler")
  File "/home/mstfrs/Desktop/ozerpan/apps/frappe/frappe/database/database.py", line 846, in get_single_value
    ).run()
  File "/home/mstfrs/Desktop/ozerpan/apps/frappe/frappe/query_builder/utils.py", line 84, in execute_query
    result = frappe.db.sql(query, params, *args, **kwargs)  # nosemgrep
  File "/home/mstfrs/Desktop/ozerpan/apps/frappe/frappe/database/database.py", line 213, in sql
    self.connect()
  File "/home/mstfrs/Desktop/ozerpan/apps/frappe/frappe/database/database.py", line 118, in connect
    self._conn: "MariadbConnection" | "PostgresConnection" = self.get_connection()
  File "/home/mstfrs/Desktop/ozerpan/apps/frappe/frappe/database/mariadb/database.py", line 107, in get_connection
    conn = self._get_connection()
  File "/home/mstfrs/Desktop/ozerpan/apps/frappe/frappe/database/mariadb/database.py", line 113, in _get_connection
    return self.create_connection()
  File "/home/mstfrs/Desktop/ozerpan/apps/frappe/frappe/database/mariadb/database.py", line 116, in create_connection
    return pymysql.connect(**self.get_connection_settings())
  File "/home/mstfrs/Desktop/ozerpan/env/lib/python3.10/site-packages/pymysql/connections.py", line 361, in __init__
    self.connect()
  File "/home/mstfrs/Desktop/ozerpan/env/lib/python3.10/site-packages/pymysql/connections.py", line 669, in connect
    self._request_authentication()
  File "/home/mstfrs/Desktop/ozerpan/env/lib/python3.10/site-packages/pymysql/connections.py", line 957, in _request_authentication
    auth_packet = self._read_packet()
  File "/home/mstfrs/Desktop/ozerpan/env/lib/python3.10/site-packages/pymysql/connections.py", line 775, in _read_packet
    packet.raise_for_error()
  File "/home/mstfrs/Desktop/ozerpan/env/lib/python3.10/site-packages/pymysql/protocol.py", line 219, in raise_for_error
    err.raise_mysql_exception(self._data)
  File "/home/mstfrs/Desktop/ozerpan/env/lib/python3.10/site-packages/pymysql/err.py", line 150, in raise_mysql_exception
    raise errorclass(errno, errval)
pymysql.err.OperationalError: (1049, "Unknown database '_be61cf5335d3ad96'")
2024-10-09 10:32:00,597 ERROR scheduler Exception in Enqueue Events for Site ozerpan.local
Traceback (most recent call last):
  File "/home/mstfrs/Desktop/ozerpan/apps/frappe/frappe/utils/scheduler.py", line 106, in enqueue_events_for_site
    if is_scheduler_inactive():
  File "/home/mstfrs/Desktop/ozerpan/apps/frappe/frappe/utils/scheduler.py", line 150, in is_scheduler_inactive
    if is_scheduler_disabled(verbose=verbose):
  File "/home/mstfrs/Desktop/ozerpan/apps/frappe/frappe/utils/scheduler.py", line 163, in is_scheduler_disabled
    frappe.db.get_single_value("System Settings", "enable_scheduler")
  File "/home/mstfrs/Desktop/ozerpan/apps/frappe/frappe/database/database.py", line 846, in get_single_value
    ).run()
  File "/home/mstfrs/Desktop/ozerpan/apps/frappe/frappe/query_builder/utils.py", line 84, in execute_query
    result = frappe.db.sql(query, params, *args, **kwargs)  # nosemgrep
  File "/home/mstfrs/Desktop/ozerpan/apps/frappe/frappe/database/database.py", line 213, in sql
    self.connect()
  File "/home/mstfrs/Desktop/ozerpan/apps/frappe/frappe/database/database.py", line 118, in connect
    self._conn: "MariadbConnection" | "PostgresConnection" = self.get_connection()
  File "/home/mstfrs/Desktop/ozerpan/apps/frappe/frappe/database/mariadb/database.py", line 107, in get_connection
    conn = self._get_connection()
  File "/home/mstfrs/Desktop/ozerpan/apps/frappe/frappe/database/mariadb/database.py", line 113, in _get_connection
    return self.create_connection()
  File "/home/mstfrs/Desktop/ozerpan/apps/frappe/frappe/database/mariadb/database.py", line 116, in create_connection
    return pymysql.connect(**self.get_connection_settings())
  File "/home/mstfrs/Desktop/ozerpan/env/lib/python3.10/site-packages/pymysql/connections.py", line 361, in __init__
    self.connect()
  File "/home/mstfrs/Desktop/ozerpan/env/lib/python3.10/site-packages/pymysql/connections.py", line 669, in connect
    self._request_authentication()
  File "/home/mstfrs/Desktop/ozerpan/env/lib/python3.10/site-packages/pymysql/connections.py", line 957, in _request_authentication
    auth_packet = self._read_packet()
  File "/home/mstfrs/Desktop/ozerpan/env/lib/python3.10/site-packages/pymysql/connections.py", line 775, in _read_packet
    packet.raise_for_error()
  File "/home/mstfrs/Desktop/ozerpan/env/lib/python3.10/site-packages/pymysql/protocol.py", line 219, in raise_for_error
    err.raise_mysql_exception(self._data)
  File "/home/mstfrs/Desktop/ozerpan/env/lib/python3.10/site-packages/pymysql/err.py", line 150, in raise_mysql_exception
    raise errorclass(errno, errval)
pymysql.err.OperationalError: (1045, "Access denied for user '_c85c2ca7b22cd0b1'@'localhost' (using password: YES)")
2024-10-09 10:36:00,713 ERROR scheduler Exception in Enqueue Events for Site ozerpan
Traceback (most recent call last):
  File "/home/mstfrs/Desktop/ozerpan/apps/frappe/frappe/utils/scheduler.py", line 106, in enqueue_events_for_site
    if is_scheduler_inactive():
  File "/home/mstfrs/Desktop/ozerpan/apps/frappe/frappe/utils/scheduler.py", line 150, in is_scheduler_inactive
    if is_scheduler_disabled(verbose=verbose):
  File "/home/mstfrs/Desktop/ozerpan/apps/frappe/frappe/utils/scheduler.py", line 163, in is_scheduler_disabled
    frappe.db.get_single_value("System Settings", "enable_scheduler")
  File "/home/mstfrs/Desktop/ozerpan/apps/frappe/frappe/database/database.py", line 846, in get_single_value
    ).run()
  File "/home/mstfrs/Desktop/ozerpan/apps/frappe/frappe/query_builder/utils.py", line 84, in execute_query
    result = frappe.db.sql(query, params, *args, **kwargs)  # nosemgrep
  File "/home/mstfrs/Desktop/ozerpan/apps/frappe/frappe/database/database.py", line 213, in sql
    self.connect()
  File "/home/mstfrs/Desktop/ozerpan/apps/frappe/frappe/database/database.py", line 118, in connect
    self._conn: "MariadbConnection" | "PostgresConnection" = self.get_connection()
  File "/home/mstfrs/Desktop/ozerpan/apps/frappe/frappe/database/mariadb/database.py", line 107, in get_connection
    conn = self._get_connection()
  File "/home/mstfrs/Desktop/ozerpan/apps/frappe/frappe/database/mariadb/database.py", line 113, in _get_connection
    return self.create_connection()
  File "/home/mstfrs/Desktop/ozerpan/apps/frappe/frappe/database/mariadb/database.py", line 116, in create_connection
    return pymysql.connect(**self.get_connection_settings())
  File "/home/mstfrs/Desktop/ozerpan/env/lib/python3.10/site-packages/pymysql/connections.py", line 361, in __init__
    self.connect()
  File "/home/mstfrs/Desktop/ozerpan/env/lib/python3.10/site-packages/pymysql/connections.py", line 669, in connect
    self._request_authentication()
  File "/home/mstfrs/Desktop/ozerpan/env/lib/python3.10/site-packages/pymysql/connections.py", line 957, in _request_authentication
    auth_packet = self._read_packet()
  File "/home/mstfrs/Desktop/ozerpan/env/lib/python3.10/site-packages/pymysql/connections.py", line 775, in _read_packet
    packet.raise_for_error()
  File "/home/mstfrs/Desktop/ozerpan/env/lib/python3.10/site-packages/pymysql/protocol.py", line 219, in raise_for_error
    err.raise_mysql_exception(self._data)
  File "/home/mstfrs/Desktop/ozerpan/env/lib/python3.10/site-packages/pymysql/err.py", line 150, in raise_mysql_exception
    raise errorclass(errno, errval)
pymysql.err.OperationalError: (1049, "Unknown database '_be61cf5335d3ad96'")
2024-10-09 10:36:01,055 ERROR scheduler Exception in Enqueue Events for Site ozerpan.local
Traceback (most recent call last):
  File "/home/mstfrs/Desktop/ozerpan/apps/frappe/frappe/utils/scheduler.py", line 106, in enqueue_events_for_site
    if is_scheduler_inactive():
  File "/home/mstfrs/Desktop/ozerpan/apps/frappe/frappe/utils/scheduler.py", line 150, in is_scheduler_inactive
    if is_scheduler_disabled(verbose=verbose):
  File "/home/mstfrs/Desktop/ozerpan/apps/frappe/frappe/utils/scheduler.py", line 163, in is_scheduler_disabled
    frappe.db.get_single_value("System Settings", "enable_scheduler")
  File "/home/mstfrs/Desktop/ozerpan/apps/frappe/frappe/database/database.py", line 846, in get_single_value
    ).run()
  File "/home/mstfrs/Desktop/ozerpan/apps/frappe/frappe/query_builder/utils.py", line 84, in execute_query
    result = frappe.db.sql(query, params, *args, **kwargs)  # nosemgrep
  File "/home/mstfrs/Desktop/ozerpan/apps/frappe/frappe/database/database.py", line 213, in sql
    self.connect()
  File "/home/mstfrs/Desktop/ozerpan/apps/frappe/frappe/database/database.py", line 118, in connect
    self._conn: "MariadbConnection" | "PostgresConnection" = self.get_connection()
  File "/home/mstfrs/Desktop/ozerpan/apps/frappe/frappe/database/mariadb/database.py", line 107, in get_connection
    conn = self._get_connection()
  File "/home/mstfrs/Desktop/ozerpan/apps/frappe/frappe/database/mariadb/database.py", line 113, in _get_connection
    return self.create_connection()
  File "/home/mstfrs/Desktop/ozerpan/apps/frappe/frappe/database/mariadb/database.py", line 116, in create_connection
    return pymysql.connect(**self.get_connection_settings())
  File "/home/mstfrs/Desktop/ozerpan/env/lib/python3.10/site-packages/pymysql/connections.py", line 361, in __init__
    self.connect()
  File "/home/mstfrs/Desktop/ozerpan/env/lib/python3.10/site-packages/pymysql/connections.py", line 669, in connect
    self._request_authentication()
  File "/home/mstfrs/Desktop/ozerpan/env/lib/python3.10/site-packages/pymysql/connections.py", line 957, in _request_authentication
    auth_packet = self._read_packet()
  File "/home/mstfrs/Desktop/ozerpan/env/lib/python3.10/site-packages/pymysql/connections.py", line 775, in _read_packet
    packet.raise_for_error()
  File "/home/mstfrs/Desktop/ozerpan/env/lib/python3.10/site-packages/pymysql/protocol.py", line 219, in raise_for_error
    err.raise_mysql_exception(self._data)
  File "/home/mstfrs/Desktop/ozerpan/env/lib/python3.10/site-packages/pymysql/err.py", line 150, in raise_mysql_exception
    raise errorclass(errno, errval)
pymysql.err.OperationalError: (1045, "Access denied for user '_c85c2ca7b22cd0b1'@'localhost' (using password: YES)")
2024-10-09 10:40:00,513 ERROR scheduler Exception in Enqueue Events for Site ozerpan.local
Traceback (most recent call last):
  File "/home/mstfrs/Desktop/ozerpan/apps/frappe/frappe/utils/scheduler.py", line 106, in enqueue_events_for_site
    if is_scheduler_inactive():
  File "/home/mstfrs/Desktop/ozerpan/apps/frappe/frappe/utils/scheduler.py", line 150, in is_scheduler_inactive
    if is_scheduler_disabled(verbose=verbose):
  File "/home/mstfrs/Desktop/ozerpan/apps/frappe/frappe/utils/scheduler.py", line 163, in is_scheduler_disabled
    frappe.db.get_single_value("System Settings", "enable_scheduler")
  File "/home/mstfrs/Desktop/ozerpan/apps/frappe/frappe/database/database.py", line 846, in get_single_value
    ).run()
  File "/home/mstfrs/Desktop/ozerpan/apps/frappe/frappe/query_builder/utils.py", line 84, in execute_query
    result = frappe.db.sql(query, params, *args, **kwargs)  # nosemgrep
  File "/home/mstfrs/Desktop/ozerpan/apps/frappe/frappe/database/database.py", line 213, in sql
    self.connect()
  File "/home/mstfrs/Desktop/ozerpan/apps/frappe/frappe/database/database.py", line 118, in connect
    self._conn: "MariadbConnection" | "PostgresConnection" = self.get_connection()
  File "/home/mstfrs/Desktop/ozerpan/apps/frappe/frappe/database/mariadb/database.py", line 107, in get_connection
    conn = self._get_connection()
  File "/home/mstfrs/Desktop/ozerpan/apps/frappe/frappe/database/mariadb/database.py", line 113, in _get_connection
    return self.create_connection()
  File "/home/mstfrs/Desktop/ozerpan/apps/frappe/frappe/database/mariadb/database.py", line 116, in create_connection
    return pymysql.connect(**self.get_connection_settings())
  File "/home/mstfrs/Desktop/ozerpan/env/lib/python3.10/site-packages/pymysql/connections.py", line 361, in __init__
    self.connect()
  File "/home/mstfrs/Desktop/ozerpan/env/lib/python3.10/site-packages/pymysql/connections.py", line 669, in connect
    self._request_authentication()
  File "/home/mstfrs/Desktop/ozerpan/env/lib/python3.10/site-packages/pymysql/connections.py", line 957, in _request_authentication
    auth_packet = self._read_packet()
  File "/home/mstfrs/Desktop/ozerpan/env/lib/python3.10/site-packages/pymysql/connections.py", line 775, in _read_packet
    packet.raise_for_error()
  File "/home/mstfrs/Desktop/ozerpan/env/lib/python3.10/site-packages/pymysql/protocol.py", line 219, in raise_for_error
    err.raise_mysql_exception(self._data)
  File "/home/mstfrs/Desktop/ozerpan/env/lib/python3.10/site-packages/pymysql/err.py", line 150, in raise_mysql_exception
    raise errorclass(errno, errval)
pymysql.err.OperationalError: (1045, "Access denied for user '_c85c2ca7b22cd0b1'@'localhost' (using password: YES)")
2024-10-09 10:40:00,516 ERROR scheduler Exception in Enqueue Events for Site ozerpan
Traceback (most recent call last):
  File "/home/mstfrs/Desktop/ozerpan/apps/frappe/frappe/utils/scheduler.py", line 106, in enqueue_events_for_site
    if is_scheduler_inactive():
  File "/home/mstfrs/Desktop/ozerpan/apps/frappe/frappe/utils/scheduler.py", line 150, in is_scheduler_inactive
    if is_scheduler_disabled(verbose=verbose):
  File "/home/mstfrs/Desktop/ozerpan/apps/frappe/frappe/utils/scheduler.py", line 163, in is_scheduler_disabled
    frappe.db.get_single_value("System Settings", "enable_scheduler")
  File "/home/mstfrs/Desktop/ozerpan/apps/frappe/frappe/database/database.py", line 846, in get_single_value
    ).run()
  File "/home/mstfrs/Desktop/ozerpan/apps/frappe/frappe/query_builder/utils.py", line 84, in execute_query
    result = frappe.db.sql(query, params, *args, **kwargs)  # nosemgrep
  File "/home/mstfrs/Desktop/ozerpan/apps/frappe/frappe/database/database.py", line 213, in sql
    self.connect()
  File "/home/mstfrs/Desktop/ozerpan/apps/frappe/frappe/database/database.py", line 118, in connect
    self._conn: "MariadbConnection" | "PostgresConnection" = self.get_connection()
  File "/home/mstfrs/Desktop/ozerpan/apps/frappe/frappe/database/mariadb/database.py", line 107, in get_connection
    conn = self._get_connection()
  File "/home/mstfrs/Desktop/ozerpan/apps/frappe/frappe/database/mariadb/database.py", line 113, in _get_connection
    return self.create_connection()
  File "/home/mstfrs/Desktop/ozerpan/apps/frappe/frappe/database/mariadb/database.py", line 116, in create_connection
    return pymysql.connect(**self.get_connection_settings())
  File "/home/mstfrs/Desktop/ozerpan/env/lib/python3.10/site-packages/pymysql/connections.py", line 361, in __init__
    self.connect()
  File "/home/mstfrs/Desktop/ozerpan/env/lib/python3.10/site-packages/pymysql/connections.py", line 669, in connect
    self._request_authentication()
  File "/home/mstfrs/Desktop/ozerpan/env/lib/python3.10/site-packages/pymysql/connections.py", line 957, in _request_authentication
    auth_packet = self._read_packet()
  File "/home/mstfrs/Desktop/ozerpan/env/lib/python3.10/site-packages/pymysql/connections.py", line 775, in _read_packet
    packet.raise_for_error()
  File "/home/mstfrs/Desktop/ozerpan/env/lib/python3.10/site-packages/pymysql/protocol.py", line 219, in raise_for_error
    err.raise_mysql_exception(self._data)
  File "/home/mstfrs/Desktop/ozerpan/env/lib/python3.10/site-packages/pymysql/err.py", line 150, in raise_mysql_exception
    raise errorclass(errno, errval)
pymysql.err.OperationalError: (1049, "Unknown database '_be61cf5335d3ad96'")
2024-10-09 10:44:00,712 ERROR scheduler Exception in Enqueue Events for Site ozerpan
Traceback (most recent call last):
  File "/home/mstfrs/Desktop/ozerpan/apps/frappe/frappe/utils/scheduler.py", line 106, in enqueue_events_for_site
    if is_scheduler_inactive():
  File "/home/mstfrs/Desktop/ozerpan/apps/frappe/frappe/utils/scheduler.py", line 150, in is_scheduler_inactive
    if is_scheduler_disabled(verbose=verbose):
  File "/home/mstfrs/Desktop/ozerpan/apps/frappe/frappe/utils/scheduler.py", line 163, in is_scheduler_disabled
    frappe.db.get_single_value("System Settings", "enable_scheduler")
  File "/home/mstfrs/Desktop/ozerpan/apps/frappe/frappe/database/database.py", line 846, in get_single_value
    ).run()
  File "/home/mstfrs/Desktop/ozerpan/apps/frappe/frappe/query_builder/utils.py", line 84, in execute_query
    result = frappe.db.sql(query, params, *args, **kwargs)  # nosemgrep
  File "/home/mstfrs/Desktop/ozerpan/apps/frappe/frappe/database/database.py", line 213, in sql
    self.connect()
  File "/home/mstfrs/Desktop/ozerpan/apps/frappe/frappe/database/database.py", line 118, in connect
    self._conn: "MariadbConnection" | "PostgresConnection" = self.get_connection()
  File "/home/mstfrs/Desktop/ozerpan/apps/frappe/frappe/database/mariadb/database.py", line 107, in get_connection
    conn = self._get_connection()
  File "/home/mstfrs/Desktop/ozerpan/apps/frappe/frappe/database/mariadb/database.py", line 113, in _get_connection
    return self.create_connection()
  File "/home/mstfrs/Desktop/ozerpan/apps/frappe/frappe/database/mariadb/database.py", line 116, in create_connection
    return pymysql.connect(**self.get_connection_settings())
  File "/home/mstfrs/Desktop/ozerpan/env/lib/python3.10/site-packages/pymysql/connections.py", line 361, in __init__
    self.connect()
  File "/home/mstfrs/Desktop/ozerpan/env/lib/python3.10/site-packages/pymysql/connections.py", line 669, in connect
    self._request_authentication()
  File "/home/mstfrs/Desktop/ozerpan/env/lib/python3.10/site-packages/pymysql/connections.py", line 957, in _request_authentication
    auth_packet = self._read_packet()
  File "/home/mstfrs/Desktop/ozerpan/env/lib/python3.10/site-packages/pymysql/connections.py", line 775, in _read_packet
    packet.raise_for_error()
  File "/home/mstfrs/Desktop/ozerpan/env/lib/python3.10/site-packages/pymysql/protocol.py", line 219, in raise_for_error
    err.raise_mysql_exception(self._data)
  File "/home/mstfrs/Desktop/ozerpan/env/lib/python3.10/site-packages/pymysql/err.py", line 150, in raise_mysql_exception
    raise errorclass(errno, errval)
pymysql.err.OperationalError: (1049, "Unknown database '_be61cf5335d3ad96'")
2024-10-09 10:44:00,715 ERROR scheduler Exception in Enqueue Events for Site ozerpan.local
Traceback (most recent call last):
  File "/home/mstfrs/Desktop/ozerpan/apps/frappe/frappe/utils/scheduler.py", line 106, in enqueue_events_for_site
    if is_scheduler_inactive():
  File "/home/mstfrs/Desktop/ozerpan/apps/frappe/frappe/utils/scheduler.py", line 150, in is_scheduler_inactive
    if is_scheduler_disabled(verbose=verbose):
  File "/home/mstfrs/Desktop/ozerpan/apps/frappe/frappe/utils/scheduler.py", line 163, in is_scheduler_disabled
    frappe.db.get_single_value("System Settings", "enable_scheduler")
  File "/home/mstfrs/Desktop/ozerpan/apps/frappe/frappe/database/database.py", line 846, in get_single_value
    ).run()
  File "/home/mstfrs/Desktop/ozerpan/apps/frappe/frappe/query_builder/utils.py", line 84, in execute_query
    result = frappe.db.sql(query, params, *args, **kwargs)  # nosemgrep
  File "/home/mstfrs/Desktop/ozerpan/apps/frappe/frappe/database/database.py", line 213, in sql
    self.connect()
  File "/home/mstfrs/Desktop/ozerpan/apps/frappe/frappe/database/database.py", line 118, in connect
    self._conn: "MariadbConnection" | "PostgresConnection" = self.get_connection()
  File "/home/mstfrs/Desktop/ozerpan/apps/frappe/frappe/database/mariadb/database.py", line 107, in get_connection
    conn = self._get_connection()
  File "/home/mstfrs/Desktop/ozerpan/apps/frappe/frappe/database/mariadb/database.py", line 113, in _get_connection
    return self.create_connection()
  File "/home/mstfrs/Desktop/ozerpan/apps/frappe/frappe/database/mariadb/database.py", line 116, in create_connection
    return pymysql.connect(**self.get_connection_settings())
  File "/home/mstfrs/Desktop/ozerpan/env/lib/python3.10/site-packages/pymysql/connections.py", line 361, in __init__
    self.connect()
  File "/home/mstfrs/Desktop/ozerpan/env/lib/python3.10/site-packages/pymysql/connections.py", line 669, in connect
    self._request_authentication()
  File "/home/mstfrs/Desktop/ozerpan/env/lib/python3.10/site-packages/pymysql/connections.py", line 957, in _request_authentication
    auth_packet = self._read_packet()
  File "/home/mstfrs/Desktop/ozerpan/env/lib/python3.10/site-packages/pymysql/connections.py", line 775, in _read_packet
    packet.raise_for_error()
  File "/home/mstfrs/Desktop/ozerpan/env/lib/python3.10/site-packages/pymysql/protocol.py", line 219, in raise_for_error
    err.raise_mysql_exception(self._data)
  File "/home/mstfrs/Desktop/ozerpan/env/lib/python3.10/site-packages/pymysql/err.py", line 150, in raise_mysql_exception
    raise errorclass(errno, errval)
pymysql.err.OperationalError: (1045, "Access denied for user '_c85c2ca7b22cd0b1'@'localhost' (using password: YES)")
2024-10-09 10:48:00,468 ERROR scheduler Exception in Enqueue Events for Site ozerpan
Traceback (most recent call last):
  File "/home/mstfrs/Desktop/ozerpan/apps/frappe/frappe/utils/scheduler.py", line 106, in enqueue_events_for_site
    if is_scheduler_inactive():
  File "/home/mstfrs/Desktop/ozerpan/apps/frappe/frappe/utils/scheduler.py", line 150, in is_scheduler_inactive
    if is_scheduler_disabled(verbose=verbose):
  File "/home/mstfrs/Desktop/ozerpan/apps/frappe/frappe/utils/scheduler.py", line 163, in is_scheduler_disabled
    frappe.db.get_single_value("System Settings", "enable_scheduler")
  File "/home/mstfrs/Desktop/ozerpan/apps/frappe/frappe/database/database.py", line 846, in get_single_value
    ).run()
  File "/home/mstfrs/Desktop/ozerpan/apps/frappe/frappe/query_builder/utils.py", line 84, in execute_query
    result = frappe.db.sql(query, params, *args, **kwargs)  # nosemgrep
  File "/home/mstfrs/Desktop/ozerpan/apps/frappe/frappe/database/database.py", line 213, in sql
    self.connect()
  File "/home/mstfrs/Desktop/ozerpan/apps/frappe/frappe/database/database.py", line 118, in connect
    self._conn: "MariadbConnection" | "PostgresConnection" = self.get_connection()
  File "/home/mstfrs/Desktop/ozerpan/apps/frappe/frappe/database/mariadb/database.py", line 107, in get_connection
    conn = self._get_connection()
  File "/home/mstfrs/Desktop/ozerpan/apps/frappe/frappe/database/mariadb/database.py", line 113, in _get_connection
    return self.create_connection()
  File "/home/mstfrs/Desktop/ozerpan/apps/frappe/frappe/database/mariadb/database.py", line 116, in create_connection
    return pymysql.connect(**self.get_connection_settings())
  File "/home/mstfrs/Desktop/ozerpan/env/lib/python3.10/site-packages/pymysql/connections.py", line 361, in __init__
    self.connect()
  File "/home/mstfrs/Desktop/ozerpan/env/lib/python3.10/site-packages/pymysql/connections.py", line 669, in connect
    self._request_authentication()
  File "/home/mstfrs/Desktop/ozerpan/env/lib/python3.10/site-packages/pymysql/connections.py", line 957, in _request_authentication
    auth_packet = self._read_packet()
  File "/home/mstfrs/Desktop/ozerpan/env/lib/python3.10/site-packages/pymysql/connections.py", line 775, in _read_packet
    packet.raise_for_error()
  File "/home/mstfrs/Desktop/ozerpan/env/lib/python3.10/site-packages/pymysql/protocol.py", line 219, in raise_for_error
    err.raise_mysql_exception(self._data)
  File "/home/mstfrs/Desktop/ozerpan/env/lib/python3.10/site-packages/pymysql/err.py", line 150, in raise_mysql_exception
    raise errorclass(errno, errval)
pymysql.err.OperationalError: (1049, "Unknown database '_be61cf5335d3ad96'")
2024-10-09 10:48:00,473 ERROR scheduler Exception in Enqueue Events for Site ozerpan.local
Traceback (most recent call last):
  File "/home/mstfrs/Desktop/ozerpan/apps/frappe/frappe/utils/scheduler.py", line 106, in enqueue_events_for_site
    if is_scheduler_inactive():
  File "/home/mstfrs/Desktop/ozerpan/apps/frappe/frappe/utils/scheduler.py", line 150, in is_scheduler_inactive
    if is_scheduler_disabled(verbose=verbose):
  File "/home/mstfrs/Desktop/ozerpan/apps/frappe/frappe/utils/scheduler.py", line 163, in is_scheduler_disabled
    frappe.db.get_single_value("System Settings", "enable_scheduler")
  File "/home/mstfrs/Desktop/ozerpan/apps/frappe/frappe/database/database.py", line 846, in get_single_value
    ).run()
  File "/home/mstfrs/Desktop/ozerpan/apps/frappe/frappe/query_builder/utils.py", line 84, in execute_query
    result = frappe.db.sql(query, params, *args, **kwargs)  # nosemgrep
  File "/home/mstfrs/Desktop/ozerpan/apps/frappe/frappe/database/database.py", line 213, in sql
    self.connect()
  File "/home/mstfrs/Desktop/ozerpan/apps/frappe/frappe/database/database.py", line 118, in connect
    self._conn: "MariadbConnection" | "PostgresConnection" = self.get_connection()
  File "/home/mstfrs/Desktop/ozerpan/apps/frappe/frappe/database/mariadb/database.py", line 107, in get_connection
    conn = self._get_connection()
  File "/home/mstfrs/Desktop/ozerpan/apps/frappe/frappe/database/mariadb/database.py", line 113, in _get_connection
    return self.create_connection()
  File "/home/mstfrs/Desktop/ozerpan/apps/frappe/frappe/database/mariadb/database.py", line 116, in create_connection
    return pymysql.connect(**self.get_connection_settings())
  File "/home/mstfrs/Desktop/ozerpan/env/lib/python3.10/site-packages/pymysql/connections.py", line 361, in __init__
    self.connect()
  File "/home/mstfrs/Desktop/ozerpan/env/lib/python3.10/site-packages/pymysql/connections.py", line 669, in connect
    self._request_authentication()
  File "/home/mstfrs/Desktop/ozerpan/env/lib/python3.10/site-packages/pymysql/connections.py", line 957, in _request_authentication
    auth_packet = self._read_packet()
  File "/home/mstfrs/Desktop/ozerpan/env/lib/python3.10/site-packages/pymysql/connections.py", line 775, in _read_packet
    packet.raise_for_error()
  File "/home/mstfrs/Desktop/ozerpan/env/lib/python3.10/site-packages/pymysql/protocol.py", line 219, in raise_for_error
    err.raise_mysql_exception(self._data)
  File "/home/mstfrs/Desktop/ozerpan/env/lib/python3.10/site-packages/pymysql/err.py", line 150, in raise_mysql_exception
    raise errorclass(errno, errval)
pymysql.err.OperationalError: (1045, "Access denied for user '_c85c2ca7b22cd0b1'@'localhost' (using password: YES)")
2024-10-09 10:52:00,898 ERROR scheduler Exception in Enqueue Events for Site ozerpan
Traceback (most recent call last):
  File "/home/mstfrs/Desktop/ozerpan/apps/frappe/frappe/utils/scheduler.py", line 106, in enqueue_events_for_site
    if is_scheduler_inactive():
  File "/home/mstfrs/Desktop/ozerpan/apps/frappe/frappe/utils/scheduler.py", line 150, in is_scheduler_inactive
    if is_scheduler_disabled(verbose=verbose):
  File "/home/mstfrs/Desktop/ozerpan/apps/frappe/frappe/utils/scheduler.py", line 163, in is_scheduler_disabled
    frappe.db.get_single_value("System Settings", "enable_scheduler")
  File "/home/mstfrs/Desktop/ozerpan/apps/frappe/frappe/database/database.py", line 846, in get_single_value
    ).run()
  File "/home/mstfrs/Desktop/ozerpan/apps/frappe/frappe/query_builder/utils.py", line 84, in execute_query
    result = frappe.db.sql(query, params, *args, **kwargs)  # nosemgrep
  File "/home/mstfrs/Desktop/ozerpan/apps/frappe/frappe/database/database.py", line 213, in sql
    self.connect()
  File "/home/mstfrs/Desktop/ozerpan/apps/frappe/frappe/database/database.py", line 118, in connect
    self._conn: "MariadbConnection" | "PostgresConnection" = self.get_connection()
  File "/home/mstfrs/Desktop/ozerpan/apps/frappe/frappe/database/mariadb/database.py", line 107, in get_connection
    conn = self._get_connection()
  File "/home/mstfrs/Desktop/ozerpan/apps/frappe/frappe/database/mariadb/database.py", line 113, in _get_connection
    return self.create_connection()
  File "/home/mstfrs/Desktop/ozerpan/apps/frappe/frappe/database/mariadb/database.py", line 116, in create_connection
    return pymysql.connect(**self.get_connection_settings())
  File "/home/mstfrs/Desktop/ozerpan/env/lib/python3.10/site-packages/pymysql/connections.py", line 361, in __init__
    self.connect()
  File "/home/mstfrs/Desktop/ozerpan/env/lib/python3.10/site-packages/pymysql/connections.py", line 669, in connect
    self._request_authentication()
  File "/home/mstfrs/Desktop/ozerpan/env/lib/python3.10/site-packages/pymysql/connections.py", line 957, in _request_authentication
    auth_packet = self._read_packet()
  File "/home/mstfrs/Desktop/ozerpan/env/lib/python3.10/site-packages/pymysql/connections.py", line 775, in _read_packet
    packet.raise_for_error()
  File "/home/mstfrs/Desktop/ozerpan/env/lib/python3.10/site-packages/pymysql/protocol.py", line 219, in raise_for_error
    err.raise_mysql_exception(self._data)
  File "/home/mstfrs/Desktop/ozerpan/env/lib/python3.10/site-packages/pymysql/err.py", line 150, in raise_mysql_exception
    raise errorclass(errno, errval)
pymysql.err.OperationalError: (1049, "Unknown database '_be61cf5335d3ad96'")
2024-10-09 10:52:00,901 ERROR scheduler Exception in Enqueue Events for Site ozerpan.local
Traceback (most recent call last):
  File "/home/mstfrs/Desktop/ozerpan/apps/frappe/frappe/utils/scheduler.py", line 106, in enqueue_events_for_site
    if is_scheduler_inactive():
  File "/home/mstfrs/Desktop/ozerpan/apps/frappe/frappe/utils/scheduler.py", line 150, in is_scheduler_inactive
    if is_scheduler_disabled(verbose=verbose):
  File "/home/mstfrs/Desktop/ozerpan/apps/frappe/frappe/utils/scheduler.py", line 163, in is_scheduler_disabled
    frappe.db.get_single_value("System Settings", "enable_scheduler")
  File "/home/mstfrs/Desktop/ozerpan/apps/frappe/frappe/database/database.py", line 846, in get_single_value
    ).run()
  File "/home/mstfrs/Desktop/ozerpan/apps/frappe/frappe/query_builder/utils.py", line 84, in execute_query
    result = frappe.db.sql(query, params, *args, **kwargs)  # nosemgrep
  File "/home/mstfrs/Desktop/ozerpan/apps/frappe/frappe/database/database.py", line 213, in sql
    self.connect()
  File "/home/mstfrs/Desktop/ozerpan/apps/frappe/frappe/database/database.py", line 118, in connect
    self._conn: "MariadbConnection" | "PostgresConnection" = self.get_connection()
  File "/home/mstfrs/Desktop/ozerpan/apps/frappe/frappe/database/mariadb/database.py", line 107, in get_connection
    conn = self._get_connection()
  File "/home/mstfrs/Desktop/ozerpan/apps/frappe/frappe/database/mariadb/database.py", line 113, in _get_connection
    return self.create_connection()
  File "/home/mstfrs/Desktop/ozerpan/apps/frappe/frappe/database/mariadb/database.py", line 116, in create_connection
    return pymysql.connect(**self.get_connection_settings())
  File "/home/mstfrs/Desktop/ozerpan/env/lib/python3.10/site-packages/pymysql/connections.py", line 361, in __init__
    self.connect()
  File "/home/mstfrs/Desktop/ozerpan/env/lib/python3.10/site-packages/pymysql/connections.py", line 669, in connect
    self._request_authentication()
  File "/home/mstfrs/Desktop/ozerpan/env/lib/python3.10/site-packages/pymysql/connections.py", line 957, in _request_authentication
    auth_packet = self._read_packet()
  File "/home/mstfrs/Desktop/ozerpan/env/lib/python3.10/site-packages/pymysql/connections.py", line 775, in _read_packet
    packet.raise_for_error()
  File "/home/mstfrs/Desktop/ozerpan/env/lib/python3.10/site-packages/pymysql/protocol.py", line 219, in raise_for_error
    err.raise_mysql_exception(self._data)
  File "/home/mstfrs/Desktop/ozerpan/env/lib/python3.10/site-packages/pymysql/err.py", line 150, in raise_mysql_exception
    raise errorclass(errno, errval)
pymysql.err.OperationalError: (1045, "Access denied for user '_c85c2ca7b22cd0b1'@'localhost' (using password: YES)")
2024-10-09 10:56:01,285 ERROR scheduler Exception in Enqueue Events for Site ozerpan
Traceback (most recent call last):
  File "/home/mstfrs/Desktop/ozerpan/apps/frappe/frappe/utils/scheduler.py", line 106, in enqueue_events_for_site
    if is_scheduler_inactive():
  File "/home/mstfrs/Desktop/ozerpan/apps/frappe/frappe/utils/scheduler.py", line 150, in is_scheduler_inactive
    if is_scheduler_disabled(verbose=verbose):
  File "/home/mstfrs/Desktop/ozerpan/apps/frappe/frappe/utils/scheduler.py", line 163, in is_scheduler_disabled
    frappe.db.get_single_value("System Settings", "enable_scheduler")
  File "/home/mstfrs/Desktop/ozerpan/apps/frappe/frappe/database/database.py", line 846, in get_single_value
    ).run()
  File "/home/mstfrs/Desktop/ozerpan/apps/frappe/frappe/query_builder/utils.py", line 84, in execute_query
    result = frappe.db.sql(query, params, *args, **kwargs)  # nosemgrep
  File "/home/mstfrs/Desktop/ozerpan/apps/frappe/frappe/database/database.py", line 213, in sql
    self.connect()
  File "/home/mstfrs/Desktop/ozerpan/apps/frappe/frappe/database/database.py", line 118, in connect
    self._conn: "MariadbConnection" | "PostgresConnection" = self.get_connection()
  File "/home/mstfrs/Desktop/ozerpan/apps/frappe/frappe/database/mariadb/database.py", line 107, in get_connection
    conn = self._get_connection()
  File "/home/mstfrs/Desktop/ozerpan/apps/frappe/frappe/database/mariadb/database.py", line 113, in _get_connection
    return self.create_connection()
  File "/home/mstfrs/Desktop/ozerpan/apps/frappe/frappe/database/mariadb/database.py", line 116, in create_connection
    return pymysql.connect(**self.get_connection_settings())
  File "/home/mstfrs/Desktop/ozerpan/env/lib/python3.10/site-packages/pymysql/connections.py", line 361, in __init__
    self.connect()
  File "/home/mstfrs/Desktop/ozerpan/env/lib/python3.10/site-packages/pymysql/connections.py", line 669, in connect
    self._request_authentication()
  File "/home/mstfrs/Desktop/ozerpan/env/lib/python3.10/site-packages/pymysql/connections.py", line 957, in _request_authentication
    auth_packet = self._read_packet()
  File "/home/mstfrs/Desktop/ozerpan/env/lib/python3.10/site-packages/pymysql/connections.py", line 775, in _read_packet
    packet.raise_for_error()
  File "/home/mstfrs/Desktop/ozerpan/env/lib/python3.10/site-packages/pymysql/protocol.py", line 219, in raise_for_error
    err.raise_mysql_exception(self._data)
  File "/home/mstfrs/Desktop/ozerpan/env/lib/python3.10/site-packages/pymysql/err.py", line 150, in raise_mysql_exception
    raise errorclass(errno, errval)
pymysql.err.OperationalError: (1049, "Unknown database '_be61cf5335d3ad96'")
