2024-10-10 11:08:00,293 ERROR scheduler Exception in Enqueue Events for Site ozerpan
Traceback (most recent call last):
  File "/home/mstfrs/Desktop/ozerpan/apps/frappe/frappe/utils/scheduler.py", line 106, in enqueue_events_for_site
    if is_scheduler_inactive():
  File "/home/mstfrs/Desktop/ozerpan/apps/frappe/frappe/utils/scheduler.py", line 150, in is_scheduler_inactive
    if is_scheduler_disabled(verbose=verbose):
  File "/home/mstfrs/Desktop/ozerpan/apps/frappe/frappe/utils/scheduler.py", line 163, in is_scheduler_disabled
    frappe.db.get_single_value("System Settings", "enable_scheduler")
  File "/home/mstfrs/Desktop/ozerpan/apps/frappe/frappe/database/database.py", line 846, in get_single_value
    ).run()
  File "/home/mstfrs/Desktop/ozerpan/apps/frappe/frappe/query_builder/utils.py", line 84, in execute_query
    result = frappe.db.sql(query, params, *args, **kwargs)  # nosemgrep
  File "/home/mstfrs/Desktop/ozerpan/apps/frappe/frappe/database/database.py", line 213, in sql
    self.connect()
  File "/home/mstfrs/Desktop/ozerpan/apps/frappe/frappe/database/database.py", line 118, in connect
    self._conn: "MariadbConnection" | "PostgresConnection" = self.get_connection()
  File "/home/mstfrs/Desktop/ozerpan/apps/frappe/frappe/database/mariadb/database.py", line 107, in get_connection
    conn = self._get_connection()
  File "/home/mstfrs/Desktop/ozerpan/apps/frappe/frappe/database/mariadb/database.py", line 113, in _get_connection
    return self.create_connection()
  File "/home/mstfrs/Desktop/ozerpan/apps/frappe/frappe/database/mariadb/database.py", line 116, in create_connection
    return pymysql.connect(**self.get_connection_settings())
  File "/home/mstfrs/Desktop/ozerpan/env/lib/python3.10/site-packages/pymysql/connections.py", line 361, in __init__
    self.connect()
  File "/home/mstfrs/Desktop/ozerpan/env/lib/python3.10/site-packages/pymysql/connections.py", line 669, in connect
    self._request_authentication()
  File "/home/mstfrs/Desktop/ozerpan/env/lib/python3.10/site-packages/pymysql/connections.py", line 957, in _request_authentication
    auth_packet = self._read_packet()
  File "/home/mstfrs/Desktop/ozerpan/env/lib/python3.10/site-packages/pymysql/connections.py", line 775, in _read_packet
    packet.raise_for_error()
  File "/home/mstfrs/Desktop/ozerpan/env/lib/python3.10/site-packages/pymysql/protocol.py", line 219, in raise_for_error
    err.raise_mysql_exception(self._data)
  File "/home/mstfrs/Desktop/ozerpan/env/lib/python3.10/site-packages/pymysql/err.py", line 150, in raise_mysql_exception
    raise errorclass(errno, errval)
pymysql.err.OperationalError: (1049, "Unknown database '_be61cf5335d3ad96'")
2024-10-10 11:12:01,220 ERROR scheduler Exception in Enqueue Events for Site ozerpan
Traceback (most recent call last):
  File "/home/mstfrs/Desktop/ozerpan/apps/frappe/frappe/utils/scheduler.py", line 106, in enqueue_events_for_site
    if is_scheduler_inactive():
  File "/home/mstfrs/Desktop/ozerpan/apps/frappe/frappe/utils/scheduler.py", line 150, in is_scheduler_inactive
    if is_scheduler_disabled(verbose=verbose):
  File "/home/mstfrs/Desktop/ozerpan/apps/frappe/frappe/utils/scheduler.py", line 163, in is_scheduler_disabled
    frappe.db.get_single_value("System Settings", "enable_scheduler")
  File "/home/mstfrs/Desktop/ozerpan/apps/frappe/frappe/database/database.py", line 846, in get_single_value
    ).run()
  File "/home/mstfrs/Desktop/ozerpan/apps/frappe/frappe/query_builder/utils.py", line 84, in execute_query
    result = frappe.db.sql(query, params, *args, **kwargs)  # nosemgrep
  File "/home/mstfrs/Desktop/ozerpan/apps/frappe/frappe/database/database.py", line 213, in sql
    self.connect()
  File "/home/mstfrs/Desktop/ozerpan/apps/frappe/frappe/database/database.py", line 118, in connect
    self._conn: "MariadbConnection" | "PostgresConnection" = self.get_connection()
  File "/home/mstfrs/Desktop/ozerpan/apps/frappe/frappe/database/mariadb/database.py", line 107, in get_connection
    conn = self._get_connection()
  File "/home/mstfrs/Desktop/ozerpan/apps/frappe/frappe/database/mariadb/database.py", line 113, in _get_connection
    return self.create_connection()
  File "/home/mstfrs/Desktop/ozerpan/apps/frappe/frappe/database/mariadb/database.py", line 116, in create_connection
    return pymysql.connect(**self.get_connection_settings())
  File "/home/mstfrs/Desktop/ozerpan/env/lib/python3.10/site-packages/pymysql/connections.py", line 361, in __init__
    self.connect()
  File "/home/mstfrs/Desktop/ozerpan/env/lib/python3.10/site-packages/pymysql/connections.py", line 669, in connect
    self._request_authentication()
  File "/home/mstfrs/Desktop/ozerpan/env/lib/python3.10/site-packages/pymysql/connections.py", line 957, in _request_authentication
    auth_packet = self._read_packet()
  File "/home/mstfrs/Desktop/ozerpan/env/lib/python3.10/site-packages/pymysql/connections.py", line 775, in _read_packet
    packet.raise_for_error()
  File "/home/mstfrs/Desktop/ozerpan/env/lib/python3.10/site-packages/pymysql/protocol.py", line 219, in raise_for_error
    err.raise_mysql_exception(self._data)
  File "/home/mstfrs/Desktop/ozerpan/env/lib/python3.10/site-packages/pymysql/err.py", line 150, in raise_mysql_exception
    raise errorclass(errno, errval)
pymysql.err.OperationalError: (1049, "Unknown database '_be61cf5335d3ad96'")
2024-10-10 11:16:00,628 ERROR scheduler Exception in Enqueue Events for Site ozerpan
Traceback (most recent call last):
  File "/home/mstfrs/Desktop/ozerpan/apps/frappe/frappe/utils/scheduler.py", line 106, in enqueue_events_for_site
    if is_scheduler_inactive():
  File "/home/mstfrs/Desktop/ozerpan/apps/frappe/frappe/utils/scheduler.py", line 150, in is_scheduler_inactive
    if is_scheduler_disabled(verbose=verbose):
  File "/home/mstfrs/Desktop/ozerpan/apps/frappe/frappe/utils/scheduler.py", line 163, in is_scheduler_disabled
    frappe.db.get_single_value("System Settings", "enable_scheduler")
  File "/home/mstfrs/Desktop/ozerpan/apps/frappe/frappe/database/database.py", line 846, in get_single_value
    ).run()
  File "/home/mstfrs/Desktop/ozerpan/apps/frappe/frappe/query_builder/utils.py", line 84, in execute_query
    result = frappe.db.sql(query, params, *args, **kwargs)  # nosemgrep
  File "/home/mstfrs/Desktop/ozerpan/apps/frappe/frappe/database/database.py", line 213, in sql
    self.connect()
  File "/home/mstfrs/Desktop/ozerpan/apps/frappe/frappe/database/database.py", line 118, in connect
    self._conn: "MariadbConnection" | "PostgresConnection" = self.get_connection()
  File "/home/mstfrs/Desktop/ozerpan/apps/frappe/frappe/database/mariadb/database.py", line 107, in get_connection
    conn = self._get_connection()
  File "/home/mstfrs/Desktop/ozerpan/apps/frappe/frappe/database/mariadb/database.py", line 113, in _get_connection
    return self.create_connection()
  File "/home/mstfrs/Desktop/ozerpan/apps/frappe/frappe/database/mariadb/database.py", line 116, in create_connection
    return pymysql.connect(**self.get_connection_settings())
  File "/home/mstfrs/Desktop/ozerpan/env/lib/python3.10/site-packages/pymysql/connections.py", line 361, in __init__
    self.connect()
  File "/home/mstfrs/Desktop/ozerpan/env/lib/python3.10/site-packages/pymysql/connections.py", line 669, in connect
    self._request_authentication()
  File "/home/mstfrs/Desktop/ozerpan/env/lib/python3.10/site-packages/pymysql/connections.py", line 957, in _request_authentication
    auth_packet = self._read_packet()
  File "/home/mstfrs/Desktop/ozerpan/env/lib/python3.10/site-packages/pymysql/connections.py", line 775, in _read_packet
    packet.raise_for_error()
  File "/home/mstfrs/Desktop/ozerpan/env/lib/python3.10/site-packages/pymysql/protocol.py", line 219, in raise_for_error
    err.raise_mysql_exception(self._data)
  File "/home/mstfrs/Desktop/ozerpan/env/lib/python3.10/site-packages/pymysql/err.py", line 150, in raise_mysql_exception
    raise errorclass(errno, errval)
pymysql.err.OperationalError: (1049, "Unknown database '_be61cf5335d3ad96'")
2024-10-10 11:20:01,104 ERROR scheduler Exception in Enqueue Events for Site ozerpan
Traceback (most recent call last):
  File "/home/mstfrs/Desktop/ozerpan/apps/frappe/frappe/utils/scheduler.py", line 106, in enqueue_events_for_site
    if is_scheduler_inactive():
  File "/home/mstfrs/Desktop/ozerpan/apps/frappe/frappe/utils/scheduler.py", line 150, in is_scheduler_inactive
    if is_scheduler_disabled(verbose=verbose):
  File "/home/mstfrs/Desktop/ozerpan/apps/frappe/frappe/utils/scheduler.py", line 163, in is_scheduler_disabled
    frappe.db.get_single_value("System Settings", "enable_scheduler")
  File "/home/mstfrs/Desktop/ozerpan/apps/frappe/frappe/database/database.py", line 846, in get_single_value
    ).run()
  File "/home/mstfrs/Desktop/ozerpan/apps/frappe/frappe/query_builder/utils.py", line 84, in execute_query
    result = frappe.db.sql(query, params, *args, **kwargs)  # nosemgrep
  File "/home/mstfrs/Desktop/ozerpan/apps/frappe/frappe/database/database.py", line 213, in sql
    self.connect()
  File "/home/mstfrs/Desktop/ozerpan/apps/frappe/frappe/database/database.py", line 118, in connect
    self._conn: "MariadbConnection" | "PostgresConnection" = self.get_connection()
  File "/home/mstfrs/Desktop/ozerpan/apps/frappe/frappe/database/mariadb/database.py", line 107, in get_connection
    conn = self._get_connection()
  File "/home/mstfrs/Desktop/ozerpan/apps/frappe/frappe/database/mariadb/database.py", line 113, in _get_connection
    return self.create_connection()
  File "/home/mstfrs/Desktop/ozerpan/apps/frappe/frappe/database/mariadb/database.py", line 116, in create_connection
    return pymysql.connect(**self.get_connection_settings())
  File "/home/mstfrs/Desktop/ozerpan/env/lib/python3.10/site-packages/pymysql/connections.py", line 361, in __init__
    self.connect()
  File "/home/mstfrs/Desktop/ozerpan/env/lib/python3.10/site-packages/pymysql/connections.py", line 669, in connect
    self._request_authentication()
  File "/home/mstfrs/Desktop/ozerpan/env/lib/python3.10/site-packages/pymysql/connections.py", line 957, in _request_authentication
    auth_packet = self._read_packet()
  File "/home/mstfrs/Desktop/ozerpan/env/lib/python3.10/site-packages/pymysql/connections.py", line 775, in _read_packet
    packet.raise_for_error()
  File "/home/mstfrs/Desktop/ozerpan/env/lib/python3.10/site-packages/pymysql/protocol.py", line 219, in raise_for_error
    err.raise_mysql_exception(self._data)
  File "/home/mstfrs/Desktop/ozerpan/env/lib/python3.10/site-packages/pymysql/err.py", line 150, in raise_mysql_exception
    raise errorclass(errno, errval)
pymysql.err.OperationalError: (1049, "Unknown database '_be61cf5335d3ad96'")
2024-10-10 11:24:00,210 ERROR scheduler Exception in Enqueue Events for Site ozerpan
Traceback (most recent call last):
  File "/home/mstfrs/Desktop/ozerpan/apps/frappe/frappe/utils/scheduler.py", line 106, in enqueue_events_for_site
    if is_scheduler_inactive():
  File "/home/mstfrs/Desktop/ozerpan/apps/frappe/frappe/utils/scheduler.py", line 150, in is_scheduler_inactive
    if is_scheduler_disabled(verbose=verbose):
  File "/home/mstfrs/Desktop/ozerpan/apps/frappe/frappe/utils/scheduler.py", line 163, in is_scheduler_disabled
    frappe.db.get_single_value("System Settings", "enable_scheduler")
  File "/home/mstfrs/Desktop/ozerpan/apps/frappe/frappe/database/database.py", line 846, in get_single_value
    ).run()
  File "/home/mstfrs/Desktop/ozerpan/apps/frappe/frappe/query_builder/utils.py", line 84, in execute_query
    result = frappe.db.sql(query, params, *args, **kwargs)  # nosemgrep
  File "/home/mstfrs/Desktop/ozerpan/apps/frappe/frappe/database/database.py", line 213, in sql
    self.connect()
  File "/home/mstfrs/Desktop/ozerpan/apps/frappe/frappe/database/database.py", line 118, in connect
    self._conn: "MariadbConnection" | "PostgresConnection" = self.get_connection()
  File "/home/mstfrs/Desktop/ozerpan/apps/frappe/frappe/database/mariadb/database.py", line 107, in get_connection
    conn = self._get_connection()
  File "/home/mstfrs/Desktop/ozerpan/apps/frappe/frappe/database/mariadb/database.py", line 113, in _get_connection
    return self.create_connection()
  File "/home/mstfrs/Desktop/ozerpan/apps/frappe/frappe/database/mariadb/database.py", line 116, in create_connection
    return pymysql.connect(**self.get_connection_settings())
  File "/home/mstfrs/Desktop/ozerpan/env/lib/python3.10/site-packages/pymysql/connections.py", line 361, in __init__
    self.connect()
  File "/home/mstfrs/Desktop/ozerpan/env/lib/python3.10/site-packages/pymysql/connections.py", line 669, in connect
    self._request_authentication()
  File "/home/mstfrs/Desktop/ozerpan/env/lib/python3.10/site-packages/pymysql/connections.py", line 957, in _request_authentication
    auth_packet = self._read_packet()
  File "/home/mstfrs/Desktop/ozerpan/env/lib/python3.10/site-packages/pymysql/connections.py", line 775, in _read_packet
    packet.raise_for_error()
  File "/home/mstfrs/Desktop/ozerpan/env/lib/python3.10/site-packages/pymysql/protocol.py", line 219, in raise_for_error
    err.raise_mysql_exception(self._data)
  File "/home/mstfrs/Desktop/ozerpan/env/lib/python3.10/site-packages/pymysql/err.py", line 150, in raise_mysql_exception
    raise errorclass(errno, errval)
pymysql.err.OperationalError: (1049, "Unknown database '_be61cf5335d3ad96'")
2024-10-10 11:28:01,007 ERROR scheduler Exception in Enqueue Events for Site ozerpan
Traceback (most recent call last):
  File "/home/mstfrs/Desktop/ozerpan/apps/frappe/frappe/utils/scheduler.py", line 106, in enqueue_events_for_site
    if is_scheduler_inactive():
  File "/home/mstfrs/Desktop/ozerpan/apps/frappe/frappe/utils/scheduler.py", line 150, in is_scheduler_inactive
    if is_scheduler_disabled(verbose=verbose):
  File "/home/mstfrs/Desktop/ozerpan/apps/frappe/frappe/utils/scheduler.py", line 163, in is_scheduler_disabled
    frappe.db.get_single_value("System Settings", "enable_scheduler")
  File "/home/mstfrs/Desktop/ozerpan/apps/frappe/frappe/database/database.py", line 846, in get_single_value
    ).run()
  File "/home/mstfrs/Desktop/ozerpan/apps/frappe/frappe/query_builder/utils.py", line 84, in execute_query
    result = frappe.db.sql(query, params, *args, **kwargs)  # nosemgrep
  File "/home/mstfrs/Desktop/ozerpan/apps/frappe/frappe/database/database.py", line 213, in sql
    self.connect()
  File "/home/mstfrs/Desktop/ozerpan/apps/frappe/frappe/database/database.py", line 118, in connect
    self._conn: "MariadbConnection" | "PostgresConnection" = self.get_connection()
  File "/home/mstfrs/Desktop/ozerpan/apps/frappe/frappe/database/mariadb/database.py", line 107, in get_connection
    conn = self._get_connection()
  File "/home/mstfrs/Desktop/ozerpan/apps/frappe/frappe/database/mariadb/database.py", line 113, in _get_connection
    return self.create_connection()
  File "/home/mstfrs/Desktop/ozerpan/apps/frappe/frappe/database/mariadb/database.py", line 116, in create_connection
    return pymysql.connect(**self.get_connection_settings())
  File "/home/mstfrs/Desktop/ozerpan/env/lib/python3.10/site-packages/pymysql/connections.py", line 361, in __init__
    self.connect()
  File "/home/mstfrs/Desktop/ozerpan/env/lib/python3.10/site-packages/pymysql/connections.py", line 669, in connect
    self._request_authentication()
  File "/home/mstfrs/Desktop/ozerpan/env/lib/python3.10/site-packages/pymysql/connections.py", line 957, in _request_authentication
    auth_packet = self._read_packet()
  File "/home/mstfrs/Desktop/ozerpan/env/lib/python3.10/site-packages/pymysql/connections.py", line 775, in _read_packet
    packet.raise_for_error()
  File "/home/mstfrs/Desktop/ozerpan/env/lib/python3.10/site-packages/pymysql/protocol.py", line 219, in raise_for_error
    err.raise_mysql_exception(self._data)
  File "/home/mstfrs/Desktop/ozerpan/env/lib/python3.10/site-packages/pymysql/err.py", line 150, in raise_mysql_exception
    raise errorclass(errno, errval)
pymysql.err.OperationalError: (1049, "Unknown database '_be61cf5335d3ad96'")
2024-10-10 11:32:00,100 ERROR scheduler Exception in Enqueue Events for Site ozerpan
Traceback (most recent call last):
  File "/home/mstfrs/Desktop/ozerpan/apps/frappe/frappe/utils/scheduler.py", line 106, in enqueue_events_for_site
    if is_scheduler_inactive():
  File "/home/mstfrs/Desktop/ozerpan/apps/frappe/frappe/utils/scheduler.py", line 150, in is_scheduler_inactive
    if is_scheduler_disabled(verbose=verbose):
  File "/home/mstfrs/Desktop/ozerpan/apps/frappe/frappe/utils/scheduler.py", line 163, in is_scheduler_disabled
    frappe.db.get_single_value("System Settings", "enable_scheduler")
  File "/home/mstfrs/Desktop/ozerpan/apps/frappe/frappe/database/database.py", line 846, in get_single_value
    ).run()
  File "/home/mstfrs/Desktop/ozerpan/apps/frappe/frappe/query_builder/utils.py", line 84, in execute_query
    result = frappe.db.sql(query, params, *args, **kwargs)  # nosemgrep
  File "/home/mstfrs/Desktop/ozerpan/apps/frappe/frappe/database/database.py", line 213, in sql
    self.connect()
  File "/home/mstfrs/Desktop/ozerpan/apps/frappe/frappe/database/database.py", line 118, in connect
    self._conn: "MariadbConnection" | "PostgresConnection" = self.get_connection()
  File "/home/mstfrs/Desktop/ozerpan/apps/frappe/frappe/database/mariadb/database.py", line 107, in get_connection
    conn = self._get_connection()
  File "/home/mstfrs/Desktop/ozerpan/apps/frappe/frappe/database/mariadb/database.py", line 113, in _get_connection
    return self.create_connection()
  File "/home/mstfrs/Desktop/ozerpan/apps/frappe/frappe/database/mariadb/database.py", line 116, in create_connection
    return pymysql.connect(**self.get_connection_settings())
  File "/home/mstfrs/Desktop/ozerpan/env/lib/python3.10/site-packages/pymysql/connections.py", line 361, in __init__
    self.connect()
  File "/home/mstfrs/Desktop/ozerpan/env/lib/python3.10/site-packages/pymysql/connections.py", line 669, in connect
    self._request_authentication()
  File "/home/mstfrs/Desktop/ozerpan/env/lib/python3.10/site-packages/pymysql/connections.py", line 957, in _request_authentication
    auth_packet = self._read_packet()
  File "/home/mstfrs/Desktop/ozerpan/env/lib/python3.10/site-packages/pymysql/connections.py", line 775, in _read_packet
    packet.raise_for_error()
  File "/home/mstfrs/Desktop/ozerpan/env/lib/python3.10/site-packages/pymysql/protocol.py", line 219, in raise_for_error
    err.raise_mysql_exception(self._data)
  File "/home/mstfrs/Desktop/ozerpan/env/lib/python3.10/site-packages/pymysql/err.py", line 150, in raise_mysql_exception
    raise errorclass(errno, errval)
pymysql.err.OperationalError: (1049, "Unknown database '_be61cf5335d3ad96'")
2024-10-10 11:36:00,909 ERROR scheduler Exception in Enqueue Events for Site ozerpan
Traceback (most recent call last):
  File "/home/mstfrs/Desktop/ozerpan/apps/frappe/frappe/utils/scheduler.py", line 106, in enqueue_events_for_site
    if is_scheduler_inactive():
  File "/home/mstfrs/Desktop/ozerpan/apps/frappe/frappe/utils/scheduler.py", line 150, in is_scheduler_inactive
    if is_scheduler_disabled(verbose=verbose):
  File "/home/mstfrs/Desktop/ozerpan/apps/frappe/frappe/utils/scheduler.py", line 163, in is_scheduler_disabled
    frappe.db.get_single_value("System Settings", "enable_scheduler")
  File "/home/mstfrs/Desktop/ozerpan/apps/frappe/frappe/database/database.py", line 846, in get_single_value
    ).run()
  File "/home/mstfrs/Desktop/ozerpan/apps/frappe/frappe/query_builder/utils.py", line 84, in execute_query
    result = frappe.db.sql(query, params, *args, **kwargs)  # nosemgrep
  File "/home/mstfrs/Desktop/ozerpan/apps/frappe/frappe/database/database.py", line 213, in sql
    self.connect()
  File "/home/mstfrs/Desktop/ozerpan/apps/frappe/frappe/database/database.py", line 118, in connect
    self._conn: "MariadbConnection" | "PostgresConnection" = self.get_connection()
  File "/home/mstfrs/Desktop/ozerpan/apps/frappe/frappe/database/mariadb/database.py", line 107, in get_connection
    conn = self._get_connection()
  File "/home/mstfrs/Desktop/ozerpan/apps/frappe/frappe/database/mariadb/database.py", line 113, in _get_connection
    return self.create_connection()
  File "/home/mstfrs/Desktop/ozerpan/apps/frappe/frappe/database/mariadb/database.py", line 116, in create_connection
    return pymysql.connect(**self.get_connection_settings())
  File "/home/mstfrs/Desktop/ozerpan/env/lib/python3.10/site-packages/pymysql/connections.py", line 361, in __init__
    self.connect()
  File "/home/mstfrs/Desktop/ozerpan/env/lib/python3.10/site-packages/pymysql/connections.py", line 669, in connect
    self._request_authentication()
  File "/home/mstfrs/Desktop/ozerpan/env/lib/python3.10/site-packages/pymysql/connections.py", line 957, in _request_authentication
    auth_packet = self._read_packet()
  File "/home/mstfrs/Desktop/ozerpan/env/lib/python3.10/site-packages/pymysql/connections.py", line 775, in _read_packet
    packet.raise_for_error()
  File "/home/mstfrs/Desktop/ozerpan/env/lib/python3.10/site-packages/pymysql/protocol.py", line 219, in raise_for_error
    err.raise_mysql_exception(self._data)
  File "/home/mstfrs/Desktop/ozerpan/env/lib/python3.10/site-packages/pymysql/err.py", line 150, in raise_mysql_exception
    raise errorclass(errno, errval)
pymysql.err.OperationalError: (1049, "Unknown database '_be61cf5335d3ad96'")
2024-10-10 11:40:01,280 ERROR scheduler Exception in Enqueue Events for Site ozerpan
Traceback (most recent call last):
  File "/home/mstfrs/Desktop/ozerpan/apps/frappe/frappe/utils/scheduler.py", line 106, in enqueue_events_for_site
    if is_scheduler_inactive():
  File "/home/mstfrs/Desktop/ozerpan/apps/frappe/frappe/utils/scheduler.py", line 150, in is_scheduler_inactive
    if is_scheduler_disabled(verbose=verbose):
  File "/home/mstfrs/Desktop/ozerpan/apps/frappe/frappe/utils/scheduler.py", line 163, in is_scheduler_disabled
    frappe.db.get_single_value("System Settings", "enable_scheduler")
  File "/home/mstfrs/Desktop/ozerpan/apps/frappe/frappe/database/database.py", line 846, in get_single_value
    ).run()
  File "/home/mstfrs/Desktop/ozerpan/apps/frappe/frappe/query_builder/utils.py", line 84, in execute_query
    result = frappe.db.sql(query, params, *args, **kwargs)  # nosemgrep
  File "/home/mstfrs/Desktop/ozerpan/apps/frappe/frappe/database/database.py", line 213, in sql
    self.connect()
  File "/home/mstfrs/Desktop/ozerpan/apps/frappe/frappe/database/database.py", line 118, in connect
    self._conn: "MariadbConnection" | "PostgresConnection" = self.get_connection()
  File "/home/mstfrs/Desktop/ozerpan/apps/frappe/frappe/database/mariadb/database.py", line 107, in get_connection
    conn = self._get_connection()
  File "/home/mstfrs/Desktop/ozerpan/apps/frappe/frappe/database/mariadb/database.py", line 113, in _get_connection
    return self.create_connection()
  File "/home/mstfrs/Desktop/ozerpan/apps/frappe/frappe/database/mariadb/database.py", line 116, in create_connection
    return pymysql.connect(**self.get_connection_settings())
  File "/home/mstfrs/Desktop/ozerpan/env/lib/python3.10/site-packages/pymysql/connections.py", line 361, in __init__
    self.connect()
  File "/home/mstfrs/Desktop/ozerpan/env/lib/python3.10/site-packages/pymysql/connections.py", line 669, in connect
    self._request_authentication()
  File "/home/mstfrs/Desktop/ozerpan/env/lib/python3.10/site-packages/pymysql/connections.py", line 957, in _request_authentication
    auth_packet = self._read_packet()
  File "/home/mstfrs/Desktop/ozerpan/env/lib/python3.10/site-packages/pymysql/connections.py", line 775, in _read_packet
    packet.raise_for_error()
  File "/home/mstfrs/Desktop/ozerpan/env/lib/python3.10/site-packages/pymysql/protocol.py", line 219, in raise_for_error
    err.raise_mysql_exception(self._data)
  File "/home/mstfrs/Desktop/ozerpan/env/lib/python3.10/site-packages/pymysql/err.py", line 150, in raise_mysql_exception
    raise errorclass(errno, errval)
pymysql.err.OperationalError: (1049, "Unknown database '_be61cf5335d3ad96'")
2024-10-10 11:44:00,668 ERROR scheduler Exception in Enqueue Events for Site ozerpan
Traceback (most recent call last):
  File "/home/mstfrs/Desktop/ozerpan/apps/frappe/frappe/utils/scheduler.py", line 106, in enqueue_events_for_site
    if is_scheduler_inactive():
  File "/home/mstfrs/Desktop/ozerpan/apps/frappe/frappe/utils/scheduler.py", line 150, in is_scheduler_inactive
    if is_scheduler_disabled(verbose=verbose):
  File "/home/mstfrs/Desktop/ozerpan/apps/frappe/frappe/utils/scheduler.py", line 163, in is_scheduler_disabled
    frappe.db.get_single_value("System Settings", "enable_scheduler")
  File "/home/mstfrs/Desktop/ozerpan/apps/frappe/frappe/database/database.py", line 846, in get_single_value
    ).run()
  File "/home/mstfrs/Desktop/ozerpan/apps/frappe/frappe/query_builder/utils.py", line 84, in execute_query
    result = frappe.db.sql(query, params, *args, **kwargs)  # nosemgrep
  File "/home/mstfrs/Desktop/ozerpan/apps/frappe/frappe/database/database.py", line 213, in sql
    self.connect()
  File "/home/mstfrs/Desktop/ozerpan/apps/frappe/frappe/database/database.py", line 118, in connect
    self._conn: "MariadbConnection" | "PostgresConnection" = self.get_connection()
  File "/home/mstfrs/Desktop/ozerpan/apps/frappe/frappe/database/mariadb/database.py", line 107, in get_connection
    conn = self._get_connection()
  File "/home/mstfrs/Desktop/ozerpan/apps/frappe/frappe/database/mariadb/database.py", line 113, in _get_connection
    return self.create_connection()
  File "/home/mstfrs/Desktop/ozerpan/apps/frappe/frappe/database/mariadb/database.py", line 116, in create_connection
    return pymysql.connect(**self.get_connection_settings())
  File "/home/mstfrs/Desktop/ozerpan/env/lib/python3.10/site-packages/pymysql/connections.py", line 361, in __init__
    self.connect()
  File "/home/mstfrs/Desktop/ozerpan/env/lib/python3.10/site-packages/pymysql/connections.py", line 669, in connect
    self._request_authentication()
  File "/home/mstfrs/Desktop/ozerpan/env/lib/python3.10/site-packages/pymysql/connections.py", line 957, in _request_authentication
    auth_packet = self._read_packet()
  File "/home/mstfrs/Desktop/ozerpan/env/lib/python3.10/site-packages/pymysql/connections.py", line 775, in _read_packet
    packet.raise_for_error()
  File "/home/mstfrs/Desktop/ozerpan/env/lib/python3.10/site-packages/pymysql/protocol.py", line 219, in raise_for_error
    err.raise_mysql_exception(self._data)
  File "/home/mstfrs/Desktop/ozerpan/env/lib/python3.10/site-packages/pymysql/err.py", line 150, in raise_mysql_exception
    raise errorclass(errno, errval)
pymysql.err.OperationalError: (1049, "Unknown database '_be61cf5335d3ad96'")
2024-10-10 11:48:00,680 ERROR scheduler Exception in Enqueue Events for Site ozerpan
Traceback (most recent call last):
  File "/home/mstfrs/Desktop/ozerpan/apps/frappe/frappe/utils/scheduler.py", line 106, in enqueue_events_for_site
    if is_scheduler_inactive():
  File "/home/mstfrs/Desktop/ozerpan/apps/frappe/frappe/utils/scheduler.py", line 150, in is_scheduler_inactive
    if is_scheduler_disabled(verbose=verbose):
  File "/home/mstfrs/Desktop/ozerpan/apps/frappe/frappe/utils/scheduler.py", line 163, in is_scheduler_disabled
    frappe.db.get_single_value("System Settings", "enable_scheduler")
  File "/home/mstfrs/Desktop/ozerpan/apps/frappe/frappe/database/database.py", line 846, in get_single_value
    ).run()
  File "/home/mstfrs/Desktop/ozerpan/apps/frappe/frappe/query_builder/utils.py", line 84, in execute_query
    result = frappe.db.sql(query, params, *args, **kwargs)  # nosemgrep
  File "/home/mstfrs/Desktop/ozerpan/apps/frappe/frappe/database/database.py", line 213, in sql
    self.connect()
  File "/home/mstfrs/Desktop/ozerpan/apps/frappe/frappe/database/database.py", line 118, in connect
    self._conn: "MariadbConnection" | "PostgresConnection" = self.get_connection()
  File "/home/mstfrs/Desktop/ozerpan/apps/frappe/frappe/database/mariadb/database.py", line 107, in get_connection
    conn = self._get_connection()
  File "/home/mstfrs/Desktop/ozerpan/apps/frappe/frappe/database/mariadb/database.py", line 113, in _get_connection
    return self.create_connection()
  File "/home/mstfrs/Desktop/ozerpan/apps/frappe/frappe/database/mariadb/database.py", line 116, in create_connection
    return pymysql.connect(**self.get_connection_settings())
  File "/home/mstfrs/Desktop/ozerpan/env/lib/python3.10/site-packages/pymysql/connections.py", line 361, in __init__
    self.connect()
  File "/home/mstfrs/Desktop/ozerpan/env/lib/python3.10/site-packages/pymysql/connections.py", line 669, in connect
    self._request_authentication()
  File "/home/mstfrs/Desktop/ozerpan/env/lib/python3.10/site-packages/pymysql/connections.py", line 957, in _request_authentication
    auth_packet = self._read_packet()
  File "/home/mstfrs/Desktop/ozerpan/env/lib/python3.10/site-packages/pymysql/connections.py", line 775, in _read_packet
    packet.raise_for_error()
  File "/home/mstfrs/Desktop/ozerpan/env/lib/python3.10/site-packages/pymysql/protocol.py", line 219, in raise_for_error
    err.raise_mysql_exception(self._data)
  File "/home/mstfrs/Desktop/ozerpan/env/lib/python3.10/site-packages/pymysql/err.py", line 150, in raise_mysql_exception
    raise errorclass(errno, errval)
pymysql.err.OperationalError: (1049, "Unknown database '_be61cf5335d3ad96'")
