2024-10-08 11:16:00,672 ERROR scheduler Exception in Enqueue Events for Site ozerpan.local
Traceback (most recent call last):
  File "/home/mstfrs/Desktop/ozerpan/apps/frappe/frappe/utils/scheduler.py", line 106, in enqueue_events_for_site
    if is_scheduler_inactive():
  File "/home/mstfrs/Desktop/ozerpan/apps/frappe/frappe/utils/scheduler.py", line 150, in is_scheduler_inactive
    if is_scheduler_disabled(verbose=verbose):
  File "/home/mstfrs/Desktop/ozerpan/apps/frappe/frappe/utils/scheduler.py", line 163, in is_scheduler_disabled
    frappe.db.get_single_value("System Settings", "enable_scheduler")
  File "/home/mstfrs/Desktop/ozerpan/apps/frappe/frappe/database/database.py", line 846, in get_single_value
    ).run()
  File "/home/mstfrs/Desktop/ozerpan/apps/frappe/frappe/query_builder/utils.py", line 84, in execute_query
    result = frappe.db.sql(query, params, *args, **kwargs)  # nosemgrep
  File "/home/mstfrs/Desktop/ozerpan/apps/frappe/frappe/database/database.py", line 213, in sql
    self.connect()
  File "/home/mstfrs/Desktop/ozerpan/apps/frappe/frappe/database/database.py", line 118, in connect
    self._conn: "MariadbConnection" | "PostgresConnection" = self.get_connection()
  File "/home/mstfrs/Desktop/ozerpan/apps/frappe/frappe/database/mariadb/database.py", line 107, in get_connection
    conn = self._get_connection()
  File "/home/mstfrs/Desktop/ozerpan/apps/frappe/frappe/database/mariadb/database.py", line 113, in _get_connection
    return self.create_connection()
  File "/home/mstfrs/Desktop/ozerpan/apps/frappe/frappe/database/mariadb/database.py", line 116, in create_connection
    return pymysql.connect(**self.get_connection_settings())
  File "/home/mstfrs/Desktop/ozerpan/env/lib/python3.10/site-packages/pymysql/connections.py", line 361, in __init__
    self.connect()
  File "/home/mstfrs/Desktop/ozerpan/env/lib/python3.10/site-packages/pymysql/connections.py", line 669, in connect
    self._request_authentication()
  File "/home/mstfrs/Desktop/ozerpan/env/lib/python3.10/site-packages/pymysql/connections.py", line 957, in _request_authentication
    auth_packet = self._read_packet()
  File "/home/mstfrs/Desktop/ozerpan/env/lib/python3.10/site-packages/pymysql/connections.py", line 775, in _read_packet
    packet.raise_for_error()
  File "/home/mstfrs/Desktop/ozerpan/env/lib/python3.10/site-packages/pymysql/protocol.py", line 219, in raise_for_error
    err.raise_mysql_exception(self._data)
  File "/home/mstfrs/Desktop/ozerpan/env/lib/python3.10/site-packages/pymysql/err.py", line 150, in raise_mysql_exception
    raise errorclass(errno, errval)
pymysql.err.OperationalError: (1045, "Access denied for user '_c85c2ca7b22cd0b1'@'localhost' (using password: YES)")
2024-10-08 11:20:00,194 ERROR scheduler Exception in Enqueue Events for Site ozerpan.local
Traceback (most recent call last):
  File "/home/mstfrs/Desktop/ozerpan/apps/frappe/frappe/utils/scheduler.py", line 106, in enqueue_events_for_site
    if is_scheduler_inactive():
  File "/home/mstfrs/Desktop/ozerpan/apps/frappe/frappe/utils/scheduler.py", line 150, in is_scheduler_inactive
    if is_scheduler_disabled(verbose=verbose):
  File "/home/mstfrs/Desktop/ozerpan/apps/frappe/frappe/utils/scheduler.py", line 163, in is_scheduler_disabled
    frappe.db.get_single_value("System Settings", "enable_scheduler")
  File "/home/mstfrs/Desktop/ozerpan/apps/frappe/frappe/database/database.py", line 846, in get_single_value
    ).run()
  File "/home/mstfrs/Desktop/ozerpan/apps/frappe/frappe/query_builder/utils.py", line 84, in execute_query
    result = frappe.db.sql(query, params, *args, **kwargs)  # nosemgrep
  File "/home/mstfrs/Desktop/ozerpan/apps/frappe/frappe/database/database.py", line 213, in sql
    self.connect()
  File "/home/mstfrs/Desktop/ozerpan/apps/frappe/frappe/database/database.py", line 118, in connect
    self._conn: "MariadbConnection" | "PostgresConnection" = self.get_connection()
  File "/home/mstfrs/Desktop/ozerpan/apps/frappe/frappe/database/mariadb/database.py", line 107, in get_connection
    conn = self._get_connection()
  File "/home/mstfrs/Desktop/ozerpan/apps/frappe/frappe/database/mariadb/database.py", line 113, in _get_connection
    return self.create_connection()
  File "/home/mstfrs/Desktop/ozerpan/apps/frappe/frappe/database/mariadb/database.py", line 116, in create_connection
    return pymysql.connect(**self.get_connection_settings())
  File "/home/mstfrs/Desktop/ozerpan/env/lib/python3.10/site-packages/pymysql/connections.py", line 361, in __init__
    self.connect()
  File "/home/mstfrs/Desktop/ozerpan/env/lib/python3.10/site-packages/pymysql/connections.py", line 669, in connect
    self._request_authentication()
  File "/home/mstfrs/Desktop/ozerpan/env/lib/python3.10/site-packages/pymysql/connections.py", line 957, in _request_authentication
    auth_packet = self._read_packet()
  File "/home/mstfrs/Desktop/ozerpan/env/lib/python3.10/site-packages/pymysql/connections.py", line 775, in _read_packet
    packet.raise_for_error()
  File "/home/mstfrs/Desktop/ozerpan/env/lib/python3.10/site-packages/pymysql/protocol.py", line 219, in raise_for_error
    err.raise_mysql_exception(self._data)
  File "/home/mstfrs/Desktop/ozerpan/env/lib/python3.10/site-packages/pymysql/err.py", line 150, in raise_mysql_exception
    raise errorclass(errno, errval)
pymysql.err.OperationalError: (1045, "Access denied for user '_c85c2ca7b22cd0b1'@'localhost' (using password: YES)")
2024-10-08 11:24:00,593 ERROR scheduler Exception in Enqueue Events for Site ozerpan.local
Traceback (most recent call last):
  File "/home/mstfrs/Desktop/ozerpan/apps/frappe/frappe/utils/scheduler.py", line 106, in enqueue_events_for_site
    if is_scheduler_inactive():
  File "/home/mstfrs/Desktop/ozerpan/apps/frappe/frappe/utils/scheduler.py", line 150, in is_scheduler_inactive
    if is_scheduler_disabled(verbose=verbose):
  File "/home/mstfrs/Desktop/ozerpan/apps/frappe/frappe/utils/scheduler.py", line 163, in is_scheduler_disabled
    frappe.db.get_single_value("System Settings", "enable_scheduler")
  File "/home/mstfrs/Desktop/ozerpan/apps/frappe/frappe/database/database.py", line 846, in get_single_value
    ).run()
  File "/home/mstfrs/Desktop/ozerpan/apps/frappe/frappe/query_builder/utils.py", line 84, in execute_query
    result = frappe.db.sql(query, params, *args, **kwargs)  # nosemgrep
  File "/home/mstfrs/Desktop/ozerpan/apps/frappe/frappe/database/database.py", line 213, in sql
    self.connect()
  File "/home/mstfrs/Desktop/ozerpan/apps/frappe/frappe/database/database.py", line 118, in connect
    self._conn: "MariadbConnection" | "PostgresConnection" = self.get_connection()
  File "/home/mstfrs/Desktop/ozerpan/apps/frappe/frappe/database/mariadb/database.py", line 107, in get_connection
    conn = self._get_connection()
  File "/home/mstfrs/Desktop/ozerpan/apps/frappe/frappe/database/mariadb/database.py", line 113, in _get_connection
    return self.create_connection()
  File "/home/mstfrs/Desktop/ozerpan/apps/frappe/frappe/database/mariadb/database.py", line 116, in create_connection
    return pymysql.connect(**self.get_connection_settings())
  File "/home/mstfrs/Desktop/ozerpan/env/lib/python3.10/site-packages/pymysql/connections.py", line 361, in __init__
    self.connect()
  File "/home/mstfrs/Desktop/ozerpan/env/lib/python3.10/site-packages/pymysql/connections.py", line 669, in connect
    self._request_authentication()
  File "/home/mstfrs/Desktop/ozerpan/env/lib/python3.10/site-packages/pymysql/connections.py", line 957, in _request_authentication
    auth_packet = self._read_packet()
  File "/home/mstfrs/Desktop/ozerpan/env/lib/python3.10/site-packages/pymysql/connections.py", line 775, in _read_packet
    packet.raise_for_error()
  File "/home/mstfrs/Desktop/ozerpan/env/lib/python3.10/site-packages/pymysql/protocol.py", line 219, in raise_for_error
    err.raise_mysql_exception(self._data)
  File "/home/mstfrs/Desktop/ozerpan/env/lib/python3.10/site-packages/pymysql/err.py", line 150, in raise_mysql_exception
    raise errorclass(errno, errval)
pymysql.err.OperationalError: (1045, "Access denied for user '_c85c2ca7b22cd0b1'@'localhost' (using password: YES)")
2024-10-08 11:28:01,287 ERROR scheduler Exception in Enqueue Events for Site ozerpan.local
Traceback (most recent call last):
  File "/home/mstfrs/Desktop/ozerpan/apps/frappe/frappe/utils/scheduler.py", line 106, in enqueue_events_for_site
    if is_scheduler_inactive():
  File "/home/mstfrs/Desktop/ozerpan/apps/frappe/frappe/utils/scheduler.py", line 150, in is_scheduler_inactive
    if is_scheduler_disabled(verbose=verbose):
  File "/home/mstfrs/Desktop/ozerpan/apps/frappe/frappe/utils/scheduler.py", line 163, in is_scheduler_disabled
    frappe.db.get_single_value("System Settings", "enable_scheduler")
  File "/home/mstfrs/Desktop/ozerpan/apps/frappe/frappe/database/database.py", line 846, in get_single_value
    ).run()
  File "/home/mstfrs/Desktop/ozerpan/apps/frappe/frappe/query_builder/utils.py", line 84, in execute_query
    result = frappe.db.sql(query, params, *args, **kwargs)  # nosemgrep
  File "/home/mstfrs/Desktop/ozerpan/apps/frappe/frappe/database/database.py", line 213, in sql
    self.connect()
  File "/home/mstfrs/Desktop/ozerpan/apps/frappe/frappe/database/database.py", line 118, in connect
    self._conn: "MariadbConnection" | "PostgresConnection" = self.get_connection()
  File "/home/mstfrs/Desktop/ozerpan/apps/frappe/frappe/database/mariadb/database.py", line 107, in get_connection
    conn = self._get_connection()
  File "/home/mstfrs/Desktop/ozerpan/apps/frappe/frappe/database/mariadb/database.py", line 113, in _get_connection
    return self.create_connection()
  File "/home/mstfrs/Desktop/ozerpan/apps/frappe/frappe/database/mariadb/database.py", line 116, in create_connection
    return pymysql.connect(**self.get_connection_settings())
  File "/home/mstfrs/Desktop/ozerpan/env/lib/python3.10/site-packages/pymysql/connections.py", line 361, in __init__
    self.connect()
  File "/home/mstfrs/Desktop/ozerpan/env/lib/python3.10/site-packages/pymysql/connections.py", line 669, in connect
    self._request_authentication()
  File "/home/mstfrs/Desktop/ozerpan/env/lib/python3.10/site-packages/pymysql/connections.py", line 957, in _request_authentication
    auth_packet = self._read_packet()
  File "/home/mstfrs/Desktop/ozerpan/env/lib/python3.10/site-packages/pymysql/connections.py", line 775, in _read_packet
    packet.raise_for_error()
  File "/home/mstfrs/Desktop/ozerpan/env/lib/python3.10/site-packages/pymysql/protocol.py", line 219, in raise_for_error
    err.raise_mysql_exception(self._data)
  File "/home/mstfrs/Desktop/ozerpan/env/lib/python3.10/site-packages/pymysql/err.py", line 150, in raise_mysql_exception
    raise errorclass(errno, errval)
pymysql.err.OperationalError: (1045, "Access denied for user '_c85c2ca7b22cd0b1'@'localhost' (using password: YES)")
2024-10-08 11:32:00,794 ERROR scheduler Exception in Enqueue Events for Site ozerpan.local
Traceback (most recent call last):
  File "/home/mstfrs/Desktop/ozerpan/apps/frappe/frappe/utils/scheduler.py", line 106, in enqueue_events_for_site
    if is_scheduler_inactive():
  File "/home/mstfrs/Desktop/ozerpan/apps/frappe/frappe/utils/scheduler.py", line 150, in is_scheduler_inactive
    if is_scheduler_disabled(verbose=verbose):
  File "/home/mstfrs/Desktop/ozerpan/apps/frappe/frappe/utils/scheduler.py", line 163, in is_scheduler_disabled
    frappe.db.get_single_value("System Settings", "enable_scheduler")
  File "/home/mstfrs/Desktop/ozerpan/apps/frappe/frappe/database/database.py", line 846, in get_single_value
    ).run()
  File "/home/mstfrs/Desktop/ozerpan/apps/frappe/frappe/query_builder/utils.py", line 84, in execute_query
    result = frappe.db.sql(query, params, *args, **kwargs)  # nosemgrep
  File "/home/mstfrs/Desktop/ozerpan/apps/frappe/frappe/database/database.py", line 213, in sql
    self.connect()
  File "/home/mstfrs/Desktop/ozerpan/apps/frappe/frappe/database/database.py", line 118, in connect
    self._conn: "MariadbConnection" | "PostgresConnection" = self.get_connection()
  File "/home/mstfrs/Desktop/ozerpan/apps/frappe/frappe/database/mariadb/database.py", line 107, in get_connection
    conn = self._get_connection()
  File "/home/mstfrs/Desktop/ozerpan/apps/frappe/frappe/database/mariadb/database.py", line 113, in _get_connection
    return self.create_connection()
  File "/home/mstfrs/Desktop/ozerpan/apps/frappe/frappe/database/mariadb/database.py", line 116, in create_connection
    return pymysql.connect(**self.get_connection_settings())
  File "/home/mstfrs/Desktop/ozerpan/env/lib/python3.10/site-packages/pymysql/connections.py", line 361, in __init__
    self.connect()
  File "/home/mstfrs/Desktop/ozerpan/env/lib/python3.10/site-packages/pymysql/connections.py", line 669, in connect
    self._request_authentication()
  File "/home/mstfrs/Desktop/ozerpan/env/lib/python3.10/site-packages/pymysql/connections.py", line 957, in _request_authentication
    auth_packet = self._read_packet()
  File "/home/mstfrs/Desktop/ozerpan/env/lib/python3.10/site-packages/pymysql/connections.py", line 775, in _read_packet
    packet.raise_for_error()
  File "/home/mstfrs/Desktop/ozerpan/env/lib/python3.10/site-packages/pymysql/protocol.py", line 219, in raise_for_error
    err.raise_mysql_exception(self._data)
  File "/home/mstfrs/Desktop/ozerpan/env/lib/python3.10/site-packages/pymysql/err.py", line 150, in raise_mysql_exception
    raise errorclass(errno, errval)
pymysql.err.OperationalError: (1045, "Access denied for user '_c85c2ca7b22cd0b1'@'localhost' (using password: YES)")
2024-10-08 11:36:00,949 ERROR scheduler Exception in Enqueue Events for Site ozerpan.local
Traceback (most recent call last):
  File "/home/mstfrs/Desktop/ozerpan/apps/frappe/frappe/utils/scheduler.py", line 106, in enqueue_events_for_site
    if is_scheduler_inactive():
  File "/home/mstfrs/Desktop/ozerpan/apps/frappe/frappe/utils/scheduler.py", line 150, in is_scheduler_inactive
    if is_scheduler_disabled(verbose=verbose):
  File "/home/mstfrs/Desktop/ozerpan/apps/frappe/frappe/utils/scheduler.py", line 163, in is_scheduler_disabled
    frappe.db.get_single_value("System Settings", "enable_scheduler")
  File "/home/mstfrs/Desktop/ozerpan/apps/frappe/frappe/database/database.py", line 846, in get_single_value
    ).run()
  File "/home/mstfrs/Desktop/ozerpan/apps/frappe/frappe/query_builder/utils.py", line 84, in execute_query
    result = frappe.db.sql(query, params, *args, **kwargs)  # nosemgrep
  File "/home/mstfrs/Desktop/ozerpan/apps/frappe/frappe/database/database.py", line 213, in sql
    self.connect()
  File "/home/mstfrs/Desktop/ozerpan/apps/frappe/frappe/database/database.py", line 118, in connect
    self._conn: "MariadbConnection" | "PostgresConnection" = self.get_connection()
  File "/home/mstfrs/Desktop/ozerpan/apps/frappe/frappe/database/mariadb/database.py", line 107, in get_connection
    conn = self._get_connection()
  File "/home/mstfrs/Desktop/ozerpan/apps/frappe/frappe/database/mariadb/database.py", line 113, in _get_connection
    return self.create_connection()
  File "/home/mstfrs/Desktop/ozerpan/apps/frappe/frappe/database/mariadb/database.py", line 116, in create_connection
    return pymysql.connect(**self.get_connection_settings())
  File "/home/mstfrs/Desktop/ozerpan/env/lib/python3.10/site-packages/pymysql/connections.py", line 361, in __init__
    self.connect()
  File "/home/mstfrs/Desktop/ozerpan/env/lib/python3.10/site-packages/pymysql/connections.py", line 669, in connect
    self._request_authentication()
  File "/home/mstfrs/Desktop/ozerpan/env/lib/python3.10/site-packages/pymysql/connections.py", line 957, in _request_authentication
    auth_packet = self._read_packet()
  File "/home/mstfrs/Desktop/ozerpan/env/lib/python3.10/site-packages/pymysql/connections.py", line 775, in _read_packet
    packet.raise_for_error()
  File "/home/mstfrs/Desktop/ozerpan/env/lib/python3.10/site-packages/pymysql/protocol.py", line 219, in raise_for_error
    err.raise_mysql_exception(self._data)
  File "/home/mstfrs/Desktop/ozerpan/env/lib/python3.10/site-packages/pymysql/err.py", line 150, in raise_mysql_exception
    raise errorclass(errno, errval)
pymysql.err.OperationalError: (1045, "Access denied for user '_c85c2ca7b22cd0b1'@'localhost' (using password: YES)")
2024-10-08 11:40:00,727 ERROR scheduler Exception in Enqueue Events for Site ozerpan.local
Traceback (most recent call last):
  File "/home/mstfrs/Desktop/ozerpan/apps/frappe/frappe/utils/scheduler.py", line 106, in enqueue_events_for_site
    if is_scheduler_inactive():
  File "/home/mstfrs/Desktop/ozerpan/apps/frappe/frappe/utils/scheduler.py", line 150, in is_scheduler_inactive
    if is_scheduler_disabled(verbose=verbose):
  File "/home/mstfrs/Desktop/ozerpan/apps/frappe/frappe/utils/scheduler.py", line 163, in is_scheduler_disabled
    frappe.db.get_single_value("System Settings", "enable_scheduler")
  File "/home/mstfrs/Desktop/ozerpan/apps/frappe/frappe/database/database.py", line 846, in get_single_value
    ).run()
  File "/home/mstfrs/Desktop/ozerpan/apps/frappe/frappe/query_builder/utils.py", line 84, in execute_query
    result = frappe.db.sql(query, params, *args, **kwargs)  # nosemgrep
  File "/home/mstfrs/Desktop/ozerpan/apps/frappe/frappe/database/database.py", line 213, in sql
    self.connect()
  File "/home/mstfrs/Desktop/ozerpan/apps/frappe/frappe/database/database.py", line 118, in connect
    self._conn: "MariadbConnection" | "PostgresConnection" = self.get_connection()
  File "/home/mstfrs/Desktop/ozerpan/apps/frappe/frappe/database/mariadb/database.py", line 107, in get_connection
    conn = self._get_connection()
  File "/home/mstfrs/Desktop/ozerpan/apps/frappe/frappe/database/mariadb/database.py", line 113, in _get_connection
    return self.create_connection()
  File "/home/mstfrs/Desktop/ozerpan/apps/frappe/frappe/database/mariadb/database.py", line 116, in create_connection
    return pymysql.connect(**self.get_connection_settings())
  File "/home/mstfrs/Desktop/ozerpan/env/lib/python3.10/site-packages/pymysql/connections.py", line 361, in __init__
    self.connect()
  File "/home/mstfrs/Desktop/ozerpan/env/lib/python3.10/site-packages/pymysql/connections.py", line 669, in connect
    self._request_authentication()
  File "/home/mstfrs/Desktop/ozerpan/env/lib/python3.10/site-packages/pymysql/connections.py", line 957, in _request_authentication
    auth_packet = self._read_packet()
  File "/home/mstfrs/Desktop/ozerpan/env/lib/python3.10/site-packages/pymysql/connections.py", line 775, in _read_packet
    packet.raise_for_error()
  File "/home/mstfrs/Desktop/ozerpan/env/lib/python3.10/site-packages/pymysql/protocol.py", line 219, in raise_for_error
    err.raise_mysql_exception(self._data)
  File "/home/mstfrs/Desktop/ozerpan/env/lib/python3.10/site-packages/pymysql/err.py", line 150, in raise_mysql_exception
    raise errorclass(errno, errval)
pymysql.err.OperationalError: (1045, "Access denied for user '_c85c2ca7b22cd0b1'@'localhost' (using password: YES)")
2024-10-08 11:44:01,165 ERROR scheduler Exception in Enqueue Events for Site ozerpan.local
Traceback (most recent call last):
  File "/home/mstfrs/Desktop/ozerpan/apps/frappe/frappe/utils/scheduler.py", line 106, in enqueue_events_for_site
    if is_scheduler_inactive():
  File "/home/mstfrs/Desktop/ozerpan/apps/frappe/frappe/utils/scheduler.py", line 150, in is_scheduler_inactive
    if is_scheduler_disabled(verbose=verbose):
  File "/home/mstfrs/Desktop/ozerpan/apps/frappe/frappe/utils/scheduler.py", line 163, in is_scheduler_disabled
    frappe.db.get_single_value("System Settings", "enable_scheduler")
  File "/home/mstfrs/Desktop/ozerpan/apps/frappe/frappe/database/database.py", line 846, in get_single_value
    ).run()
  File "/home/mstfrs/Desktop/ozerpan/apps/frappe/frappe/query_builder/utils.py", line 84, in execute_query
    result = frappe.db.sql(query, params, *args, **kwargs)  # nosemgrep
  File "/home/mstfrs/Desktop/ozerpan/apps/frappe/frappe/database/database.py", line 213, in sql
    self.connect()
  File "/home/mstfrs/Desktop/ozerpan/apps/frappe/frappe/database/database.py", line 118, in connect
    self._conn: "MariadbConnection" | "PostgresConnection" = self.get_connection()
  File "/home/mstfrs/Desktop/ozerpan/apps/frappe/frappe/database/mariadb/database.py", line 107, in get_connection
    conn = self._get_connection()
  File "/home/mstfrs/Desktop/ozerpan/apps/frappe/frappe/database/mariadb/database.py", line 113, in _get_connection
    return self.create_connection()
  File "/home/mstfrs/Desktop/ozerpan/apps/frappe/frappe/database/mariadb/database.py", line 116, in create_connection
    return pymysql.connect(**self.get_connection_settings())
  File "/home/mstfrs/Desktop/ozerpan/env/lib/python3.10/site-packages/pymysql/connections.py", line 361, in __init__
    self.connect()
  File "/home/mstfrs/Desktop/ozerpan/env/lib/python3.10/site-packages/pymysql/connections.py", line 669, in connect
    self._request_authentication()
  File "/home/mstfrs/Desktop/ozerpan/env/lib/python3.10/site-packages/pymysql/connections.py", line 957, in _request_authentication
    auth_packet = self._read_packet()
  File "/home/mstfrs/Desktop/ozerpan/env/lib/python3.10/site-packages/pymysql/connections.py", line 775, in _read_packet
    packet.raise_for_error()
  File "/home/mstfrs/Desktop/ozerpan/env/lib/python3.10/site-packages/pymysql/protocol.py", line 219, in raise_for_error
    err.raise_mysql_exception(self._data)
  File "/home/mstfrs/Desktop/ozerpan/env/lib/python3.10/site-packages/pymysql/err.py", line 150, in raise_mysql_exception
    raise errorclass(errno, errval)
pymysql.err.OperationalError: (1045, "Access denied for user '_c85c2ca7b22cd0b1'@'localhost' (using password: YES)")
2024-10-08 11:48:00,244 ERROR scheduler Exception in Enqueue Events for Site ozerpan.local
Traceback (most recent call last):
  File "/home/mstfrs/Desktop/ozerpan/apps/frappe/frappe/utils/scheduler.py", line 106, in enqueue_events_for_site
    if is_scheduler_inactive():
  File "/home/mstfrs/Desktop/ozerpan/apps/frappe/frappe/utils/scheduler.py", line 150, in is_scheduler_inactive
    if is_scheduler_disabled(verbose=verbose):
  File "/home/mstfrs/Desktop/ozerpan/apps/frappe/frappe/utils/scheduler.py", line 163, in is_scheduler_disabled
    frappe.db.get_single_value("System Settings", "enable_scheduler")
  File "/home/mstfrs/Desktop/ozerpan/apps/frappe/frappe/database/database.py", line 846, in get_single_value
    ).run()
  File "/home/mstfrs/Desktop/ozerpan/apps/frappe/frappe/query_builder/utils.py", line 84, in execute_query
    result = frappe.db.sql(query, params, *args, **kwargs)  # nosemgrep
  File "/home/mstfrs/Desktop/ozerpan/apps/frappe/frappe/database/database.py", line 213, in sql
    self.connect()
  File "/home/mstfrs/Desktop/ozerpan/apps/frappe/frappe/database/database.py", line 118, in connect
    self._conn: "MariadbConnection" | "PostgresConnection" = self.get_connection()
  File "/home/mstfrs/Desktop/ozerpan/apps/frappe/frappe/database/mariadb/database.py", line 107, in get_connection
    conn = self._get_connection()
  File "/home/mstfrs/Desktop/ozerpan/apps/frappe/frappe/database/mariadb/database.py", line 113, in _get_connection
    return self.create_connection()
  File "/home/mstfrs/Desktop/ozerpan/apps/frappe/frappe/database/mariadb/database.py", line 116, in create_connection
    return pymysql.connect(**self.get_connection_settings())
  File "/home/mstfrs/Desktop/ozerpan/env/lib/python3.10/site-packages/pymysql/connections.py", line 361, in __init__
    self.connect()
  File "/home/mstfrs/Desktop/ozerpan/env/lib/python3.10/site-packages/pymysql/connections.py", line 669, in connect
    self._request_authentication()
  File "/home/mstfrs/Desktop/ozerpan/env/lib/python3.10/site-packages/pymysql/connections.py", line 957, in _request_authentication
    auth_packet = self._read_packet()
  File "/home/mstfrs/Desktop/ozerpan/env/lib/python3.10/site-packages/pymysql/connections.py", line 775, in _read_packet
    packet.raise_for_error()
  File "/home/mstfrs/Desktop/ozerpan/env/lib/python3.10/site-packages/pymysql/protocol.py", line 219, in raise_for_error
    err.raise_mysql_exception(self._data)
  File "/home/mstfrs/Desktop/ozerpan/env/lib/python3.10/site-packages/pymysql/err.py", line 150, in raise_mysql_exception
    raise errorclass(errno, errval)
pymysql.err.OperationalError: (1045, "Access denied for user '_c85c2ca7b22cd0b1'@'localhost' (using password: YES)")
2024-10-08 11:52:01,062 ERROR scheduler Exception in Enqueue Events for Site ozerpan.local
Traceback (most recent call last):
  File "/home/mstfrs/Desktop/ozerpan/apps/frappe/frappe/utils/scheduler.py", line 106, in enqueue_events_for_site
    if is_scheduler_inactive():
  File "/home/mstfrs/Desktop/ozerpan/apps/frappe/frappe/utils/scheduler.py", line 150, in is_scheduler_inactive
    if is_scheduler_disabled(verbose=verbose):
  File "/home/mstfrs/Desktop/ozerpan/apps/frappe/frappe/utils/scheduler.py", line 163, in is_scheduler_disabled
    frappe.db.get_single_value("System Settings", "enable_scheduler")
  File "/home/mstfrs/Desktop/ozerpan/apps/frappe/frappe/database/database.py", line 846, in get_single_value
    ).run()
  File "/home/mstfrs/Desktop/ozerpan/apps/frappe/frappe/query_builder/utils.py", line 84, in execute_query
    result = frappe.db.sql(query, params, *args, **kwargs)  # nosemgrep
  File "/home/mstfrs/Desktop/ozerpan/apps/frappe/frappe/database/database.py", line 213, in sql
    self.connect()
  File "/home/mstfrs/Desktop/ozerpan/apps/frappe/frappe/database/database.py", line 118, in connect
    self._conn: "MariadbConnection" | "PostgresConnection" = self.get_connection()
  File "/home/mstfrs/Desktop/ozerpan/apps/frappe/frappe/database/mariadb/database.py", line 107, in get_connection
    conn = self._get_connection()
  File "/home/mstfrs/Desktop/ozerpan/apps/frappe/frappe/database/mariadb/database.py", line 113, in _get_connection
    return self.create_connection()
  File "/home/mstfrs/Desktop/ozerpan/apps/frappe/frappe/database/mariadb/database.py", line 116, in create_connection
    return pymysql.connect(**self.get_connection_settings())
  File "/home/mstfrs/Desktop/ozerpan/env/lib/python3.10/site-packages/pymysql/connections.py", line 361, in __init__
    self.connect()
  File "/home/mstfrs/Desktop/ozerpan/env/lib/python3.10/site-packages/pymysql/connections.py", line 669, in connect
    self._request_authentication()
  File "/home/mstfrs/Desktop/ozerpan/env/lib/python3.10/site-packages/pymysql/connections.py", line 957, in _request_authentication
    auth_packet = self._read_packet()
  File "/home/mstfrs/Desktop/ozerpan/env/lib/python3.10/site-packages/pymysql/connections.py", line 775, in _read_packet
    packet.raise_for_error()
  File "/home/mstfrs/Desktop/ozerpan/env/lib/python3.10/site-packages/pymysql/protocol.py", line 219, in raise_for_error
    err.raise_mysql_exception(self._data)
  File "/home/mstfrs/Desktop/ozerpan/env/lib/python3.10/site-packages/pymysql/err.py", line 150, in raise_mysql_exception
    raise errorclass(errno, errval)
pymysql.err.OperationalError: (1045, "Access denied for user '_c85c2ca7b22cd0b1'@'localhost' (using password: YES)")
2024-10-08 11:56:00,470 ERROR scheduler Exception in Enqueue Events for Site ozerpan.local
Traceback (most recent call last):
  File "/home/mstfrs/Desktop/ozerpan/apps/frappe/frappe/utils/scheduler.py", line 106, in enqueue_events_for_site
    if is_scheduler_inactive():
  File "/home/mstfrs/Desktop/ozerpan/apps/frappe/frappe/utils/scheduler.py", line 150, in is_scheduler_inactive
    if is_scheduler_disabled(verbose=verbose):
  File "/home/mstfrs/Desktop/ozerpan/apps/frappe/frappe/utils/scheduler.py", line 163, in is_scheduler_disabled
    frappe.db.get_single_value("System Settings", "enable_scheduler")
  File "/home/mstfrs/Desktop/ozerpan/apps/frappe/frappe/database/database.py", line 846, in get_single_value
    ).run()
  File "/home/mstfrs/Desktop/ozerpan/apps/frappe/frappe/query_builder/utils.py", line 84, in execute_query
    result = frappe.db.sql(query, params, *args, **kwargs)  # nosemgrep
  File "/home/mstfrs/Desktop/ozerpan/apps/frappe/frappe/database/database.py", line 213, in sql
    self.connect()
  File "/home/mstfrs/Desktop/ozerpan/apps/frappe/frappe/database/database.py", line 118, in connect
    self._conn: "MariadbConnection" | "PostgresConnection" = self.get_connection()
  File "/home/mstfrs/Desktop/ozerpan/apps/frappe/frappe/database/mariadb/database.py", line 107, in get_connection
    conn = self._get_connection()
  File "/home/mstfrs/Desktop/ozerpan/apps/frappe/frappe/database/mariadb/database.py", line 113, in _get_connection
    return self.create_connection()
  File "/home/mstfrs/Desktop/ozerpan/apps/frappe/frappe/database/mariadb/database.py", line 116, in create_connection
    return pymysql.connect(**self.get_connection_settings())
  File "/home/mstfrs/Desktop/ozerpan/env/lib/python3.10/site-packages/pymysql/connections.py", line 361, in __init__
    self.connect()
  File "/home/mstfrs/Desktop/ozerpan/env/lib/python3.10/site-packages/pymysql/connections.py", line 669, in connect
    self._request_authentication()
  File "/home/mstfrs/Desktop/ozerpan/env/lib/python3.10/site-packages/pymysql/connections.py", line 957, in _request_authentication
    auth_packet = self._read_packet()
  File "/home/mstfrs/Desktop/ozerpan/env/lib/python3.10/site-packages/pymysql/connections.py", line 775, in _read_packet
    packet.raise_for_error()
  File "/home/mstfrs/Desktop/ozerpan/env/lib/python3.10/site-packages/pymysql/protocol.py", line 219, in raise_for_error
    err.raise_mysql_exception(self._data)
  File "/home/mstfrs/Desktop/ozerpan/env/lib/python3.10/site-packages/pymysql/err.py", line 150, in raise_mysql_exception
    raise errorclass(errno, errval)
pymysql.err.OperationalError: (1045, "Access denied for user '_c85c2ca7b22cd0b1'@'localhost' (using password: YES)")
2024-10-08 12:00:01,187 ERROR scheduler Exception in Enqueue Events for Site ozerpan.local
Traceback (most recent call last):
  File "/home/mstfrs/Desktop/ozerpan/apps/frappe/frappe/utils/scheduler.py", line 106, in enqueue_events_for_site
    if is_scheduler_inactive():
  File "/home/mstfrs/Desktop/ozerpan/apps/frappe/frappe/utils/scheduler.py", line 150, in is_scheduler_inactive
    if is_scheduler_disabled(verbose=verbose):
  File "/home/mstfrs/Desktop/ozerpan/apps/frappe/frappe/utils/scheduler.py", line 163, in is_scheduler_disabled
    frappe.db.get_single_value("System Settings", "enable_scheduler")
  File "/home/mstfrs/Desktop/ozerpan/apps/frappe/frappe/database/database.py", line 846, in get_single_value
    ).run()
  File "/home/mstfrs/Desktop/ozerpan/apps/frappe/frappe/query_builder/utils.py", line 84, in execute_query
    result = frappe.db.sql(query, params, *args, **kwargs)  # nosemgrep
  File "/home/mstfrs/Desktop/ozerpan/apps/frappe/frappe/database/database.py", line 213, in sql
    self.connect()
  File "/home/mstfrs/Desktop/ozerpan/apps/frappe/frappe/database/database.py", line 118, in connect
    self._conn: "MariadbConnection" | "PostgresConnection" = self.get_connection()
  File "/home/mstfrs/Desktop/ozerpan/apps/frappe/frappe/database/mariadb/database.py", line 107, in get_connection
    conn = self._get_connection()
  File "/home/mstfrs/Desktop/ozerpan/apps/frappe/frappe/database/mariadb/database.py", line 113, in _get_connection
    return self.create_connection()
  File "/home/mstfrs/Desktop/ozerpan/apps/frappe/frappe/database/mariadb/database.py", line 116, in create_connection
    return pymysql.connect(**self.get_connection_settings())
  File "/home/mstfrs/Desktop/ozerpan/env/lib/python3.10/site-packages/pymysql/connections.py", line 361, in __init__
    self.connect()
  File "/home/mstfrs/Desktop/ozerpan/env/lib/python3.10/site-packages/pymysql/connections.py", line 669, in connect
    self._request_authentication()
  File "/home/mstfrs/Desktop/ozerpan/env/lib/python3.10/site-packages/pymysql/connections.py", line 957, in _request_authentication
    auth_packet = self._read_packet()
  File "/home/mstfrs/Desktop/ozerpan/env/lib/python3.10/site-packages/pymysql/connections.py", line 775, in _read_packet
    packet.raise_for_error()
  File "/home/mstfrs/Desktop/ozerpan/env/lib/python3.10/site-packages/pymysql/protocol.py", line 219, in raise_for_error
    err.raise_mysql_exception(self._data)
  File "/home/mstfrs/Desktop/ozerpan/env/lib/python3.10/site-packages/pymysql/err.py", line 150, in raise_mysql_exception
    raise errorclass(errno, errval)
pymysql.err.OperationalError: (1045, "Access denied for user '_c85c2ca7b22cd0b1'@'localhost' (using password: YES)")
2024-10-08 12:04:00,289 ERROR scheduler Exception in Enqueue Events for Site ozerpan.local
Traceback (most recent call last):
  File "/home/mstfrs/Desktop/ozerpan/apps/frappe/frappe/utils/scheduler.py", line 106, in enqueue_events_for_site
    if is_scheduler_inactive():
  File "/home/mstfrs/Desktop/ozerpan/apps/frappe/frappe/utils/scheduler.py", line 150, in is_scheduler_inactive
    if is_scheduler_disabled(verbose=verbose):
  File "/home/mstfrs/Desktop/ozerpan/apps/frappe/frappe/utils/scheduler.py", line 163, in is_scheduler_disabled
    frappe.db.get_single_value("System Settings", "enable_scheduler")
  File "/home/mstfrs/Desktop/ozerpan/apps/frappe/frappe/database/database.py", line 846, in get_single_value
    ).run()
  File "/home/mstfrs/Desktop/ozerpan/apps/frappe/frappe/query_builder/utils.py", line 84, in execute_query
    result = frappe.db.sql(query, params, *args, **kwargs)  # nosemgrep
  File "/home/mstfrs/Desktop/ozerpan/apps/frappe/frappe/database/database.py", line 213, in sql
    self.connect()
  File "/home/mstfrs/Desktop/ozerpan/apps/frappe/frappe/database/database.py", line 118, in connect
    self._conn: "MariadbConnection" | "PostgresConnection" = self.get_connection()
  File "/home/mstfrs/Desktop/ozerpan/apps/frappe/frappe/database/mariadb/database.py", line 107, in get_connection
    conn = self._get_connection()
  File "/home/mstfrs/Desktop/ozerpan/apps/frappe/frappe/database/mariadb/database.py", line 113, in _get_connection
    return self.create_connection()
  File "/home/mstfrs/Desktop/ozerpan/apps/frappe/frappe/database/mariadb/database.py", line 116, in create_connection
    return pymysql.connect(**self.get_connection_settings())
  File "/home/mstfrs/Desktop/ozerpan/env/lib/python3.10/site-packages/pymysql/connections.py", line 361, in __init__
    self.connect()
  File "/home/mstfrs/Desktop/ozerpan/env/lib/python3.10/site-packages/pymysql/connections.py", line 669, in connect
    self._request_authentication()
  File "/home/mstfrs/Desktop/ozerpan/env/lib/python3.10/site-packages/pymysql/connections.py", line 957, in _request_authentication
    auth_packet = self._read_packet()
  File "/home/mstfrs/Desktop/ozerpan/env/lib/python3.10/site-packages/pymysql/connections.py", line 775, in _read_packet
    packet.raise_for_error()
  File "/home/mstfrs/Desktop/ozerpan/env/lib/python3.10/site-packages/pymysql/protocol.py", line 219, in raise_for_error
    err.raise_mysql_exception(self._data)
  File "/home/mstfrs/Desktop/ozerpan/env/lib/python3.10/site-packages/pymysql/err.py", line 150, in raise_mysql_exception
    raise errorclass(errno, errval)
pymysql.err.OperationalError: (1045, "Access denied for user '_c85c2ca7b22cd0b1'@'localhost' (using password: YES)")
2024-10-08 12:08:01,045 ERROR scheduler Exception in Enqueue Events for Site ozerpan.local
Traceback (most recent call last):
  File "/home/mstfrs/Desktop/ozerpan/apps/frappe/frappe/utils/scheduler.py", line 106, in enqueue_events_for_site
    if is_scheduler_inactive():
  File "/home/mstfrs/Desktop/ozerpan/apps/frappe/frappe/utils/scheduler.py", line 150, in is_scheduler_inactive
    if is_scheduler_disabled(verbose=verbose):
  File "/home/mstfrs/Desktop/ozerpan/apps/frappe/frappe/utils/scheduler.py", line 163, in is_scheduler_disabled
    frappe.db.get_single_value("System Settings", "enable_scheduler")
  File "/home/mstfrs/Desktop/ozerpan/apps/frappe/frappe/database/database.py", line 846, in get_single_value
    ).run()
  File "/home/mstfrs/Desktop/ozerpan/apps/frappe/frappe/query_builder/utils.py", line 84, in execute_query
    result = frappe.db.sql(query, params, *args, **kwargs)  # nosemgrep
  File "/home/mstfrs/Desktop/ozerpan/apps/frappe/frappe/database/database.py", line 213, in sql
    self.connect()
  File "/home/mstfrs/Desktop/ozerpan/apps/frappe/frappe/database/database.py", line 118, in connect
    self._conn: "MariadbConnection" | "PostgresConnection" = self.get_connection()
  File "/home/mstfrs/Desktop/ozerpan/apps/frappe/frappe/database/mariadb/database.py", line 107, in get_connection
    conn = self._get_connection()
  File "/home/mstfrs/Desktop/ozerpan/apps/frappe/frappe/database/mariadb/database.py", line 113, in _get_connection
    return self.create_connection()
  File "/home/mstfrs/Desktop/ozerpan/apps/frappe/frappe/database/mariadb/database.py", line 116, in create_connection
    return pymysql.connect(**self.get_connection_settings())
  File "/home/mstfrs/Desktop/ozerpan/env/lib/python3.10/site-packages/pymysql/connections.py", line 361, in __init__
    self.connect()
  File "/home/mstfrs/Desktop/ozerpan/env/lib/python3.10/site-packages/pymysql/connections.py", line 669, in connect
    self._request_authentication()
  File "/home/mstfrs/Desktop/ozerpan/env/lib/python3.10/site-packages/pymysql/connections.py", line 957, in _request_authentication
    auth_packet = self._read_packet()
  File "/home/mstfrs/Desktop/ozerpan/env/lib/python3.10/site-packages/pymysql/connections.py", line 775, in _read_packet
    packet.raise_for_error()
  File "/home/mstfrs/Desktop/ozerpan/env/lib/python3.10/site-packages/pymysql/protocol.py", line 219, in raise_for_error
    err.raise_mysql_exception(self._data)
  File "/home/mstfrs/Desktop/ozerpan/env/lib/python3.10/site-packages/pymysql/err.py", line 150, in raise_mysql_exception
    raise errorclass(errno, errval)
pymysql.err.OperationalError: (1045, "Access denied for user '_c85c2ca7b22cd0b1'@'localhost' (using password: YES)")
2024-10-08 12:12:00,451 ERROR scheduler Exception in Enqueue Events for Site ozerpan.local
Traceback (most recent call last):
  File "/home/mstfrs/Desktop/ozerpan/apps/frappe/frappe/utils/scheduler.py", line 106, in enqueue_events_for_site
    if is_scheduler_inactive():
  File "/home/mstfrs/Desktop/ozerpan/apps/frappe/frappe/utils/scheduler.py", line 150, in is_scheduler_inactive
    if is_scheduler_disabled(verbose=verbose):
  File "/home/mstfrs/Desktop/ozerpan/apps/frappe/frappe/utils/scheduler.py", line 163, in is_scheduler_disabled
    frappe.db.get_single_value("System Settings", "enable_scheduler")
  File "/home/mstfrs/Desktop/ozerpan/apps/frappe/frappe/database/database.py", line 846, in get_single_value
    ).run()
  File "/home/mstfrs/Desktop/ozerpan/apps/frappe/frappe/query_builder/utils.py", line 84, in execute_query
    result = frappe.db.sql(query, params, *args, **kwargs)  # nosemgrep
  File "/home/mstfrs/Desktop/ozerpan/apps/frappe/frappe/database/database.py", line 213, in sql
    self.connect()
  File "/home/mstfrs/Desktop/ozerpan/apps/frappe/frappe/database/database.py", line 118, in connect
    self._conn: "MariadbConnection" | "PostgresConnection" = self.get_connection()
  File "/home/mstfrs/Desktop/ozerpan/apps/frappe/frappe/database/mariadb/database.py", line 107, in get_connection
    conn = self._get_connection()
  File "/home/mstfrs/Desktop/ozerpan/apps/frappe/frappe/database/mariadb/database.py", line 113, in _get_connection
    return self.create_connection()
  File "/home/mstfrs/Desktop/ozerpan/apps/frappe/frappe/database/mariadb/database.py", line 116, in create_connection
    return pymysql.connect(**self.get_connection_settings())
  File "/home/mstfrs/Desktop/ozerpan/env/lib/python3.10/site-packages/pymysql/connections.py", line 361, in __init__
    self.connect()
  File "/home/mstfrs/Desktop/ozerpan/env/lib/python3.10/site-packages/pymysql/connections.py", line 669, in connect
    self._request_authentication()
  File "/home/mstfrs/Desktop/ozerpan/env/lib/python3.10/site-packages/pymysql/connections.py", line 957, in _request_authentication
    auth_packet = self._read_packet()
  File "/home/mstfrs/Desktop/ozerpan/env/lib/python3.10/site-packages/pymysql/connections.py", line 775, in _read_packet
    packet.raise_for_error()
  File "/home/mstfrs/Desktop/ozerpan/env/lib/python3.10/site-packages/pymysql/protocol.py", line 219, in raise_for_error
    err.raise_mysql_exception(self._data)
  File "/home/mstfrs/Desktop/ozerpan/env/lib/python3.10/site-packages/pymysql/err.py", line 150, in raise_mysql_exception
    raise errorclass(errno, errval)
pymysql.err.OperationalError: (1045, "Access denied for user '_c85c2ca7b22cd0b1'@'localhost' (using password: YES)")
2024-10-08 12:16:00,888 ERROR scheduler Exception in Enqueue Events for Site ozerpan.local
Traceback (most recent call last):
  File "/home/mstfrs/Desktop/ozerpan/apps/frappe/frappe/utils/scheduler.py", line 106, in enqueue_events_for_site
    if is_scheduler_inactive():
  File "/home/mstfrs/Desktop/ozerpan/apps/frappe/frappe/utils/scheduler.py", line 150, in is_scheduler_inactive
    if is_scheduler_disabled(verbose=verbose):
  File "/home/mstfrs/Desktop/ozerpan/apps/frappe/frappe/utils/scheduler.py", line 163, in is_scheduler_disabled
    frappe.db.get_single_value("System Settings", "enable_scheduler")
  File "/home/mstfrs/Desktop/ozerpan/apps/frappe/frappe/database/database.py", line 846, in get_single_value
    ).run()
  File "/home/mstfrs/Desktop/ozerpan/apps/frappe/frappe/query_builder/utils.py", line 84, in execute_query
    result = frappe.db.sql(query, params, *args, **kwargs)  # nosemgrep
  File "/home/mstfrs/Desktop/ozerpan/apps/frappe/frappe/database/database.py", line 213, in sql
    self.connect()
  File "/home/mstfrs/Desktop/ozerpan/apps/frappe/frappe/database/database.py", line 118, in connect
    self._conn: "MariadbConnection" | "PostgresConnection" = self.get_connection()
  File "/home/mstfrs/Desktop/ozerpan/apps/frappe/frappe/database/mariadb/database.py", line 107, in get_connection
    conn = self._get_connection()
  File "/home/mstfrs/Desktop/ozerpan/apps/frappe/frappe/database/mariadb/database.py", line 113, in _get_connection
    return self.create_connection()
  File "/home/mstfrs/Desktop/ozerpan/apps/frappe/frappe/database/mariadb/database.py", line 116, in create_connection
    return pymysql.connect(**self.get_connection_settings())
  File "/home/mstfrs/Desktop/ozerpan/env/lib/python3.10/site-packages/pymysql/connections.py", line 361, in __init__
    self.connect()
  File "/home/mstfrs/Desktop/ozerpan/env/lib/python3.10/site-packages/pymysql/connections.py", line 669, in connect
    self._request_authentication()
  File "/home/mstfrs/Desktop/ozerpan/env/lib/python3.10/site-packages/pymysql/connections.py", line 957, in _request_authentication
    auth_packet = self._read_packet()
  File "/home/mstfrs/Desktop/ozerpan/env/lib/python3.10/site-packages/pymysql/connections.py", line 775, in _read_packet
    packet.raise_for_error()
  File "/home/mstfrs/Desktop/ozerpan/env/lib/python3.10/site-packages/pymysql/protocol.py", line 219, in raise_for_error
    err.raise_mysql_exception(self._data)
  File "/home/mstfrs/Desktop/ozerpan/env/lib/python3.10/site-packages/pymysql/err.py", line 150, in raise_mysql_exception
    raise errorclass(errno, errval)
pymysql.err.OperationalError: (1045, "Access denied for user '_c85c2ca7b22cd0b1'@'localhost' (using password: YES)")
2024-10-08 12:20:00,945 ERROR scheduler Exception in Enqueue Events for Site ozerpan.local
Traceback (most recent call last):
  File "/home/mstfrs/Desktop/ozerpan/apps/frappe/frappe/utils/scheduler.py", line 106, in enqueue_events_for_site
    if is_scheduler_inactive():
  File "/home/mstfrs/Desktop/ozerpan/apps/frappe/frappe/utils/scheduler.py", line 150, in is_scheduler_inactive
    if is_scheduler_disabled(verbose=verbose):
  File "/home/mstfrs/Desktop/ozerpan/apps/frappe/frappe/utils/scheduler.py", line 163, in is_scheduler_disabled
    frappe.db.get_single_value("System Settings", "enable_scheduler")
  File "/home/mstfrs/Desktop/ozerpan/apps/frappe/frappe/database/database.py", line 846, in get_single_value
    ).run()
  File "/home/mstfrs/Desktop/ozerpan/apps/frappe/frappe/query_builder/utils.py", line 84, in execute_query
    result = frappe.db.sql(query, params, *args, **kwargs)  # nosemgrep
  File "/home/mstfrs/Desktop/ozerpan/apps/frappe/frappe/database/database.py", line 213, in sql
    self.connect()
  File "/home/mstfrs/Desktop/ozerpan/apps/frappe/frappe/database/database.py", line 118, in connect
    self._conn: "MariadbConnection" | "PostgresConnection" = self.get_connection()
  File "/home/mstfrs/Desktop/ozerpan/apps/frappe/frappe/database/mariadb/database.py", line 107, in get_connection
    conn = self._get_connection()
  File "/home/mstfrs/Desktop/ozerpan/apps/frappe/frappe/database/mariadb/database.py", line 113, in _get_connection
    return self.create_connection()
  File "/home/mstfrs/Desktop/ozerpan/apps/frappe/frappe/database/mariadb/database.py", line 116, in create_connection
    return pymysql.connect(**self.get_connection_settings())
  File "/home/mstfrs/Desktop/ozerpan/env/lib/python3.10/site-packages/pymysql/connections.py", line 361, in __init__
    self.connect()
  File "/home/mstfrs/Desktop/ozerpan/env/lib/python3.10/site-packages/pymysql/connections.py", line 669, in connect
    self._request_authentication()
  File "/home/mstfrs/Desktop/ozerpan/env/lib/python3.10/site-packages/pymysql/connections.py", line 957, in _request_authentication
    auth_packet = self._read_packet()
  File "/home/mstfrs/Desktop/ozerpan/env/lib/python3.10/site-packages/pymysql/connections.py", line 775, in _read_packet
    packet.raise_for_error()
  File "/home/mstfrs/Desktop/ozerpan/env/lib/python3.10/site-packages/pymysql/protocol.py", line 219, in raise_for_error
    err.raise_mysql_exception(self._data)
  File "/home/mstfrs/Desktop/ozerpan/env/lib/python3.10/site-packages/pymysql/err.py", line 150, in raise_mysql_exception
    raise errorclass(errno, errval)
pymysql.err.OperationalError: (1045, "Access denied for user '_c85c2ca7b22cd0b1'@'localhost' (using password: YES)")
2024-10-08 12:24:00,638 ERROR scheduler Exception in Enqueue Events for Site ozerpan.local
Traceback (most recent call last):
  File "/home/mstfrs/Desktop/ozerpan/apps/frappe/frappe/utils/scheduler.py", line 106, in enqueue_events_for_site
    if is_scheduler_inactive():
  File "/home/mstfrs/Desktop/ozerpan/apps/frappe/frappe/utils/scheduler.py", line 150, in is_scheduler_inactive
    if is_scheduler_disabled(verbose=verbose):
  File "/home/mstfrs/Desktop/ozerpan/apps/frappe/frappe/utils/scheduler.py", line 163, in is_scheduler_disabled
    frappe.db.get_single_value("System Settings", "enable_scheduler")
  File "/home/mstfrs/Desktop/ozerpan/apps/frappe/frappe/database/database.py", line 846, in get_single_value
    ).run()
  File "/home/mstfrs/Desktop/ozerpan/apps/frappe/frappe/query_builder/utils.py", line 84, in execute_query
    result = frappe.db.sql(query, params, *args, **kwargs)  # nosemgrep
  File "/home/mstfrs/Desktop/ozerpan/apps/frappe/frappe/database/database.py", line 213, in sql
    self.connect()
  File "/home/mstfrs/Desktop/ozerpan/apps/frappe/frappe/database/database.py", line 118, in connect
    self._conn: "MariadbConnection" | "PostgresConnection" = self.get_connection()
  File "/home/mstfrs/Desktop/ozerpan/apps/frappe/frappe/database/mariadb/database.py", line 107, in get_connection
    conn = self._get_connection()
  File "/home/mstfrs/Desktop/ozerpan/apps/frappe/frappe/database/mariadb/database.py", line 113, in _get_connection
    return self.create_connection()
  File "/home/mstfrs/Desktop/ozerpan/apps/frappe/frappe/database/mariadb/database.py", line 116, in create_connection
    return pymysql.connect(**self.get_connection_settings())
  File "/home/mstfrs/Desktop/ozerpan/env/lib/python3.10/site-packages/pymysql/connections.py", line 361, in __init__
    self.connect()
  File "/home/mstfrs/Desktop/ozerpan/env/lib/python3.10/site-packages/pymysql/connections.py", line 669, in connect
    self._request_authentication()
  File "/home/mstfrs/Desktop/ozerpan/env/lib/python3.10/site-packages/pymysql/connections.py", line 957, in _request_authentication
    auth_packet = self._read_packet()
  File "/home/mstfrs/Desktop/ozerpan/env/lib/python3.10/site-packages/pymysql/connections.py", line 775, in _read_packet
    packet.raise_for_error()
  File "/home/mstfrs/Desktop/ozerpan/env/lib/python3.10/site-packages/pymysql/protocol.py", line 219, in raise_for_error
    err.raise_mysql_exception(self._data)
  File "/home/mstfrs/Desktop/ozerpan/env/lib/python3.10/site-packages/pymysql/err.py", line 150, in raise_mysql_exception
    raise errorclass(errno, errval)
pymysql.err.OperationalError: (1045, "Access denied for user '_c85c2ca7b22cd0b1'@'localhost' (using password: YES)")
2024-10-08 12:28:01,194 ERROR scheduler Exception in Enqueue Events for Site ozerpan.local
Traceback (most recent call last):
  File "/home/mstfrs/Desktop/ozerpan/apps/frappe/frappe/utils/scheduler.py", line 106, in enqueue_events_for_site
    if is_scheduler_inactive():
  File "/home/mstfrs/Desktop/ozerpan/apps/frappe/frappe/utils/scheduler.py", line 150, in is_scheduler_inactive
    if is_scheduler_disabled(verbose=verbose):
  File "/home/mstfrs/Desktop/ozerpan/apps/frappe/frappe/utils/scheduler.py", line 163, in is_scheduler_disabled
    frappe.db.get_single_value("System Settings", "enable_scheduler")
  File "/home/mstfrs/Desktop/ozerpan/apps/frappe/frappe/database/database.py", line 846, in get_single_value
    ).run()
  File "/home/mstfrs/Desktop/ozerpan/apps/frappe/frappe/query_builder/utils.py", line 84, in execute_query
    result = frappe.db.sql(query, params, *args, **kwargs)  # nosemgrep
  File "/home/mstfrs/Desktop/ozerpan/apps/frappe/frappe/database/database.py", line 213, in sql
    self.connect()
  File "/home/mstfrs/Desktop/ozerpan/apps/frappe/frappe/database/database.py", line 118, in connect
    self._conn: "MariadbConnection" | "PostgresConnection" = self.get_connection()
  File "/home/mstfrs/Desktop/ozerpan/apps/frappe/frappe/database/mariadb/database.py", line 107, in get_connection
    conn = self._get_connection()
  File "/home/mstfrs/Desktop/ozerpan/apps/frappe/frappe/database/mariadb/database.py", line 113, in _get_connection
    return self.create_connection()
  File "/home/mstfrs/Desktop/ozerpan/apps/frappe/frappe/database/mariadb/database.py", line 116, in create_connection
    return pymysql.connect(**self.get_connection_settings())
  File "/home/mstfrs/Desktop/ozerpan/env/lib/python3.10/site-packages/pymysql/connections.py", line 361, in __init__
    self.connect()
  File "/home/mstfrs/Desktop/ozerpan/env/lib/python3.10/site-packages/pymysql/connections.py", line 669, in connect
    self._request_authentication()
  File "/home/mstfrs/Desktop/ozerpan/env/lib/python3.10/site-packages/pymysql/connections.py", line 957, in _request_authentication
    auth_packet = self._read_packet()
  File "/home/mstfrs/Desktop/ozerpan/env/lib/python3.10/site-packages/pymysql/connections.py", line 775, in _read_packet
    packet.raise_for_error()
  File "/home/mstfrs/Desktop/ozerpan/env/lib/python3.10/site-packages/pymysql/protocol.py", line 219, in raise_for_error
    err.raise_mysql_exception(self._data)
  File "/home/mstfrs/Desktop/ozerpan/env/lib/python3.10/site-packages/pymysql/err.py", line 150, in raise_mysql_exception
    raise errorclass(errno, errval)
pymysql.err.OperationalError: (1045, "Access denied for user '_c85c2ca7b22cd0b1'@'localhost' (using password: YES)")
2024-10-08 12:32:00,670 ERROR scheduler Exception in Enqueue Events for Site ozerpan.local
Traceback (most recent call last):
  File "/home/mstfrs/Desktop/ozerpan/apps/frappe/frappe/utils/scheduler.py", line 106, in enqueue_events_for_site
    if is_scheduler_inactive():
  File "/home/mstfrs/Desktop/ozerpan/apps/frappe/frappe/utils/scheduler.py", line 150, in is_scheduler_inactive
    if is_scheduler_disabled(verbose=verbose):
  File "/home/mstfrs/Desktop/ozerpan/apps/frappe/frappe/utils/scheduler.py", line 163, in is_scheduler_disabled
    frappe.db.get_single_value("System Settings", "enable_scheduler")
  File "/home/mstfrs/Desktop/ozerpan/apps/frappe/frappe/database/database.py", line 846, in get_single_value
    ).run()
  File "/home/mstfrs/Desktop/ozerpan/apps/frappe/frappe/query_builder/utils.py", line 84, in execute_query
    result = frappe.db.sql(query, params, *args, **kwargs)  # nosemgrep
  File "/home/mstfrs/Desktop/ozerpan/apps/frappe/frappe/database/database.py", line 213, in sql
    self.connect()
  File "/home/mstfrs/Desktop/ozerpan/apps/frappe/frappe/database/database.py", line 118, in connect
    self._conn: "MariadbConnection" | "PostgresConnection" = self.get_connection()
  File "/home/mstfrs/Desktop/ozerpan/apps/frappe/frappe/database/mariadb/database.py", line 107, in get_connection
    conn = self._get_connection()
  File "/home/mstfrs/Desktop/ozerpan/apps/frappe/frappe/database/mariadb/database.py", line 113, in _get_connection
    return self.create_connection()
  File "/home/mstfrs/Desktop/ozerpan/apps/frappe/frappe/database/mariadb/database.py", line 116, in create_connection
    return pymysql.connect(**self.get_connection_settings())
  File "/home/mstfrs/Desktop/ozerpan/env/lib/python3.10/site-packages/pymysql/connections.py", line 361, in __init__
    self.connect()
  File "/home/mstfrs/Desktop/ozerpan/env/lib/python3.10/site-packages/pymysql/connections.py", line 669, in connect
    self._request_authentication()
  File "/home/mstfrs/Desktop/ozerpan/env/lib/python3.10/site-packages/pymysql/connections.py", line 957, in _request_authentication
    auth_packet = self._read_packet()
  File "/home/mstfrs/Desktop/ozerpan/env/lib/python3.10/site-packages/pymysql/connections.py", line 775, in _read_packet
    packet.raise_for_error()
  File "/home/mstfrs/Desktop/ozerpan/env/lib/python3.10/site-packages/pymysql/protocol.py", line 219, in raise_for_error
    err.raise_mysql_exception(self._data)
  File "/home/mstfrs/Desktop/ozerpan/env/lib/python3.10/site-packages/pymysql/err.py", line 150, in raise_mysql_exception
    raise errorclass(errno, errval)
pymysql.err.OperationalError: (1045, "Access denied for user '_c85c2ca7b22cd0b1'@'localhost' (using password: YES)")
2024-10-08 12:36:00,773 ERROR scheduler Exception in Enqueue Events for Site ozerpan.local
Traceback (most recent call last):
  File "/home/mstfrs/Desktop/ozerpan/apps/frappe/frappe/utils/scheduler.py", line 106, in enqueue_events_for_site
    if is_scheduler_inactive():
  File "/home/mstfrs/Desktop/ozerpan/apps/frappe/frappe/utils/scheduler.py", line 150, in is_scheduler_inactive
    if is_scheduler_disabled(verbose=verbose):
  File "/home/mstfrs/Desktop/ozerpan/apps/frappe/frappe/utils/scheduler.py", line 163, in is_scheduler_disabled
    frappe.db.get_single_value("System Settings", "enable_scheduler")
  File "/home/mstfrs/Desktop/ozerpan/apps/frappe/frappe/database/database.py", line 846, in get_single_value
    ).run()
  File "/home/mstfrs/Desktop/ozerpan/apps/frappe/frappe/query_builder/utils.py", line 84, in execute_query
    result = frappe.db.sql(query, params, *args, **kwargs)  # nosemgrep
  File "/home/mstfrs/Desktop/ozerpan/apps/frappe/frappe/database/database.py", line 213, in sql
    self.connect()
  File "/home/mstfrs/Desktop/ozerpan/apps/frappe/frappe/database/database.py", line 118, in connect
    self._conn: "MariadbConnection" | "PostgresConnection" = self.get_connection()
  File "/home/mstfrs/Desktop/ozerpan/apps/frappe/frappe/database/mariadb/database.py", line 107, in get_connection
    conn = self._get_connection()
  File "/home/mstfrs/Desktop/ozerpan/apps/frappe/frappe/database/mariadb/database.py", line 113, in _get_connection
    return self.create_connection()
  File "/home/mstfrs/Desktop/ozerpan/apps/frappe/frappe/database/mariadb/database.py", line 116, in create_connection
    return pymysql.connect(**self.get_connection_settings())
  File "/home/mstfrs/Desktop/ozerpan/env/lib/python3.10/site-packages/pymysql/connections.py", line 361, in __init__
    self.connect()
  File "/home/mstfrs/Desktop/ozerpan/env/lib/python3.10/site-packages/pymysql/connections.py", line 669, in connect
    self._request_authentication()
  File "/home/mstfrs/Desktop/ozerpan/env/lib/python3.10/site-packages/pymysql/connections.py", line 957, in _request_authentication
    auth_packet = self._read_packet()
  File "/home/mstfrs/Desktop/ozerpan/env/lib/python3.10/site-packages/pymysql/connections.py", line 775, in _read_packet
    packet.raise_for_error()
  File "/home/mstfrs/Desktop/ozerpan/env/lib/python3.10/site-packages/pymysql/protocol.py", line 219, in raise_for_error
    err.raise_mysql_exception(self._data)
  File "/home/mstfrs/Desktop/ozerpan/env/lib/python3.10/site-packages/pymysql/err.py", line 150, in raise_mysql_exception
    raise errorclass(errno, errval)
pymysql.err.OperationalError: (1045, "Access denied for user '_c85c2ca7b22cd0b1'@'localhost' (using password: YES)")
2024-10-08 12:40:00,272 ERROR scheduler Exception in Enqueue Events for Site ozerpan.local
Traceback (most recent call last):
  File "/home/mstfrs/Desktop/ozerpan/apps/frappe/frappe/utils/scheduler.py", line 106, in enqueue_events_for_site
    if is_scheduler_inactive():
  File "/home/mstfrs/Desktop/ozerpan/apps/frappe/frappe/utils/scheduler.py", line 150, in is_scheduler_inactive
    if is_scheduler_disabled(verbose=verbose):
  File "/home/mstfrs/Desktop/ozerpan/apps/frappe/frappe/utils/scheduler.py", line 163, in is_scheduler_disabled
    frappe.db.get_single_value("System Settings", "enable_scheduler")
  File "/home/mstfrs/Desktop/ozerpan/apps/frappe/frappe/database/database.py", line 846, in get_single_value
    ).run()
  File "/home/mstfrs/Desktop/ozerpan/apps/frappe/frappe/query_builder/utils.py", line 84, in execute_query
    result = frappe.db.sql(query, params, *args, **kwargs)  # nosemgrep
  File "/home/mstfrs/Desktop/ozerpan/apps/frappe/frappe/database/database.py", line 213, in sql
    self.connect()
  File "/home/mstfrs/Desktop/ozerpan/apps/frappe/frappe/database/database.py", line 118, in connect
    self._conn: "MariadbConnection" | "PostgresConnection" = self.get_connection()
  File "/home/mstfrs/Desktop/ozerpan/apps/frappe/frappe/database/mariadb/database.py", line 107, in get_connection
    conn = self._get_connection()
  File "/home/mstfrs/Desktop/ozerpan/apps/frappe/frappe/database/mariadb/database.py", line 113, in _get_connection
    return self.create_connection()
  File "/home/mstfrs/Desktop/ozerpan/apps/frappe/frappe/database/mariadb/database.py", line 116, in create_connection
    return pymysql.connect(**self.get_connection_settings())
  File "/home/mstfrs/Desktop/ozerpan/env/lib/python3.10/site-packages/pymysql/connections.py", line 361, in __init__
    self.connect()
  File "/home/mstfrs/Desktop/ozerpan/env/lib/python3.10/site-packages/pymysql/connections.py", line 669, in connect
    self._request_authentication()
  File "/home/mstfrs/Desktop/ozerpan/env/lib/python3.10/site-packages/pymysql/connections.py", line 957, in _request_authentication
    auth_packet = self._read_packet()
  File "/home/mstfrs/Desktop/ozerpan/env/lib/python3.10/site-packages/pymysql/connections.py", line 775, in _read_packet
    packet.raise_for_error()
  File "/home/mstfrs/Desktop/ozerpan/env/lib/python3.10/site-packages/pymysql/protocol.py", line 219, in raise_for_error
    err.raise_mysql_exception(self._data)
  File "/home/mstfrs/Desktop/ozerpan/env/lib/python3.10/site-packages/pymysql/err.py", line 150, in raise_mysql_exception
    raise errorclass(errno, errval)
pymysql.err.OperationalError: (1045, "Access denied for user '_c85c2ca7b22cd0b1'@'localhost' (using password: YES)")
2024-10-08 12:44:00,582 ERROR scheduler Exception in Enqueue Events for Site ozerpan.local
Traceback (most recent call last):
  File "/home/mstfrs/Desktop/ozerpan/apps/frappe/frappe/utils/scheduler.py", line 106, in enqueue_events_for_site
    if is_scheduler_inactive():
  File "/home/mstfrs/Desktop/ozerpan/apps/frappe/frappe/utils/scheduler.py", line 150, in is_scheduler_inactive
    if is_scheduler_disabled(verbose=verbose):
  File "/home/mstfrs/Desktop/ozerpan/apps/frappe/frappe/utils/scheduler.py", line 163, in is_scheduler_disabled
    frappe.db.get_single_value("System Settings", "enable_scheduler")
  File "/home/mstfrs/Desktop/ozerpan/apps/frappe/frappe/database/database.py", line 846, in get_single_value
    ).run()
  File "/home/mstfrs/Desktop/ozerpan/apps/frappe/frappe/query_builder/utils.py", line 84, in execute_query
    result = frappe.db.sql(query, params, *args, **kwargs)  # nosemgrep
  File "/home/mstfrs/Desktop/ozerpan/apps/frappe/frappe/database/database.py", line 213, in sql
    self.connect()
  File "/home/mstfrs/Desktop/ozerpan/apps/frappe/frappe/database/database.py", line 118, in connect
    self._conn: "MariadbConnection" | "PostgresConnection" = self.get_connection()
  File "/home/mstfrs/Desktop/ozerpan/apps/frappe/frappe/database/mariadb/database.py", line 107, in get_connection
    conn = self._get_connection()
  File "/home/mstfrs/Desktop/ozerpan/apps/frappe/frappe/database/mariadb/database.py", line 113, in _get_connection
    return self.create_connection()
  File "/home/mstfrs/Desktop/ozerpan/apps/frappe/frappe/database/mariadb/database.py", line 116, in create_connection
    return pymysql.connect(**self.get_connection_settings())
  File "/home/mstfrs/Desktop/ozerpan/env/lib/python3.10/site-packages/pymysql/connections.py", line 361, in __init__
    self.connect()
  File "/home/mstfrs/Desktop/ozerpan/env/lib/python3.10/site-packages/pymysql/connections.py", line 669, in connect
    self._request_authentication()
  File "/home/mstfrs/Desktop/ozerpan/env/lib/python3.10/site-packages/pymysql/connections.py", line 957, in _request_authentication
    auth_packet = self._read_packet()
  File "/home/mstfrs/Desktop/ozerpan/env/lib/python3.10/site-packages/pymysql/connections.py", line 775, in _read_packet
    packet.raise_for_error()
  File "/home/mstfrs/Desktop/ozerpan/env/lib/python3.10/site-packages/pymysql/protocol.py", line 219, in raise_for_error
    err.raise_mysql_exception(self._data)
  File "/home/mstfrs/Desktop/ozerpan/env/lib/python3.10/site-packages/pymysql/err.py", line 150, in raise_mysql_exception
    raise errorclass(errno, errval)
pymysql.err.OperationalError: (1045, "Access denied for user '_c85c2ca7b22cd0b1'@'localhost' (using password: YES)")
2024-10-08 12:48:01,292 ERROR scheduler Exception in Enqueue Events for Site ozerpan.local
Traceback (most recent call last):
  File "/home/mstfrs/Desktop/ozerpan/apps/frappe/frappe/utils/scheduler.py", line 106, in enqueue_events_for_site
    if is_scheduler_inactive():
  File "/home/mstfrs/Desktop/ozerpan/apps/frappe/frappe/utils/scheduler.py", line 150, in is_scheduler_inactive
    if is_scheduler_disabled(verbose=verbose):
  File "/home/mstfrs/Desktop/ozerpan/apps/frappe/frappe/utils/scheduler.py", line 163, in is_scheduler_disabled
    frappe.db.get_single_value("System Settings", "enable_scheduler")
  File "/home/mstfrs/Desktop/ozerpan/apps/frappe/frappe/database/database.py", line 846, in get_single_value
    ).run()
  File "/home/mstfrs/Desktop/ozerpan/apps/frappe/frappe/query_builder/utils.py", line 84, in execute_query
    result = frappe.db.sql(query, params, *args, **kwargs)  # nosemgrep
  File "/home/mstfrs/Desktop/ozerpan/apps/frappe/frappe/database/database.py", line 213, in sql
    self.connect()
  File "/home/mstfrs/Desktop/ozerpan/apps/frappe/frappe/database/database.py", line 118, in connect
    self._conn: "MariadbConnection" | "PostgresConnection" = self.get_connection()
  File "/home/mstfrs/Desktop/ozerpan/apps/frappe/frappe/database/mariadb/database.py", line 107, in get_connection
    conn = self._get_connection()
  File "/home/mstfrs/Desktop/ozerpan/apps/frappe/frappe/database/mariadb/database.py", line 113, in _get_connection
    return self.create_connection()
  File "/home/mstfrs/Desktop/ozerpan/apps/frappe/frappe/database/mariadb/database.py", line 116, in create_connection
    return pymysql.connect(**self.get_connection_settings())
  File "/home/mstfrs/Desktop/ozerpan/env/lib/python3.10/site-packages/pymysql/connections.py", line 361, in __init__
    self.connect()
  File "/home/mstfrs/Desktop/ozerpan/env/lib/python3.10/site-packages/pymysql/connections.py", line 669, in connect
    self._request_authentication()
  File "/home/mstfrs/Desktop/ozerpan/env/lib/python3.10/site-packages/pymysql/connections.py", line 957, in _request_authentication
    auth_packet = self._read_packet()
  File "/home/mstfrs/Desktop/ozerpan/env/lib/python3.10/site-packages/pymysql/connections.py", line 775, in _read_packet
    packet.raise_for_error()
  File "/home/mstfrs/Desktop/ozerpan/env/lib/python3.10/site-packages/pymysql/protocol.py", line 219, in raise_for_error
    err.raise_mysql_exception(self._data)
  File "/home/mstfrs/Desktop/ozerpan/env/lib/python3.10/site-packages/pymysql/err.py", line 150, in raise_mysql_exception
    raise errorclass(errno, errval)
pymysql.err.OperationalError: (1045, "Access denied for user '_c85c2ca7b22cd0b1'@'localhost' (using password: YES)")
2024-10-08 12:52:00,396 ERROR scheduler Exception in Enqueue Events for Site ozerpan.local
Traceback (most recent call last):
  File "/home/mstfrs/Desktop/ozerpan/apps/frappe/frappe/utils/scheduler.py", line 106, in enqueue_events_for_site
    if is_scheduler_inactive():
  File "/home/mstfrs/Desktop/ozerpan/apps/frappe/frappe/utils/scheduler.py", line 150, in is_scheduler_inactive
    if is_scheduler_disabled(verbose=verbose):
  File "/home/mstfrs/Desktop/ozerpan/apps/frappe/frappe/utils/scheduler.py", line 163, in is_scheduler_disabled
    frappe.db.get_single_value("System Settings", "enable_scheduler")
  File "/home/mstfrs/Desktop/ozerpan/apps/frappe/frappe/database/database.py", line 846, in get_single_value
    ).run()
  File "/home/mstfrs/Desktop/ozerpan/apps/frappe/frappe/query_builder/utils.py", line 84, in execute_query
    result = frappe.db.sql(query, params, *args, **kwargs)  # nosemgrep
  File "/home/mstfrs/Desktop/ozerpan/apps/frappe/frappe/database/database.py", line 213, in sql
    self.connect()
  File "/home/mstfrs/Desktop/ozerpan/apps/frappe/frappe/database/database.py", line 118, in connect
    self._conn: "MariadbConnection" | "PostgresConnection" = self.get_connection()
  File "/home/mstfrs/Desktop/ozerpan/apps/frappe/frappe/database/mariadb/database.py", line 107, in get_connection
    conn = self._get_connection()
  File "/home/mstfrs/Desktop/ozerpan/apps/frappe/frappe/database/mariadb/database.py", line 113, in _get_connection
    return self.create_connection()
  File "/home/mstfrs/Desktop/ozerpan/apps/frappe/frappe/database/mariadb/database.py", line 116, in create_connection
    return pymysql.connect(**self.get_connection_settings())
  File "/home/mstfrs/Desktop/ozerpan/env/lib/python3.10/site-packages/pymysql/connections.py", line 361, in __init__
    self.connect()
  File "/home/mstfrs/Desktop/ozerpan/env/lib/python3.10/site-packages/pymysql/connections.py", line 669, in connect
    self._request_authentication()
  File "/home/mstfrs/Desktop/ozerpan/env/lib/python3.10/site-packages/pymysql/connections.py", line 957, in _request_authentication
    auth_packet = self._read_packet()
  File "/home/mstfrs/Desktop/ozerpan/env/lib/python3.10/site-packages/pymysql/connections.py", line 775, in _read_packet
    packet.raise_for_error()
  File "/home/mstfrs/Desktop/ozerpan/env/lib/python3.10/site-packages/pymysql/protocol.py", line 219, in raise_for_error
    err.raise_mysql_exception(self._data)
  File "/home/mstfrs/Desktop/ozerpan/env/lib/python3.10/site-packages/pymysql/err.py", line 150, in raise_mysql_exception
    raise errorclass(errno, errval)
pymysql.err.OperationalError: (1045, "Access denied for user '_c85c2ca7b22cd0b1'@'localhost' (using password: YES)")
2024-10-08 12:56:00,801 ERROR scheduler Exception in Enqueue Events for Site ozerpan.local
Traceback (most recent call last):
  File "/home/mstfrs/Desktop/ozerpan/apps/frappe/frappe/utils/scheduler.py", line 106, in enqueue_events_for_site
    if is_scheduler_inactive():
  File "/home/mstfrs/Desktop/ozerpan/apps/frappe/frappe/utils/scheduler.py", line 150, in is_scheduler_inactive
    if is_scheduler_disabled(verbose=verbose):
  File "/home/mstfrs/Desktop/ozerpan/apps/frappe/frappe/utils/scheduler.py", line 163, in is_scheduler_disabled
    frappe.db.get_single_value("System Settings", "enable_scheduler")
  File "/home/mstfrs/Desktop/ozerpan/apps/frappe/frappe/database/database.py", line 846, in get_single_value
    ).run()
  File "/home/mstfrs/Desktop/ozerpan/apps/frappe/frappe/query_builder/utils.py", line 84, in execute_query
    result = frappe.db.sql(query, params, *args, **kwargs)  # nosemgrep
  File "/home/mstfrs/Desktop/ozerpan/apps/frappe/frappe/database/database.py", line 213, in sql
    self.connect()
  File "/home/mstfrs/Desktop/ozerpan/apps/frappe/frappe/database/database.py", line 118, in connect
    self._conn: "MariadbConnection" | "PostgresConnection" = self.get_connection()
  File "/home/mstfrs/Desktop/ozerpan/apps/frappe/frappe/database/mariadb/database.py", line 107, in get_connection
    conn = self._get_connection()
  File "/home/mstfrs/Desktop/ozerpan/apps/frappe/frappe/database/mariadb/database.py", line 113, in _get_connection
    return self.create_connection()
  File "/home/mstfrs/Desktop/ozerpan/apps/frappe/frappe/database/mariadb/database.py", line 116, in create_connection
    return pymysql.connect(**self.get_connection_settings())
  File "/home/mstfrs/Desktop/ozerpan/env/lib/python3.10/site-packages/pymysql/connections.py", line 361, in __init__
    self.connect()
  File "/home/mstfrs/Desktop/ozerpan/env/lib/python3.10/site-packages/pymysql/connections.py", line 669, in connect
    self._request_authentication()
  File "/home/mstfrs/Desktop/ozerpan/env/lib/python3.10/site-packages/pymysql/connections.py", line 957, in _request_authentication
    auth_packet = self._read_packet()
  File "/home/mstfrs/Desktop/ozerpan/env/lib/python3.10/site-packages/pymysql/connections.py", line 775, in _read_packet
    packet.raise_for_error()
  File "/home/mstfrs/Desktop/ozerpan/env/lib/python3.10/site-packages/pymysql/protocol.py", line 219, in raise_for_error
    err.raise_mysql_exception(self._data)
  File "/home/mstfrs/Desktop/ozerpan/env/lib/python3.10/site-packages/pymysql/err.py", line 150, in raise_mysql_exception
    raise errorclass(errno, errval)
pymysql.err.OperationalError: (1045, "Access denied for user '_c85c2ca7b22cd0b1'@'localhost' (using password: YES)")
2024-10-08 13:00:00,192 ERROR scheduler Exception in Enqueue Events for Site ozerpan.local
Traceback (most recent call last):
  File "/home/mstfrs/Desktop/ozerpan/apps/frappe/frappe/utils/scheduler.py", line 106, in enqueue_events_for_site
    if is_scheduler_inactive():
  File "/home/mstfrs/Desktop/ozerpan/apps/frappe/frappe/utils/scheduler.py", line 150, in is_scheduler_inactive
    if is_scheduler_disabled(verbose=verbose):
  File "/home/mstfrs/Desktop/ozerpan/apps/frappe/frappe/utils/scheduler.py", line 163, in is_scheduler_disabled
    frappe.db.get_single_value("System Settings", "enable_scheduler")
  File "/home/mstfrs/Desktop/ozerpan/apps/frappe/frappe/database/database.py", line 846, in get_single_value
    ).run()
  File "/home/mstfrs/Desktop/ozerpan/apps/frappe/frappe/query_builder/utils.py", line 84, in execute_query
    result = frappe.db.sql(query, params, *args, **kwargs)  # nosemgrep
  File "/home/mstfrs/Desktop/ozerpan/apps/frappe/frappe/database/database.py", line 213, in sql
    self.connect()
  File "/home/mstfrs/Desktop/ozerpan/apps/frappe/frappe/database/database.py", line 118, in connect
    self._conn: "MariadbConnection" | "PostgresConnection" = self.get_connection()
  File "/home/mstfrs/Desktop/ozerpan/apps/frappe/frappe/database/mariadb/database.py", line 107, in get_connection
    conn = self._get_connection()
  File "/home/mstfrs/Desktop/ozerpan/apps/frappe/frappe/database/mariadb/database.py", line 113, in _get_connection
    return self.create_connection()
  File "/home/mstfrs/Desktop/ozerpan/apps/frappe/frappe/database/mariadb/database.py", line 116, in create_connection
    return pymysql.connect(**self.get_connection_settings())
  File "/home/mstfrs/Desktop/ozerpan/env/lib/python3.10/site-packages/pymysql/connections.py", line 361, in __init__
    self.connect()
  File "/home/mstfrs/Desktop/ozerpan/env/lib/python3.10/site-packages/pymysql/connections.py", line 669, in connect
    self._request_authentication()
  File "/home/mstfrs/Desktop/ozerpan/env/lib/python3.10/site-packages/pymysql/connections.py", line 957, in _request_authentication
    auth_packet = self._read_packet()
  File "/home/mstfrs/Desktop/ozerpan/env/lib/python3.10/site-packages/pymysql/connections.py", line 775, in _read_packet
    packet.raise_for_error()
  File "/home/mstfrs/Desktop/ozerpan/env/lib/python3.10/site-packages/pymysql/protocol.py", line 219, in raise_for_error
    err.raise_mysql_exception(self._data)
  File "/home/mstfrs/Desktop/ozerpan/env/lib/python3.10/site-packages/pymysql/err.py", line 150, in raise_mysql_exception
    raise errorclass(errno, errval)
pymysql.err.OperationalError: (1045, "Access denied for user '_c85c2ca7b22cd0b1'@'localhost' (using password: YES)")
2024-10-08 13:04:00,994 ERROR scheduler Exception in Enqueue Events for Site ozerpan.local
Traceback (most recent call last):
  File "/home/mstfrs/Desktop/ozerpan/apps/frappe/frappe/utils/scheduler.py", line 106, in enqueue_events_for_site
    if is_scheduler_inactive():
  File "/home/mstfrs/Desktop/ozerpan/apps/frappe/frappe/utils/scheduler.py", line 150, in is_scheduler_inactive
    if is_scheduler_disabled(verbose=verbose):
  File "/home/mstfrs/Desktop/ozerpan/apps/frappe/frappe/utils/scheduler.py", line 163, in is_scheduler_disabled
    frappe.db.get_single_value("System Settings", "enable_scheduler")
  File "/home/mstfrs/Desktop/ozerpan/apps/frappe/frappe/database/database.py", line 846, in get_single_value
    ).run()
  File "/home/mstfrs/Desktop/ozerpan/apps/frappe/frappe/query_builder/utils.py", line 84, in execute_query
    result = frappe.db.sql(query, params, *args, **kwargs)  # nosemgrep
  File "/home/mstfrs/Desktop/ozerpan/apps/frappe/frappe/database/database.py", line 213, in sql
    self.connect()
  File "/home/mstfrs/Desktop/ozerpan/apps/frappe/frappe/database/database.py", line 118, in connect
    self._conn: "MariadbConnection" | "PostgresConnection" = self.get_connection()
  File "/home/mstfrs/Desktop/ozerpan/apps/frappe/frappe/database/mariadb/database.py", line 107, in get_connection
    conn = self._get_connection()
  File "/home/mstfrs/Desktop/ozerpan/apps/frappe/frappe/database/mariadb/database.py", line 113, in _get_connection
    return self.create_connection()
  File "/home/mstfrs/Desktop/ozerpan/apps/frappe/frappe/database/mariadb/database.py", line 116, in create_connection
    return pymysql.connect(**self.get_connection_settings())
  File "/home/mstfrs/Desktop/ozerpan/env/lib/python3.10/site-packages/pymysql/connections.py", line 361, in __init__
    self.connect()
  File "/home/mstfrs/Desktop/ozerpan/env/lib/python3.10/site-packages/pymysql/connections.py", line 669, in connect
    self._request_authentication()
  File "/home/mstfrs/Desktop/ozerpan/env/lib/python3.10/site-packages/pymysql/connections.py", line 957, in _request_authentication
    auth_packet = self._read_packet()
  File "/home/mstfrs/Desktop/ozerpan/env/lib/python3.10/site-packages/pymysql/connections.py", line 775, in _read_packet
    packet.raise_for_error()
  File "/home/mstfrs/Desktop/ozerpan/env/lib/python3.10/site-packages/pymysql/protocol.py", line 219, in raise_for_error
    err.raise_mysql_exception(self._data)
  File "/home/mstfrs/Desktop/ozerpan/env/lib/python3.10/site-packages/pymysql/err.py", line 150, in raise_mysql_exception
    raise errorclass(errno, errval)
pymysql.err.OperationalError: (1045, "Access denied for user '_c85c2ca7b22cd0b1'@'localhost' (using password: YES)")
2024-10-08 13:08:01,447 ERROR scheduler Exception in Enqueue Events for Site ozerpan.local
Traceback (most recent call last):
  File "/home/mstfrs/Desktop/ozerpan/apps/frappe/frappe/utils/scheduler.py", line 106, in enqueue_events_for_site
    if is_scheduler_inactive():
  File "/home/mstfrs/Desktop/ozerpan/apps/frappe/frappe/utils/scheduler.py", line 150, in is_scheduler_inactive
    if is_scheduler_disabled(verbose=verbose):
  File "/home/mstfrs/Desktop/ozerpan/apps/frappe/frappe/utils/scheduler.py", line 163, in is_scheduler_disabled
    frappe.db.get_single_value("System Settings", "enable_scheduler")
  File "/home/mstfrs/Desktop/ozerpan/apps/frappe/frappe/database/database.py", line 846, in get_single_value
    ).run()
  File "/home/mstfrs/Desktop/ozerpan/apps/frappe/frappe/query_builder/utils.py", line 84, in execute_query
    result = frappe.db.sql(query, params, *args, **kwargs)  # nosemgrep
  File "/home/mstfrs/Desktop/ozerpan/apps/frappe/frappe/database/database.py", line 213, in sql
    self.connect()
  File "/home/mstfrs/Desktop/ozerpan/apps/frappe/frappe/database/database.py", line 118, in connect
    self._conn: "MariadbConnection" | "PostgresConnection" = self.get_connection()
  File "/home/mstfrs/Desktop/ozerpan/apps/frappe/frappe/database/mariadb/database.py", line 107, in get_connection
    conn = self._get_connection()
  File "/home/mstfrs/Desktop/ozerpan/apps/frappe/frappe/database/mariadb/database.py", line 113, in _get_connection
    return self.create_connection()
  File "/home/mstfrs/Desktop/ozerpan/apps/frappe/frappe/database/mariadb/database.py", line 116, in create_connection
    return pymysql.connect(**self.get_connection_settings())
  File "/home/mstfrs/Desktop/ozerpan/env/lib/python3.10/site-packages/pymysql/connections.py", line 361, in __init__
    self.connect()
  File "/home/mstfrs/Desktop/ozerpan/env/lib/python3.10/site-packages/pymysql/connections.py", line 669, in connect
    self._request_authentication()
  File "/home/mstfrs/Desktop/ozerpan/env/lib/python3.10/site-packages/pymysql/connections.py", line 957, in _request_authentication
    auth_packet = self._read_packet()
  File "/home/mstfrs/Desktop/ozerpan/env/lib/python3.10/site-packages/pymysql/connections.py", line 775, in _read_packet
    packet.raise_for_error()
  File "/home/mstfrs/Desktop/ozerpan/env/lib/python3.10/site-packages/pymysql/protocol.py", line 219, in raise_for_error
    err.raise_mysql_exception(self._data)
  File "/home/mstfrs/Desktop/ozerpan/env/lib/python3.10/site-packages/pymysql/err.py", line 150, in raise_mysql_exception
    raise errorclass(errno, errval)
pymysql.err.OperationalError: (1045, "Access denied for user '_c85c2ca7b22cd0b1'@'localhost' (using password: YES)")
2024-10-08 13:12:00,981 ERROR scheduler Exception in Enqueue Events for Site ozerpan.local
Traceback (most recent call last):
  File "/home/mstfrs/Desktop/ozerpan/apps/frappe/frappe/utils/scheduler.py", line 106, in enqueue_events_for_site
    if is_scheduler_inactive():
  File "/home/mstfrs/Desktop/ozerpan/apps/frappe/frappe/utils/scheduler.py", line 150, in is_scheduler_inactive
    if is_scheduler_disabled(verbose=verbose):
  File "/home/mstfrs/Desktop/ozerpan/apps/frappe/frappe/utils/scheduler.py", line 163, in is_scheduler_disabled
    frappe.db.get_single_value("System Settings", "enable_scheduler")
  File "/home/mstfrs/Desktop/ozerpan/apps/frappe/frappe/database/database.py", line 846, in get_single_value
    ).run()
  File "/home/mstfrs/Desktop/ozerpan/apps/frappe/frappe/query_builder/utils.py", line 84, in execute_query
    result = frappe.db.sql(query, params, *args, **kwargs)  # nosemgrep
  File "/home/mstfrs/Desktop/ozerpan/apps/frappe/frappe/database/database.py", line 213, in sql
    self.connect()
  File "/home/mstfrs/Desktop/ozerpan/apps/frappe/frappe/database/database.py", line 118, in connect
    self._conn: "MariadbConnection" | "PostgresConnection" = self.get_connection()
  File "/home/mstfrs/Desktop/ozerpan/apps/frappe/frappe/database/mariadb/database.py", line 107, in get_connection
    conn = self._get_connection()
  File "/home/mstfrs/Desktop/ozerpan/apps/frappe/frappe/database/mariadb/database.py", line 113, in _get_connection
    return self.create_connection()
  File "/home/mstfrs/Desktop/ozerpan/apps/frappe/frappe/database/mariadb/database.py", line 116, in create_connection
    return pymysql.connect(**self.get_connection_settings())
  File "/home/mstfrs/Desktop/ozerpan/env/lib/python3.10/site-packages/pymysql/connections.py", line 361, in __init__
    self.connect()
  File "/home/mstfrs/Desktop/ozerpan/env/lib/python3.10/site-packages/pymysql/connections.py", line 669, in connect
    self._request_authentication()
  File "/home/mstfrs/Desktop/ozerpan/env/lib/python3.10/site-packages/pymysql/connections.py", line 957, in _request_authentication
    auth_packet = self._read_packet()
  File "/home/mstfrs/Desktop/ozerpan/env/lib/python3.10/site-packages/pymysql/connections.py", line 775, in _read_packet
    packet.raise_for_error()
  File "/home/mstfrs/Desktop/ozerpan/env/lib/python3.10/site-packages/pymysql/protocol.py", line 219, in raise_for_error
    err.raise_mysql_exception(self._data)
  File "/home/mstfrs/Desktop/ozerpan/env/lib/python3.10/site-packages/pymysql/err.py", line 150, in raise_mysql_exception
    raise errorclass(errno, errval)
pymysql.err.OperationalError: (1045, "Access denied for user '_c85c2ca7b22cd0b1'@'localhost' (using password: YES)")
2024-10-08 13:16:01,103 ERROR scheduler Exception in Enqueue Events for Site ozerpan.local
Traceback (most recent call last):
  File "/home/mstfrs/Desktop/ozerpan/apps/frappe/frappe/utils/scheduler.py", line 106, in enqueue_events_for_site
    if is_scheduler_inactive():
  File "/home/mstfrs/Desktop/ozerpan/apps/frappe/frappe/utils/scheduler.py", line 150, in is_scheduler_inactive
    if is_scheduler_disabled(verbose=verbose):
  File "/home/mstfrs/Desktop/ozerpan/apps/frappe/frappe/utils/scheduler.py", line 163, in is_scheduler_disabled
    frappe.db.get_single_value("System Settings", "enable_scheduler")
  File "/home/mstfrs/Desktop/ozerpan/apps/frappe/frappe/database/database.py", line 846, in get_single_value
    ).run()
  File "/home/mstfrs/Desktop/ozerpan/apps/frappe/frappe/query_builder/utils.py", line 84, in execute_query
    result = frappe.db.sql(query, params, *args, **kwargs)  # nosemgrep
  File "/home/mstfrs/Desktop/ozerpan/apps/frappe/frappe/database/database.py", line 213, in sql
    self.connect()
  File "/home/mstfrs/Desktop/ozerpan/apps/frappe/frappe/database/database.py", line 118, in connect
    self._conn: "MariadbConnection" | "PostgresConnection" = self.get_connection()
  File "/home/mstfrs/Desktop/ozerpan/apps/frappe/frappe/database/mariadb/database.py", line 107, in get_connection
    conn = self._get_connection()
  File "/home/mstfrs/Desktop/ozerpan/apps/frappe/frappe/database/mariadb/database.py", line 113, in _get_connection
    return self.create_connection()
  File "/home/mstfrs/Desktop/ozerpan/apps/frappe/frappe/database/mariadb/database.py", line 116, in create_connection
    return pymysql.connect(**self.get_connection_settings())
  File "/home/mstfrs/Desktop/ozerpan/env/lib/python3.10/site-packages/pymysql/connections.py", line 361, in __init__
    self.connect()
  File "/home/mstfrs/Desktop/ozerpan/env/lib/python3.10/site-packages/pymysql/connections.py", line 669, in connect
    self._request_authentication()
  File "/home/mstfrs/Desktop/ozerpan/env/lib/python3.10/site-packages/pymysql/connections.py", line 957, in _request_authentication
    auth_packet = self._read_packet()
  File "/home/mstfrs/Desktop/ozerpan/env/lib/python3.10/site-packages/pymysql/connections.py", line 775, in _read_packet
    packet.raise_for_error()
  File "/home/mstfrs/Desktop/ozerpan/env/lib/python3.10/site-packages/pymysql/protocol.py", line 219, in raise_for_error
    err.raise_mysql_exception(self._data)
  File "/home/mstfrs/Desktop/ozerpan/env/lib/python3.10/site-packages/pymysql/err.py", line 150, in raise_mysql_exception
    raise errorclass(errno, errval)
pymysql.err.OperationalError: (1045, "Access denied for user '_c85c2ca7b22cd0b1'@'localhost' (using password: YES)")
2024-10-08 13:20:00,836 ERROR scheduler Exception in Enqueue Events for Site ozerpan.local
Traceback (most recent call last):
  File "/home/mstfrs/Desktop/ozerpan/apps/frappe/frappe/utils/scheduler.py", line 106, in enqueue_events_for_site
    if is_scheduler_inactive():
  File "/home/mstfrs/Desktop/ozerpan/apps/frappe/frappe/utils/scheduler.py", line 150, in is_scheduler_inactive
    if is_scheduler_disabled(verbose=verbose):
  File "/home/mstfrs/Desktop/ozerpan/apps/frappe/frappe/utils/scheduler.py", line 163, in is_scheduler_disabled
    frappe.db.get_single_value("System Settings", "enable_scheduler")
  File "/home/mstfrs/Desktop/ozerpan/apps/frappe/frappe/database/database.py", line 846, in get_single_value
    ).run()
  File "/home/mstfrs/Desktop/ozerpan/apps/frappe/frappe/query_builder/utils.py", line 84, in execute_query
    result = frappe.db.sql(query, params, *args, **kwargs)  # nosemgrep
  File "/home/mstfrs/Desktop/ozerpan/apps/frappe/frappe/database/database.py", line 213, in sql
    self.connect()
  File "/home/mstfrs/Desktop/ozerpan/apps/frappe/frappe/database/database.py", line 118, in connect
    self._conn: "MariadbConnection" | "PostgresConnection" = self.get_connection()
  File "/home/mstfrs/Desktop/ozerpan/apps/frappe/frappe/database/mariadb/database.py", line 107, in get_connection
    conn = self._get_connection()
  File "/home/mstfrs/Desktop/ozerpan/apps/frappe/frappe/database/mariadb/database.py", line 113, in _get_connection
    return self.create_connection()
  File "/home/mstfrs/Desktop/ozerpan/apps/frappe/frappe/database/mariadb/database.py", line 116, in create_connection
    return pymysql.connect(**self.get_connection_settings())
  File "/home/mstfrs/Desktop/ozerpan/env/lib/python3.10/site-packages/pymysql/connections.py", line 361, in __init__
    self.connect()
  File "/home/mstfrs/Desktop/ozerpan/env/lib/python3.10/site-packages/pymysql/connections.py", line 669, in connect
    self._request_authentication()
  File "/home/mstfrs/Desktop/ozerpan/env/lib/python3.10/site-packages/pymysql/connections.py", line 957, in _request_authentication
    auth_packet = self._read_packet()
  File "/home/mstfrs/Desktop/ozerpan/env/lib/python3.10/site-packages/pymysql/connections.py", line 775, in _read_packet
    packet.raise_for_error()
  File "/home/mstfrs/Desktop/ozerpan/env/lib/python3.10/site-packages/pymysql/protocol.py", line 219, in raise_for_error
    err.raise_mysql_exception(self._data)
  File "/home/mstfrs/Desktop/ozerpan/env/lib/python3.10/site-packages/pymysql/err.py", line 150, in raise_mysql_exception
    raise errorclass(errno, errval)
pymysql.err.OperationalError: (1045, "Access denied for user '_c85c2ca7b22cd0b1'@'localhost' (using password: YES)")
2024-10-08 13:24:00,600 ERROR scheduler Exception in Enqueue Events for Site ozerpan.local
Traceback (most recent call last):
  File "/home/mstfrs/Desktop/ozerpan/apps/frappe/frappe/utils/scheduler.py", line 106, in enqueue_events_for_site
    if is_scheduler_inactive():
  File "/home/mstfrs/Desktop/ozerpan/apps/frappe/frappe/utils/scheduler.py", line 150, in is_scheduler_inactive
    if is_scheduler_disabled(verbose=verbose):
  File "/home/mstfrs/Desktop/ozerpan/apps/frappe/frappe/utils/scheduler.py", line 163, in is_scheduler_disabled
    frappe.db.get_single_value("System Settings", "enable_scheduler")
  File "/home/mstfrs/Desktop/ozerpan/apps/frappe/frappe/database/database.py", line 846, in get_single_value
    ).run()
  File "/home/mstfrs/Desktop/ozerpan/apps/frappe/frappe/query_builder/utils.py", line 84, in execute_query
    result = frappe.db.sql(query, params, *args, **kwargs)  # nosemgrep
  File "/home/mstfrs/Desktop/ozerpan/apps/frappe/frappe/database/database.py", line 213, in sql
    self.connect()
  File "/home/mstfrs/Desktop/ozerpan/apps/frappe/frappe/database/database.py", line 118, in connect
    self._conn: "MariadbConnection" | "PostgresConnection" = self.get_connection()
  File "/home/mstfrs/Desktop/ozerpan/apps/frappe/frappe/database/mariadb/database.py", line 107, in get_connection
    conn = self._get_connection()
  File "/home/mstfrs/Desktop/ozerpan/apps/frappe/frappe/database/mariadb/database.py", line 113, in _get_connection
    return self.create_connection()
  File "/home/mstfrs/Desktop/ozerpan/apps/frappe/frappe/database/mariadb/database.py", line 116, in create_connection
    return pymysql.connect(**self.get_connection_settings())
  File "/home/mstfrs/Desktop/ozerpan/env/lib/python3.10/site-packages/pymysql/connections.py", line 361, in __init__
    self.connect()
  File "/home/mstfrs/Desktop/ozerpan/env/lib/python3.10/site-packages/pymysql/connections.py", line 669, in connect
    self._request_authentication()
  File "/home/mstfrs/Desktop/ozerpan/env/lib/python3.10/site-packages/pymysql/connections.py", line 957, in _request_authentication
    auth_packet = self._read_packet()
  File "/home/mstfrs/Desktop/ozerpan/env/lib/python3.10/site-packages/pymysql/connections.py", line 775, in _read_packet
    packet.raise_for_error()
  File "/home/mstfrs/Desktop/ozerpan/env/lib/python3.10/site-packages/pymysql/protocol.py", line 219, in raise_for_error
    err.raise_mysql_exception(self._data)
  File "/home/mstfrs/Desktop/ozerpan/env/lib/python3.10/site-packages/pymysql/err.py", line 150, in raise_mysql_exception
    raise errorclass(errno, errval)
pymysql.err.OperationalError: (1045, "Access denied for user '_c85c2ca7b22cd0b1'@'localhost' (using password: YES)")
2024-10-08 13:28:00,723 ERROR scheduler Exception in Enqueue Events for Site ozerpan.local
Traceback (most recent call last):
  File "/home/mstfrs/Desktop/ozerpan/apps/frappe/frappe/utils/scheduler.py", line 106, in enqueue_events_for_site
    if is_scheduler_inactive():
  File "/home/mstfrs/Desktop/ozerpan/apps/frappe/frappe/utils/scheduler.py", line 150, in is_scheduler_inactive
    if is_scheduler_disabled(verbose=verbose):
  File "/home/mstfrs/Desktop/ozerpan/apps/frappe/frappe/utils/scheduler.py", line 163, in is_scheduler_disabled
    frappe.db.get_single_value("System Settings", "enable_scheduler")
  File "/home/mstfrs/Desktop/ozerpan/apps/frappe/frappe/database/database.py", line 846, in get_single_value
    ).run()
  File "/home/mstfrs/Desktop/ozerpan/apps/frappe/frappe/query_builder/utils.py", line 84, in execute_query
    result = frappe.db.sql(query, params, *args, **kwargs)  # nosemgrep
  File "/home/mstfrs/Desktop/ozerpan/apps/frappe/frappe/database/database.py", line 213, in sql
    self.connect()
  File "/home/mstfrs/Desktop/ozerpan/apps/frappe/frappe/database/database.py", line 118, in connect
    self._conn: "MariadbConnection" | "PostgresConnection" = self.get_connection()
  File "/home/mstfrs/Desktop/ozerpan/apps/frappe/frappe/database/mariadb/database.py", line 107, in get_connection
    conn = self._get_connection()
  File "/home/mstfrs/Desktop/ozerpan/apps/frappe/frappe/database/mariadb/database.py", line 113, in _get_connection
    return self.create_connection()
  File "/home/mstfrs/Desktop/ozerpan/apps/frappe/frappe/database/mariadb/database.py", line 116, in create_connection
    return pymysql.connect(**self.get_connection_settings())
  File "/home/mstfrs/Desktop/ozerpan/env/lib/python3.10/site-packages/pymysql/connections.py", line 361, in __init__
    self.connect()
  File "/home/mstfrs/Desktop/ozerpan/env/lib/python3.10/site-packages/pymysql/connections.py", line 669, in connect
    self._request_authentication()
  File "/home/mstfrs/Desktop/ozerpan/env/lib/python3.10/site-packages/pymysql/connections.py", line 957, in _request_authentication
    auth_packet = self._read_packet()
  File "/home/mstfrs/Desktop/ozerpan/env/lib/python3.10/site-packages/pymysql/connections.py", line 775, in _read_packet
    packet.raise_for_error()
  File "/home/mstfrs/Desktop/ozerpan/env/lib/python3.10/site-packages/pymysql/protocol.py", line 219, in raise_for_error
    err.raise_mysql_exception(self._data)
  File "/home/mstfrs/Desktop/ozerpan/env/lib/python3.10/site-packages/pymysql/err.py", line 150, in raise_mysql_exception
    raise errorclass(errno, errval)
pymysql.err.OperationalError: (1045, "Access denied for user '_c85c2ca7b22cd0b1'@'localhost' (using password: YES)")
2024-10-08 13:32:00,472 ERROR scheduler Exception in Enqueue Events for Site ozerpan.local
Traceback (most recent call last):
  File "/home/mstfrs/Desktop/ozerpan/apps/frappe/frappe/utils/scheduler.py", line 106, in enqueue_events_for_site
    if is_scheduler_inactive():
  File "/home/mstfrs/Desktop/ozerpan/apps/frappe/frappe/utils/scheduler.py", line 150, in is_scheduler_inactive
    if is_scheduler_disabled(verbose=verbose):
  File "/home/mstfrs/Desktop/ozerpan/apps/frappe/frappe/utils/scheduler.py", line 163, in is_scheduler_disabled
    frappe.db.get_single_value("System Settings", "enable_scheduler")
  File "/home/mstfrs/Desktop/ozerpan/apps/frappe/frappe/database/database.py", line 846, in get_single_value
    ).run()
  File "/home/mstfrs/Desktop/ozerpan/apps/frappe/frappe/query_builder/utils.py", line 84, in execute_query
    result = frappe.db.sql(query, params, *args, **kwargs)  # nosemgrep
  File "/home/mstfrs/Desktop/ozerpan/apps/frappe/frappe/database/database.py", line 213, in sql
    self.connect()
  File "/home/mstfrs/Desktop/ozerpan/apps/frappe/frappe/database/database.py", line 118, in connect
    self._conn: "MariadbConnection" | "PostgresConnection" = self.get_connection()
  File "/home/mstfrs/Desktop/ozerpan/apps/frappe/frappe/database/mariadb/database.py", line 107, in get_connection
    conn = self._get_connection()
  File "/home/mstfrs/Desktop/ozerpan/apps/frappe/frappe/database/mariadb/database.py", line 113, in _get_connection
    return self.create_connection()
  File "/home/mstfrs/Desktop/ozerpan/apps/frappe/frappe/database/mariadb/database.py", line 116, in create_connection
    return pymysql.connect(**self.get_connection_settings())
  File "/home/mstfrs/Desktop/ozerpan/env/lib/python3.10/site-packages/pymysql/connections.py", line 361, in __init__
    self.connect()
  File "/home/mstfrs/Desktop/ozerpan/env/lib/python3.10/site-packages/pymysql/connections.py", line 669, in connect
    self._request_authentication()
  File "/home/mstfrs/Desktop/ozerpan/env/lib/python3.10/site-packages/pymysql/connections.py", line 957, in _request_authentication
    auth_packet = self._read_packet()
  File "/home/mstfrs/Desktop/ozerpan/env/lib/python3.10/site-packages/pymysql/connections.py", line 775, in _read_packet
    packet.raise_for_error()
  File "/home/mstfrs/Desktop/ozerpan/env/lib/python3.10/site-packages/pymysql/protocol.py", line 219, in raise_for_error
    err.raise_mysql_exception(self._data)
  File "/home/mstfrs/Desktop/ozerpan/env/lib/python3.10/site-packages/pymysql/err.py", line 150, in raise_mysql_exception
    raise errorclass(errno, errval)
pymysql.err.OperationalError: (1045, "Access denied for user '_c85c2ca7b22cd0b1'@'localhost' (using password: YES)")
2024-10-08 13:36:01,236 ERROR scheduler Exception in Enqueue Events for Site ozerpan.local
Traceback (most recent call last):
  File "/home/mstfrs/Desktop/ozerpan/apps/frappe/frappe/utils/scheduler.py", line 106, in enqueue_events_for_site
    if is_scheduler_inactive():
  File "/home/mstfrs/Desktop/ozerpan/apps/frappe/frappe/utils/scheduler.py", line 150, in is_scheduler_inactive
    if is_scheduler_disabled(verbose=verbose):
  File "/home/mstfrs/Desktop/ozerpan/apps/frappe/frappe/utils/scheduler.py", line 163, in is_scheduler_disabled
    frappe.db.get_single_value("System Settings", "enable_scheduler")
  File "/home/mstfrs/Desktop/ozerpan/apps/frappe/frappe/database/database.py", line 846, in get_single_value
    ).run()
  File "/home/mstfrs/Desktop/ozerpan/apps/frappe/frappe/query_builder/utils.py", line 84, in execute_query
    result = frappe.db.sql(query, params, *args, **kwargs)  # nosemgrep
  File "/home/mstfrs/Desktop/ozerpan/apps/frappe/frappe/database/database.py", line 213, in sql
    self.connect()
  File "/home/mstfrs/Desktop/ozerpan/apps/frappe/frappe/database/database.py", line 118, in connect
    self._conn: "MariadbConnection" | "PostgresConnection" = self.get_connection()
  File "/home/mstfrs/Desktop/ozerpan/apps/frappe/frappe/database/mariadb/database.py", line 107, in get_connection
    conn = self._get_connection()
  File "/home/mstfrs/Desktop/ozerpan/apps/frappe/frappe/database/mariadb/database.py", line 113, in _get_connection
    return self.create_connection()
  File "/home/mstfrs/Desktop/ozerpan/apps/frappe/frappe/database/mariadb/database.py", line 116, in create_connection
    return pymysql.connect(**self.get_connection_settings())
  File "/home/mstfrs/Desktop/ozerpan/env/lib/python3.10/site-packages/pymysql/connections.py", line 361, in __init__
    self.connect()
  File "/home/mstfrs/Desktop/ozerpan/env/lib/python3.10/site-packages/pymysql/connections.py", line 669, in connect
    self._request_authentication()
  File "/home/mstfrs/Desktop/ozerpan/env/lib/python3.10/site-packages/pymysql/connections.py", line 957, in _request_authentication
    auth_packet = self._read_packet()
  File "/home/mstfrs/Desktop/ozerpan/env/lib/python3.10/site-packages/pymysql/connections.py", line 775, in _read_packet
    packet.raise_for_error()
  File "/home/mstfrs/Desktop/ozerpan/env/lib/python3.10/site-packages/pymysql/protocol.py", line 219, in raise_for_error
    err.raise_mysql_exception(self._data)
  File "/home/mstfrs/Desktop/ozerpan/env/lib/python3.10/site-packages/pymysql/err.py", line 150, in raise_mysql_exception
    raise errorclass(errno, errval)
pymysql.err.OperationalError: (1045, "Access denied for user '_c85c2ca7b22cd0b1'@'localhost' (using password: YES)")
